<robot
  name="koko_gazebo">
  <link name="world"/>
  <link name="base_link">
    <inertial>
      <origin
        xyz="-0.0757957750238399 0.140984711919552 -0.0275242044620397"
        rpy="0 0 0" />
      <mass
        value="5.35087699357395" />
      <inertia
        ixx="0.0187422392203513"
        ixy="0.000249830365012887"
        ixz="-9.95942614361503E-05"
        iyy="0.0149272112233475"
        iyz="-0.0026993960481081"
        izz="0.0181034939902423" />
    </inertial>
    <visual>
      <origin
        xyz="0 0 0"
        rpy="0 0 0" />
      <geometry>
        <mesh
          filename="package://koko_gazebo/meshes/base_link.STL" />
      </geometry>
      <material
        name="">
        <color
          rgba="0.752941176470588 0.752941176470588 0.752941176470588 1" />
      </material>
    </visual>
    <collision>
      <origin
        xyz="0 0 0"
        rpy="0 0 0" />
      <geometry>
        <mesh
          filename="package://koko_gazebo/meshes/base_link.STL" />
      </geometry>
    </collision>
  </link>
  <link
    name="lift_link">
    <inertial>
      <origin
        xyz="0.0137518298200178 9.31785077161046E-05 -4.72900080879524E-05"
        rpy="0 0 0" />
      <mass
        value="0.0945714084478179" />
      <inertia
        ixx="5.09580014268689E-05"
        ixy="-1.9745804718431E-08"
        ixz="1.63492553760009E-07"
        iyy="9.24996047366959E-05"
        iyz="-8.22989412877518E-10"
        izz="5.29296115073191E-05" />
    </inertial>
    <visual>
      <origin
        xyz="0 0 0"
        rpy="0 0 0" />
      <geometry>
        <mesh
          filename="package://koko_gazebo/meshes/lift_link.STL" />
      </geometry>
      <material
        name="">
        <color
          rgba="1 1 1 1" />
      </material>
    </visual>
    <collision>
      <origin
        xyz="0 0 0"
        rpy="0 0 0" />
      <geometry>
        <mesh
          filename="package://koko_gazebo/meshes/lift_link.STL" />
      </geometry>
    </collision>
  </link>
  <joint
    name="lift_joint"
    type="continuous">
    <origin
      xyz="-0.0762 0.22288 0.078275"
      rpy="1.5708 -0.7854 1.5708" />
    <parent
      link="base_link" />
    <child
      link="lift_link" />
    <axis
      xyz="0 0 1" />
  </joint>
  <link
    name="sroll_link">
    <inertial>
      <origin
        xyz="-2.69564467042516E-06 -0.0103941247742759 0.067080285801929"
        rpy="0 0 0" />
      <mass
        value="4.87714486845394" />
      <inertia
        ixx="0.0102609522942837"
        ixy="6.12489730276725E-08"
        ixz="-9.76949290734999E-07"
        iyy="0.0104359418011871"
        iyz="0.000111882173967031"
        izz="0.00815305827142092" />
    </inertial>
    <visual>
      <origin
        xyz="0 0 0"
        rpy="0 0 0" />
      <geometry>
        <mesh
          filename="package://koko_gazebo/meshes/sroll_link.STL" />
      </geometry>
      <material
        name="">
        <color
          rgba="1 1 1 1" />
      </material>
    </visual>
    <collision>
      <origin
        xyz="0 0 0"
        rpy="0 0 0" />
      <geometry>
        <mesh
          filename="package://koko_gazebo/meshes/sroll_link.STL" />
      </geometry>
    </collision>
  </link>
  <joint
    name="sroll_joint"
    type="continuous">
    <origin
      xyz="0.06495 0 0"
      rpy="0 1.5708 0" />
    <parent
      link="lift_link" />
    <child
      link="sroll_link" />
    <axis
      xyz="0 0 1" />
  </joint>
  <link
    name="elbow_link">
    <inertial>
      <origin
        xyz="0.0422346678984667 4.42730856626689E-05 4.14314615251321E-05"
        rpy="0 0 0" />
      <mass
        value="0.203035966469269" />
      <inertia
        ixx="0.000167473173510081"
        ixy="2.30817545507112E-07"
        ixz="-1.83612742409275E-07"
        iyy="0.000166157351385167"
        iyz="-2.2611457356263E-08"
        izz="0.000167396300440238" />
    </inertial>
    <visual>
      <origin
        xyz="0 0 0"
        rpy="0 0 0" />
      <geometry>
        <mesh
          filename="package://koko_gazebo/meshes/elbow_link.STL" />
      </geometry>
      <material
        name="">
        <color
          rgba="1 1 1 1" />
      </material>
    </visual>
    <collision>
      <origin
        xyz="0 0 0"
        rpy="0 0 0" />
      <geometry>
        <mesh
          filename="package://koko_gazebo/meshes/elbow_link.STL" />
      </geometry>
    </collision>
  </link>
  <joint
    name="elbow_joint"
    type="continuous">
    <origin
      xyz="0 0.01 0.19025"
      rpy="2.9745 -1.5708 -2.9745" />
    <parent
      link="sroll_link" />
    <child
      link="elbow_link" />
    <axis
      xyz="0 0 1" />
  </joint>
  <link
    name="eroll_link">
    <inertial>
      <origin
        xyz="-2.69578007960902E-06 -0.0103941248103617 0.0670802858040951"
        rpy="0 0 0" />
      <mass
        value="4.87714486426897" />
      <inertia
        ixx="0.0102609512250403"
        ixy="6.12485520913233E-08"
        ixz="-9.76947490299796E-07"
        iyy="0.0104359611445639"
        iyz="0.000111882172510607"
        izz="0.0081530765474748" />
    </inertial>
    <visual>
      <origin
        xyz="0 0 0"
        rpy="0 0 0" />
      <geometry>
        <mesh
          filename="package://koko_gazebo/meshes/eroll_link.STL" />
      </geometry>
      <material
        name="">
        <color
          rgba="1 1 1 1" />
      </material>
    </visual>
    <collision>
      <origin
        xyz="0 0 0"
        rpy="0 0 0" />
      <geometry>
        <mesh
          filename="package://koko_gazebo/meshes/eroll_link.STL" />
      </geometry>
    </collision>
  </link>
  <joint
    name="eroll_joint"
    type="continuous">
    <origin
      xyz="0.06495 0 0"
      rpy="0 1.5708 0" />
    <parent
      link="elbow_link" />
    <child
      link="eroll_link" />
    <axis
      xyz="0 0 1" />
  </joint>
  <link
    name="wrist_link">
    <inertial>
      <origin
        xyz="0.0137518298200184 9.31785077139813E-05 -4.72900080885075E-05"
        rpy="0 0 0" />
      <mass
        value="0.0945714084478188" />
      <inertia
        ixx="5.0958001426869E-05"
        ixy="-1.97458047184852E-08"
        ixz="1.6349255376012E-07"
        iyy="9.24996047366979E-05"
        iyz="-8.22989412959943E-10"
        izz="5.29296115073212E-05" />
    </inertial>
    <visual>
      <origin
        xyz="0 0 0"
        rpy="0 0 0" />
      <geometry>
        <mesh
          filename="package://koko_gazebo/meshes/wrist_link.STL" />
      </geometry>
      <material
        name="">
        <color
          rgba="0.898039215686275 0.917647058823529 0.929411764705882 1" />
      </material>
    </visual>
    <collision>
      <origin
        xyz="0 0 0"
        rpy="0 0 0" />
      <geometry>
        <mesh
          filename="package://koko_gazebo/meshes/wrist_link.STL" />
      </geometry>
    </collision>
  </link>
  <joint
    name="wrist_joint"
    type="continuous">
    <origin
      xyz="0 0.01 0.19025"
      rpy="-1.8925 -1.5708 1.9513" />
    <parent
      link="eroll_link" />
    <child
      link="wrist_link" />
    <axis
      xyz="0 0 1" />
  </joint>
  <link
    name="wroll_link">
    <inertial>
      <origin
        xyz="-0.0562350071035924 -0.00280283331198616 0.0375786926130955"
        rpy="0 0 0" />
      <mass
        value="0.95686918925379" />
      <inertia
        ixx="0.00121575344897543"
        ixy="0.000346811275988596"
        ixz="0.000669697569817252"
        iyy="0.00596774482621568"
        iyz="3.34290139549377E-05"
        izz="0.00564190463158831" />
    </inertial>
    <visual>
      <origin
        xyz="0 0 0"
        rpy="0 0 0" />
      <geometry>
        <mesh
          filename="package://koko_gazebo/meshes/wroll_link.STL" />
      </geometry>
      <material
        name="">
        <color
          rgba="1 1 1 1" />
      </material>
    </visual>
    <collision>
      <origin
        xyz="0 0 0"
        rpy="0 0 0" />
      <geometry>
        <mesh
          filename="package://koko_gazebo/meshes/wroll_link.STL" />
      </geometry>
    </collision>
  </link>
  <joint
    name="wroll_joint"
    type="continuous">
    <origin
      xyz="0.06495 0 0"
      rpy="0 1.5708 0" />
    <parent
      link="wrist_link" />
    <child
      link="wroll_link" />
    <axis
      xyz="0 0 1" />
  </joint>

  <joint name ="world_joint" type= "fixed">
    <origin xyz="0 0 2" rpy="0 0 0" />
    <parent link="world"/>
    <child link="base_link"/>
  </joint>
 <transmission name="tran1">
    <type>transmission_interface/SimpleTransmission</type>
    <joint name="lift_joint"><hardwareInterface>EffortJointInterface</hardwareInterface>
    </joint>
    <actuator name="motor1">
      <hardwareInterface>EffortJointInterface</hardwareInterface>
      <mechanicalReduction>1</mechanicalReduction>
    </actuator>
  </transmission>

  <transmission name="tran2">
    <type>transmission_interface/SimpleTransmission</type>
    <joint name="sroll_joint"><hardwareInterface>EffortJointInterface</hardwareInterface>
    </joint>
    <actuator name="motor2">
      <hardwareInterface>EffortJointInterface</hardwareInterface>
      <mechanicalReduction>1</mechanicalReduction>
    </actuator>
  </transmission>

  <transmission name="tran3">
    <type>transmission_interface/SimpleTransmission</type>
    <joint name="elbow_joint"><hardwareInterface>EffortJointInterface</hardwareInterface>
    </joint>
    <actuator name="motor3">
      <hardwareInterface>EffortJointInterface</hardwareInterface>
      <mechanicalReduction>1</mechanicalReduction>
    </actuator>
  </transmission>
  
  <transmission name="tran4">
    <type>transmission_interface/SimpleTransmission</type>
    <joint name="eroll_joint"><hardwareInterface>EffortJointInterface</hardwareInterface>
    </joint>
    <actuator name="motor4">
      <hardwareInterface>EffortJointInterface</hardwareInterface>
      <mechanicalReduction>1</mechanicalReduction>
    </actuator>
  </transmission>

  <transmission name="tran5">
    <type>transmission_interface/SimpleTransmission</type>
    <joint name="wrist_joint"><hardwareInterface>EffortJointInterface</hardwareInterface>
    </joint>
    <actuator name="motor5">
      <hardwareInterface>EffortJointInterface</hardwareInterface>
      <mechanicalReduction>1</mechanicalReduction>
    </actuator>
  </transmission>

  <transmission name="tran6">
    <type>transmission_interface/SimpleTransmission</type>
    <joint name="wroll_joint"><hardwareInterface>EffortJointInterface</hardwareInterface>
    </joint>
    <actuator name="motor6">
      <hardwareInterface>EffortJointInterface</hardwareInterface>
      <mechanicalReduction>1</mechanicalReduction>
    </actuator>
  </transmission>

  <gazebo>
    <plugin name="gazebo_ros_control" filename="libgazebo_ros_control.so">
      <robotNamespace>/DOF</robotNamespace>
    </plugin>
  </gazebo>
</robot>