<robot
  name="sixDOF_tracker_kin_v0">
  <link name="world"/>
  <link
    name="base_link">
    <inertial>
      <origin
        xyz="0.0682394837309409 0.105961654484643 0.215286346431961"
        rpy="0 0 0" />
      <mass
        value="1.17376561177193" />
      <inertia
        ixx="0.0354875108216887"
        ixy="4.02919521213019E-06"
        ixz="-0.000318212077500433"
        iyy="0.0293186849740791"
        iyz="-6.19456248926417E-05"
        izz="0.0120382710975123" />
    </inertial>
    <visual>
      <origin
        xyz="0 0 0"
        rpy="0 0 0" />
      <geometry>
        <mesh
          filename="package://sixDOF_tracker_kin_v0/meshes/base_link.STL" />
      </geometry>
      <material
        name="">
        <color
          rgba="0.752941176470588 0.752941176470588 0.752941176470588 1" />
      </material>
    </visual>
    <collision>
      <origin
        xyz="0 0 0"
        rpy="0 0 0" />
      <geometry>
        <mesh
          filename="package://sixDOF_tracker_kin_v0/meshes/base_link.STL" />
      </geometry>
    </collision>
  </link>
  <link
    name="lift_link">
    <inertial>
      <origin
        xyz="-0.0722070836014649 0.0754634317735985 -0.0096283443115166"
        rpy="0 0 0" />
      <mass
        value="2.22101260575421" />
      <inertia
        ixx="0.00501587573563656"
        ixy="0.000623751567095968"
        ixz="0.000151158398444018"
        iyy="0.00315932258802144"
        iyz="-0.000733074632959002"
        izz="0.00553149848162358" />
    </inertial>
    <visual>
      <origin
        xyz="0 0 0"
        rpy="0 0 0" />
      <geometry>
        <mesh
          filename="package://sixDOF_tracker_kin_v0/meshes/lift_link .STL" />
      </geometry>
      <material
        name="">
        <color
          rgba="0.529411764705882 0.549019607843137 0.549019607843137 1" />
      </material>
    </visual>
    <collision>
      <origin
        xyz="0 0 0"
        rpy="0 0 0" />
      <geometry>
        <mesh
          filename="package://sixDOF_tracker_kin_v0/meshes/lift_link .STL" />
      </geometry>
    </collision>
  </link>
  <joint
    name="lift_joint"
    type="continuous">
    <origin
      xyz="0.17145 0.05972 0.28194"
      rpy="1.5708 -6.123E-17 -1.5708" />
    <parent
      link="base_link" />
    <child
      link="lift_link" />
    <axis
      xyz="1 0 0" />
  </joint>
  <link
    name="sroll_link">
    <inertial>
      <origin
        xyz="0.0854447175246464 -0.0398284291536859 3.82416430466659E-09"
        rpy="0 0 0" />
      <mass
        value="3.94751896221057" />
      <inertia
        ixx="0.0039846018959534"
        ixy="0.000507090906969598"
        ixz="0.000881349336769348"
        iyy="0.00943847485877612"
        iyz="1.6408490799747E-10"
        izz="0.00887312956281006" />
    </inertial>
    <visual>
      <origin
        xyz="0 0 0"
        rpy="0 0 0" />
      <geometry>
        <mesh
          filename="package://sixDOF_tracker_kin_v0/meshes/sroll_link .STL" />
      </geometry>
      <material
        name="">
        <color
          rgba="1 1 1 1" />
      </material>
    </visual>
    <collision>
      <origin
        xyz="0 0 0"
        rpy="0 0 0" />
      <geometry>
        <mesh
          filename="package://sixDOF_tracker_kin_v0/meshes/sroll_link .STL" />
      </geometry>
    </collision>
  </link>
  <joint
    name="sroll_joint"
    type="continuous">
    <origin
      xyz="-0.057071 0 -0.04445"
      rpy="3.1416 1.5708 3.1416" />
    <parent
      link="lift_link" />
    <child
      link="sroll_link" />
    <axis
      xyz="1 0 0" />
  </joint>
  <link
    name="elbow_link">
    <inertial>
      <origin
        xyz="0.0462434190171923 0.0170539293837029 -0.00124723722031522"
        rpy="0 0 0" />
      <mass
        value="0.2431225035047" />
      <inertia
        ixx="0.000287349101443919"
        ixy="-1.97216697563278E-05"
        ixz="1.44222571440713E-06"
        iyy="0.000350550227472013"
        iyz="-7.84702983240501E-06"
        izz="0.000413771904088825" />
    </inertial>
    <visual>
      <origin
        xyz="0 0 0"
        rpy="0 0 0" />
      <geometry>
        <mesh
          filename="package://sixDOF_tracker_kin_v0/meshes/elbow_link.STL" />
      </geometry>
      <material
        name="">
        <color
          rgba="1 1 1 1" />
      </material>
    </visual>
    <collision>
      <origin
        xyz="0 0 0"
        rpy="0 0 0" />
      <geometry>
        <mesh
          filename="package://sixDOF_tracker_kin_v0/meshes/elbow_link.STL" />
      </geometry>
    </collision>
  </link>
  <joint
    name="elbow_joint"
    type="continuous">
    <origin
      xyz="0.27915 0.014 -0.051"
      rpy="3.1416 -1.5708 0" />
    <parent
      link="sroll_link" />
    <child
      link="elbow_link" />
    <axis
      xyz="1 0 0" />
  </joint>
  <link
    name="eroll_link">
    <inertial>
      <origin
        xyz="-0.0838462800512732 0.000803353868510659 -0.00131038540560245"
        rpy="0 0 0" />
      <mass
        value="0.45601400582867" />
      <inertia
        ixx="0.000529844752453312"
        ixy="-4.17458732373497E-05"
        ixz="7.03457444112151E-05"
        iyy="0.00200644972391329"
        iyz="6.38804776661798E-06"
        izz="0.00169871312341941" />
    </inertial>
    <visual>
      <origin
        xyz="0 0 0"
        rpy="0 0 0" />
      <geometry>
        <mesh
          filename="package://sixDOF_tracker_kin_v0/meshes/eroll_link.STL" />
      </geometry>
      <material
        name="">
        <color
          rgba="0.898039215686275 0.917647058823529 0.929411764705882 1" />
      </material>
    </visual>
    <collision>
      <origin
        xyz="0 0 0"
        rpy="0 0 0" />
      <geometry>
        <mesh
          filename="package://sixDOF_tracker_kin_v0/meshes/eroll_link.STL" />
      </geometry>
    </collision>
  </link>
  <joint
    name="eroll_joint"
    type="continuous">
    <origin
      xyz="0.051 0.20876 0"
      rpy="1.5708 -2.2204E-16 1.5708" />
    <parent
      link="elbow_link" />
    <child
      link="eroll_link" />
    <axis
      xyz="1 0 0" />
  </joint>
  <link
    name="wrist_link">
    <inertial>
      <origin
        xyz="-2.01676172970344E-05 0.00377150455685027 -0.00190428759291311"
        rpy="0 0 0" />
      <mass
        value="0.073326481358293" />
      <inertia
        ixx="1.96748973033557E-05"
        ixy="-5.56150301885178E-09"
        ixz="2.70970576499869E-09"
        iyy="6.62145130070652E-05"
        iyz="-9.7528384049795E-07"
        izz="7.07545014802813E-05" />
    </inertial>
    <visual>
      <origin
        xyz="0 0 0"
        rpy="0 0 0" />
      <geometry>
        <mesh
          filename="package://sixDOF_tracker_kin_v0/meshes/wrist_link .STL" />
      </geometry>
      <material
        name="">
        <color
          rgba="1 1 1 1" />
      </material>
    </visual>
    <collision>
      <origin
        xyz="0 0 0"
        rpy="0 0 0" />
      <geometry>
        <mesh
          filename="package://sixDOF_tracker_kin_v0/meshes/wrist_link .STL" />
      </geometry>
    </collision>
  </link>
  <joint
    name="wrist_joint"
    type="continuous">
    <origin
      xyz="0.059001 0.036587 0"
      rpy="1.5708 -1.5708 0" />
    <parent
      link="eroll_link" />
    <child
      link="wrist_link" />
    <axis
      xyz="1 0 0" />
  </joint>
  <link
    name="wroll_link">
    <inertial>
      <origin
        xyz="5.97002243847011E-05 0.0264652769338756 -4.32317619935563E-05"
        rpy="0 0 0" />
      <mass
        value="0.191780556161435" />
      <inertia
        ixx="0.000103292534968937"
        ixy="-2.33722310430005E-07"
        ixz="8.40795417903918E-08"
        iyy="0.000122680534206285"
        iyz="2.23026449486201E-07"
        izz="0.000103289268868594" />
    </inertial>
    <visual>
      <origin
        xyz="0 0 0"
        rpy="0 0 0" />
      <geometry>
        <mesh
          filename="package://sixDOF_tracker_kin_v0/meshes/wroll_link.STL" />
      </geometry>
      <material
        name="">
        <color
          rgba="0.647058823529412 0.517647058823529 0 1" />
      </material>
    </visual>
    <collision>
      <origin
        xyz="0 0 0"
        rpy="0 0 0" />
      <geometry>
        <mesh
          filename="package://sixDOF_tracker_kin_v0/meshes/wroll_link.STL" />
      </geometry>
    </collision>
  </link>
  <joint
    name="wroll_joint"
    type="continuous">
    <origin
      xyz="0 0.026859 0"
      rpy="3.1416 -0.7854 -3.1416" />
    <parent
      link="wrist_link" />
    <child
      link="wroll_link" />
    <axis
      xyz="0 1 0" />
  </joint>
  <link
    name="ee_tracker_link">
    <inertial>
      <origin
        xyz="-8.01166369232553E-07 3.04183060452767E-05 0.0143118565092358"
        rpy="0 0 0" />
      <mass
        value="0.0852058469172091" />
      <inertia
        ixx="5.02601345271498E-05"
        ixy="3.55567262763946E-09"
        ixz="8.05802151674336E-10"
        iyy="5.0543001381441E-05"
        iyz="-1.54466070855994E-07"
        izz="8.4882254844128E-05" />
    </inertial>
    <visual>
      <origin
        xyz="0 0 0"
        rpy="0 0 0" />
      <geometry>
        <mesh
          filename="package://sixDOF_tracker_kin_v0/meshes/ee_tracker_link.STL" />
      </geometry>
      <material
        name="">
        <color
          rgba="0.698039215686274 0.698039215686274 0.698039215686274 1" />
      </material>
    </visual>
    <collision>
      <origin
        xyz="0 0 0"
        rpy="0 0 0" />
      <geometry>
        <mesh
          filename="package://sixDOF_tracker_kin_v0/meshes/ee_tracker_link.STL" />
      </geometry>
    </collision>
  </link>
  <joint
    name="ee_tracker_joint"
    type="fixed">
    <origin
      xyz="0 0.051125 0"
      rpy="-1.5708 -0.78539 -1.5701E-14" />
    <parent
      link="wroll_link" />
    <child
      link="ee_tracker_link" />
    <axis
      xyz="0 0 1" />
  </joint>
  <link
    name="base_tracker_link">
    <inertial>
      <origin
        xyz="-7.96867933416934E-07 3.04158362704754E-05 0.0143118579201663"
        rpy="0 0 0" />
      <mass
        value="0.0852058438167774" />
      <inertia
        ixx="5.02601459391029E-05"
        ixy="3.55210825274934E-09"
        ixz="7.9651164511398E-10"
        iyy="5.05429948319599E-05"
        iyz="-1.54448336332006E-07"
        izz="8.48822527367183E-05" />
    </inertial>
    <visual>
      <origin
        xyz="0 0 0"
        rpy="0 0 0" />
      <geometry>
        <mesh
          filename="package://sixDOF_tracker_kin_v0/meshes/base_tracker_link.STL" />
      </geometry>
      <material
        name="">
        <color
          rgba="0.698039215686274 0.698039215686274 0.698039215686274 1" />
      </material>
    </visual>
    <collision>
      <origin
        xyz="0 0 0"
        rpy="0 0 0" />
      <geometry>
        <mesh
          filename="package://sixDOF_tracker_kin_v0/meshes/base_tracker_link.STL" />
      </geometry>
    </collision>
  </link>
  <joint
    name="base_tracker_joint"
    type="fixed">
    <origin
      xyz="0.05969 0.18605 0.43609"
      rpy="6.123E-17 -2.1575E-21 -3.1416" />
    <parent
      link="base_link" />
    <child
      link="base_tracker_link" />
    <axis
      xyz="0 0 0" />
  </joint>
  <joint name ="world_joint" type= "fixed">
    <origin xyz="0 0 2" rpy="0 0 0" />
    <parent link="world"/>
    <child link="base_link"/>
  </joint>

</robot>