<robot
  name="koko_description_sevendof_kin">
  <link
    name="base_link">
    <inertial>
      <origin
        xyz="-0.00237523344929972 -0.1517165080015 0.133562829709273"
        rpy="0 0 0" />
      <mass
        value="0.210349130781402" />
      <inertia
        ixx="0.00131121369963536"
        ixy="-3.09616125639546E-09"
        ixz="0.000877219835937122"
        iyy="0.00192535968380682"
        iyz="-4.97710584568109E-09"
        izz="0.00130019808237566" />
    </inertial>
    <visual>
      <origin
        xyz="0 0 0"
        rpy="0 0 0" />
      <geometry>
        <mesh
          filename="package://koko_description_sevendof_kin/meshes/base_link.STL" />
      </geometry>
      <material
        name="">
        <color
          rgba="0.792156862745098 0.819607843137255 0.933333333333333 1" />
      </material>
    </visual>
    <collision>
      <origin
        xyz="0 0 0"
        rpy="0 0 0" />
      <geometry>
        <mesh
          filename="package://koko_description_sevendof_kin/meshes/base_link.STL" />
      </geometry>
    </collision>
  </link>
  <link
    name="shoulder_link">
    <inertial>
      <origin
        xyz="-0.00743279514063305 -2.52071514625918E-05 0.0799017938353"
        rpy="0 0 0" />
      <mass
        value="4.06059384155066" />
      <inertia
        ixx="0.00615693282567219"
        ixy="-5.06333124630133E-07"
        ixz="-3.99043950516939E-06"
        iyy="0.00629903077613048"
        iyz="-3.71787023920647E-07"
        izz="0.00592096380187952" />
    </inertial>
    <visual>
      <origin
        xyz="0 0 0"
        rpy="0 0 0" />
      <geometry>
        <mesh
          filename="package://koko_description_sevendof_kin/meshes/shoulder_link.STL" />
      </geometry>
      <material
        name="">
        <color
          rgba="0.843137254901961 0.815686274509804 0.752941176470588 1" />
      </material>
    </visual>
    <collision>
      <origin
        xyz="0 0 0"
        rpy="0 0 0" />
      <geometry>
        <mesh
          filename="package://koko_description_sevendof_kin/meshes/shoulder_link.STL" />
      </geometry>
    </collision>
  </link>
  <joint
    name="base_roll_joint"
    type="revolute">
    <origin
      xyz="0.011376 -0.15172 0.15127"
      rpy="6.8694E-15 0.7854 4.8574E-15" />
    <parent
      link="base_link" />
    <child
      link="shoulder_link" />
    <axis
      xyz="0 0 1" />
    <limit
      lower="-3"
      upper="3"
      effort="0"
      velocity="0" />
  </joint>
  <link
    name="shoulder_lift_link">
    <inertial>
      <origin
        xyz="-0.000675436886318742 0.00184134271669295 -4.83936786754846E-08"
        rpy="0 0 0" />
      <mass
        value="0.437261742750678" />
      <inertia
        ixx="0.00102944853640165"
        ixy="-2.02390378444949E-05"
        ixz="-6.05037379180454E-07"
        iyy="0.00107939830701215"
        iyz="-8.03926874740817E-07"
        izz="0.00065753081493914" />
    </inertial>
    <visual>
      <origin
        xyz="0 0 0"
        rpy="0 0 0" />
      <geometry>
        <mesh
          filename="package://koko_description_sevendof_kin/meshes/shoulder_lift_link.STL" />
      </geometry>
      <material
        name="">
        <color
          rgba="1 0.501960784313725 0.501960784313725 1" />
      </material>
    </visual>
    <collision>
      <origin
        xyz="0 0 0"
        rpy="0 0 0" />
      <geometry>
        <mesh
          filename="package://koko_description_sevendof_kin/meshes/shoulder_lift_link.STL" />
      </geometry>
    </collision>
  </link>
  <joint
    name="shoulder_lift_joint"
    type="revolute">
    <origin
      xyz="0.01143 4.0407E-05 0.20168"
      rpy="1.5708 -0.7854 0.0035351" />
    <parent
      link="shoulder_link" />
    <child
      link="shoulder_lift_link" />
    <axis
      xyz="0 0 1" />
    <limit
      lower="-3"
      upper="3"
      effort="0"
      velocity="0" />
  </joint>
  <link
    name="upper_arm_link">
    <inertial>
      <origin
        xyz="0.00883684635503601 -2.10376834621218E-05 0.0545707620911055"
        rpy="0 0 0" />
      <mass
        value="4.20794110984285" />
      <inertia
        ixx="0.00687960187039797"
        ixy="1.67396590783052E-06"
        ixz="-0.000316051448006955"
        iyy="0.00746098333457099"
        iyz="2.43898407920875E-06"
        izz="0.00648402378721376" />
    </inertial>
    <visual>
      <origin
        xyz="0 0 0"
        rpy="0 0 0" />
      <geometry>
        <mesh
          filename="package://koko_description_sevendof_kin/meshes/upper_arm_link.STL" />
      </geometry>
      <material
        name="">
        <color
          rgba="0.843137254901961 0.815686274509804 0.752941176470588 1" />
      </material>
    </visual>
    <collision>
      <origin
        xyz="0 0 0"
        rpy="0 0 0" />
      <geometry>
        <mesh
          filename="package://koko_description_sevendof_kin/meshes/upper_arm_link.STL" />
      </geometry>
    </collision>
  </link>
  <joint
    name="shoulder_roll_joint"
    type="revolute">
    <origin
      xyz="0.024593 -0.066237 0"
      rpy="1.5708 -0.0026664 0.35551" />
    <parent
      link="shoulder_lift_link" />
    <child
      link="upper_arm_link" />
    <axis
      xyz="0 0 -1" />
    <limit
      lower="-3"
      upper="3"
      effort="0"
      velocity="0" />
  </joint>
  <link
    name="upper_arm_lift_link">
    <inertial>
      <origin
        xyz="-3.53817429799008E-08 -0.00196475888435105 4.92619368614444E-05"
        rpy="0 0 0" />
      <mass
        value="0.437261171596511" />
      <inertia
        ixx="0.000657522904405021"
        ixy="5.54290931107256E-07"
        ixz="-1.90224252707453E-06"
        iyy="0.0010863552157954"
        iyz="5.19345168708606E-07"
        izz="0.00102244604898481" />
    </inertial>
    <visual>
      <origin
        xyz="0 0 0"
        rpy="0 0 0" />
      <geometry>
        <mesh
          filename="package://koko_description_sevendof_kin/meshes/upper_arm_lift_link.STL" />
      </geometry>
      <material
        name="">
        <color
          rgba="1 0.501960784313725 0.501960784313725 1" />
      </material>
    </visual>
    <collision>
      <origin
        xyz="0 0 0"
        rpy="0 0 0" />
      <geometry>
        <mesh
          filename="package://koko_description_sevendof_kin/meshes/upper_arm_lift_link.STL" />
      </geometry>
    </collision>
  </link>
  <joint
    name="elbow_lift_joint"
    type="revolute">
    <origin
      xyz="-0.01143 3.0476E-05 0.18102"
      rpy="1.3257 5.4262E-15 1.5681" />
    <parent
      link="upper_arm_link" />
    <child
      link="upper_arm_lift_link" />
    <axis
      xyz="1 0 0" />
    <limit
      lower="-3"
      upper="3"
      effort="0"
      velocity="0" />
  </joint>
  <link
    name="forearm_link">
    <inertial>
      <origin
        xyz="0.0547161453894347 -0.00731386870772321 -2.50594714140684E-06"
        rpy="0 0 0" />
      <mass
        value="4.12272375225066" />
      <inertia
        ixx="0.00596487176016726"
        ixy="3.34654485211887E-05"
        ixz="-1.65208226901162E-06"
        iyy="0.0066449689249241"
        iyz="1.07478451069075E-07"
        izz="0.00679246806328858" />
    </inertial>
    <visual>
      <origin
        xyz="0 0 0"
        rpy="0 0 0" />
      <geometry>
        <mesh
          filename="package://koko_description_sevendof_kin/meshes/forearm_link.STL" />
      </geometry>
      <material
        name="">
        <color
          rgba="0.843137254901961 0.815686274509804 0.752941176470588 1" />
      </material>
    </visual>
    <collision>
      <origin
        xyz="0 0 0"
        rpy="0 0 0" />
      <geometry>
        <mesh
          filename="package://koko_description_sevendof_kin/meshes/forearm_link.STL" />
      </geometry>
    </collision>
  </link>
  <joint
    name="elbow_roll_joint"
    type="revolute">
    <origin
      xyz="0 0.073871 0"
      rpy="-1.5708 1.6307E-15 1.5708" />
    <parent
      link="upper_arm_lift_link" />
    <child
      link="forearm_link" />
    <axis
      xyz="-1 0 0" />
    <limit
      lower="-3"
      upper="3"
      effort="0"
      velocity="0" />
  </joint>
  <link
    name="wrist_lift_link">
    <inertial>
      <origin
        xyz="0.000974827085185093 0.00171170705299935 -1.58170796460411E-08"
        rpy="0 0 0" />
      <mass
        value="0.437254818610311" />
      <inertia
        ixx="0.00103675451210623"
        ixy="2.62040106953331E-05"
        ixz="-1.86750656652842E-06"
        iyy="0.00107204090822893"
        iyz="2.46663788703419E-07"
        izz="0.000657516170676713" />
    </inertial>
    <visual>
      <origin
        xyz="0 0 0"
        rpy="0 0 0" />
      <geometry>
        <mesh
          filename="package://koko_description_sevendof_kin/meshes/wrist_lift_link.STL" />
      </geometry>
      <material
        name="">
        <color
          rgba="1 0.501960784313725 0.501960784313725 1" />
      </material>
    </visual>
    <collision>
      <origin
        xyz="0 0 0"
        rpy="0 0 0" />
      <geometry>
        <mesh
          filename="package://koko_description_sevendof_kin/meshes/wrist_lift_link.STL" />
      </geometry>
    </collision>
  </link>
  <joint
    name="wrist_lift_joint"
    type="revolute">
    <origin
      xyz="0.1778 0.01143 0"
      rpy="3.1416 -1.5135E-15 -1.4604" />
    <parent
      link="forearm_link" />
    <child
      link="wrist_lift_link" />
    <axis
      xyz="0 0 1" />
    <limit
      lower="-3"
      upper="3"
      effort="0"
      velocity="0" />
  </joint>
  <link
    name="wrist_roll_link">
    <inertial>
      <origin
        xyz="-2.08725103496565E-05 -7.17969804725493E-06 0.0698761509683182"
        rpy="0 0 0" />
      <mass
        value="1.42202378562226" />
      <inertia
        ixx="0.00150756967573788"
        ixy="-3.66544847715874E-08"
        ixz="-1.04603627993617E-06"
        iyy="0.001545092554322"
        iyz="-6.02164923056069E-07"
        izz="0.00134410355890926" />
    </inertial>
    <visual>
      <origin
        xyz="0 0 0"
        rpy="0 0 0" />
      <geometry>
        <mesh
          filename="package://koko_description_sevendof_kin/meshes/wrist_roll_link.STL" />
      </geometry>
      <material
        name="">
        <color
          rgba="0.792156862745098 0.819607843137255 0.933333333333333 1" />
      </material>
    </visual>
    <collision>
      <origin
        xyz="0 0 0"
        rpy="0 0 0" />
      <geometry>
        <mesh
          filename="package://koko_description_sevendof_kin/meshes/wrist_roll_link.STL" />
      </geometry>
    </collision>
  </link>
  <joint
    name="wrist_roll_joint"
    type="revolute">
    <origin
      xyz="-0.019428 -0.035935 0"
      rpy="-1.5708 -6.5009E-15 2.646" />
    <parent
      link="wrist_lift_link" />
    <child
      link="wrist_roll_link" />
    <axis
      xyz="0 0 -1" />
    <limit
      lower="-3"
      upper="3"
      effort="0"
      velocity="0" />
  </joint>
  <link
    name="ee_tracker_link">
    <inertial>
      <origin
        xyz="-1.44965915938045E-06 3.07664897831322E-05 0.0143119823117693"
        rpy="0 0 0" />
      <mass
        value="0.0852083357798641" />
      <inertia
        ixx="5.02598188485247E-05"
        ixy="3.05893908961165E-09"
        ixz="1.39673231070021E-09"
        iyy="5.05459029578684E-05"
        iyz="-1.54515047546543E-07"
        izz="8.48847132546202E-05" />
    </inertial>
    <visual>
      <origin
        xyz="0 0 0"
        rpy="0 0 0" />
      <geometry>
        <mesh
          filename="package://koko_description_sevendof_kin/meshes/ee_tracker_link.STL" />
      </geometry>
      <material
        name="">
        <color
          rgba="0.698039215686274 0.698039215686274 0.698039215686274 1" />
      </material>
    </visual>
    <collision>
      <origin
        xyz="0 0 0"
        rpy="0 0 0" />
      <geometry>
        <mesh
          filename="package://koko_description_sevendof_kin/meshes/ee_tracker_link.STL" />
      </geometry>
    </collision>
  </link>
  <joint
    name="ee_tracker_joint"
    type="fixed">
    <origin
      xyz="0 -0.0465977473524162 0.0940905126607386"
      rpy="-1.5707963267949 3.52354834015197E-05 -3.14159265358978" />
    <parent
      link="wrist_roll_link" />
    <child
      link="ee_tracker_link" />
    <axis
      xyz="0 0 0" />
  </joint>
  <link
    name="forearm_tracker_link">
    <inertial>
      <origin
        xyz="-7.74192843389088E-07 3.04089992254758E-05 0.0143118681036251"
        rpy="0 0 0" />
      <mass
        value="0.0852058022688794" />
      <inertia
        ixx="5.02600717286775E-05"
        ixy="3.55456081034346E-09"
        ixz="7.91264380028255E-10"
        iyy="5.05430652693332E-05"
        iyz="-1.5444865924116E-07"
        izz="8.48822157077333E-05" />
    </inertial>
    <visual>
      <origin
        xyz="0 0 0"
        rpy="0 0 0" />
      <geometry>
        <mesh
          filename="package://koko_description_sevendof_kin/meshes/forearm_tracker_link.STL" />
      </geometry>
      <material
        name="">
        <color
          rgba="0.698039215686274 0.698039215686274 0.698039215686274 1" />
      </material>
    </visual>
    <collision>
      <origin
        xyz="0 0 0"
        rpy="0 0 0" />
      <geometry>
        <mesh
          filename="package://koko_description_sevendof_kin/meshes/forearm_tracker_link.STL" />
      </geometry>
    </collision>
  </link>
  <joint
    name="forearm_tracker_joint"
    type="fixed">
    <origin
      xyz="0.093326996938786 -0.0683720755168485 0"
      rpy="1.57079632696237 1.57074964653677 0.310508528471775" />
    <parent
      link="forearm_link" />
    <child
      link="forearm_tracker_link" />
    <axis
      xyz="0 0 0" />
  </joint>
  <link
    name="upper_arm_tracker_link">
    <inertial>
      <origin
        xyz="-5.17594583082648E-07 3.04440494210134E-05 0.0143118437773025"
        rpy="0 0 0" />
      <mass
        value="0.0852060442329189" />
      <inertia
        ixx="5.02596761132747E-05"
        ixy="3.31551896111938E-09"
        ixz="9.86865890396396E-10"
        iyy="5.05436920555182E-05"
        iyz="-1.54429302951155E-07"
        izz="8.48824612895774E-05" />
    </inertial>
    <visual>
      <origin
        xyz="0 0 0"
        rpy="0 0 0" />
      <geometry>
        <mesh
          filename="package://koko_description_sevendof_kin/meshes/upper_arm_tracker_link.STL" />
      </geometry>
      <material
        name="">
        <color
          rgba="0.698039215686274 0.698039215686274 0.698039215686274 1" />
      </material>
    </visual>
    <collision>
      <origin
        xyz="0 0 0"
        rpy="0 0 0" />
      <geometry>
        <mesh
          filename="package://koko_description_sevendof_kin/meshes/upper_arm_tracker_link.STL" />
      </geometry>
    </collision>
  </link>
  <joint
    name="upper_arm_tracker_joint"
    type="fixed">
    <origin
      xyz="0.068372 -0.00018252 0.096543"
      rpy="1.2603 -2.2741E-05 1.5681" />
    <parent
      link="upper_arm_link" />
    <child
      link="upper_arm_tracker_link" />
    <axis
      xyz="0 0 0" />
  </joint>
  <link
    name="base_tracker_link">
    <inertial>
      <origin
        xyz="-1.0100229746457E-06 1.84420897696436E-05 0.0154315392996306"
        rpy="0 0 0" />
      <mass
        value="0.0852058039730557" />
      <inertia
        ixx="5.02595166773505E-05"
        ixy="3.4190250943531E-09"
        ixz="9.88592972729904E-10"
        iyy="5.05436854219069E-05"
        iyz="-1.54406892613585E-07"
        izz="8.48822662574294E-05" />
    </inertial>
    <visual>
      <origin
        xyz="0 0 0"
        rpy="0 0 0" />
      <geometry>
        <mesh
          filename="package://koko_description_sevendof_kin/meshes/base_tracker_link.STL" />
      </geometry>
      <material
        name="">
        <color
          rgba="0.698039215686274 0.698039215686274 0.698039215686274 1" />
      </material>
    </visual>
    <collision>
      <origin
        xyz="0 0 0"
        rpy="0 0 0" />
      <geometry>
        <mesh
          filename="package://koko_description_sevendof_kin/meshes/base_tracker_link.STL" />
      </geometry>
    </collision>
  </link>
  <joint
    name="base_tracker_joint"
    type="fixed">
    <origin
      xyz="-0.0498692449226366 -0.151716256860219 0.179829435830465"
      rpy="-0.785398286004807 -5.15847808661681E-07 1.5707968426427" />
    <parent
      link="base_link" />
    <child
      link="base_tracker_link" />
    <axis
      xyz="0 0 0" />
  </joint>
</robot>
