<robot
  name="koko_description_sevendof_kin">
  <link
    name="base_link">
    <inertial>
      <origin
        xyz="-0.00237523344929972 -0.1517165080015 0.133562829709273"
        rpy="0 0 0" />
      <mass
        value="0.210349130781402" />
      <inertia
        ixx="0.00131121369963536"
        ixy="-3.09616125638608E-09"
        ixz="0.000877219835937122"
        iyy="0.00192535968380682"
        iyz="-4.97710584568403E-09"
        izz="0.00130019808237566" />
    </inertial>
    <visual>
      <origin
        xyz="0 0 0"
        rpy="0 0 0" />
      <geometry>
        <mesh
          filename="package://koko_description_sevendof_kin/meshes/base_link.STL" />
      </geometry>
      <material
        name="">
        <color
          rgba="0.792156862745098 0.819607843137255 0.933333333333333 1" />
      </material>
    </visual>
    <collision>
      <origin
        xyz="0 0 0"
        rpy="0 0 0" />
      <geometry>
        <mesh
          filename="package://koko_description_sevendof_kin/meshes/base_link.STL" />
      </geometry>
    </collision>
  </link>
  <link
    name="shoulder_link">
    <inertial>
      <origin
        xyz="-0.00742540950524501 -2.52983663371342E-05 0.0799021977321933"
        rpy="0 0 0" />
      <mass
        value="4.06060300135281" />
      <inertia
        ixx="0.00615696534468231"
        ixy="-5.24446396802067E-07"
        ixz="-3.96039332717607E-06"
        iyy="0.00629905043020347"
        iyz="-3.51714297900969E-07"
        izz="0.00592100303296699" />
    </inertial>
    <visual>
      <origin
        xyz="0 0 0"
        rpy="0 0 0" />
      <geometry>
        <mesh
          filename="package://koko_description_sevendof_kin/meshes/shoulder_link.STL" />
      </geometry>
      <material
        name="">
        <color
          rgba="0.843137254901961 0.815686274509804 0.752941176470588 1" />
      </material>
    </visual>
    <collision>
      <origin
        xyz="0 0 0"
        rpy="0 0 0" />
      <geometry>
        <mesh
          filename="package://koko_description_sevendof_kin/meshes/shoulder_link.STL" />
      </geometry>
    </collision>
  </link>
  <joint
    name="base_roll_joint"
    type="revolute">
    <origin
      xyz="0.011376 -0.15172 0.15127"
      rpy="6.8694E-15 0.7854 4.8574E-15" />
    <parent
      link="base_link" />
    <child
      link="shoulder_link" />
    <axis
      xyz="0 0 1" />
    <limit
      lower="-1.54"
      upper="1.54"
      effort="0"
      velocity="0" />
  </joint>
  <link
    name="shoulder_lift_link">
    <inertial>
      <origin
        xyz="-0.000676420326486932 0.00184227618310823 -4.83935395090285E-08"
        rpy="0 0 0" />
      <mass
        value="0.43726174275049" />
      <inertia
        ixx="0.0010294530389637"
        ixy="-2.02400832489509E-05"
        ixz="-6.05084164956974E-07"
        iyy="0.00107940368937244"
        iyz="-8.03811502305761E-07"
        izz="0.000657528738855015" />
    </inertial>
    <visual>
      <origin
        xyz="0 0 0"
        rpy="0 0 0" />
      <geometry>
        <mesh
          filename="package://koko_description_sevendof_kin/meshes/shoulder_lift_link.STL" />
      </geometry>
      <material
        name="">
        <color
          rgba="1 0.501960784313725 0.501960784313725 1" />
      </material>
    </visual>
    <collision>
      <origin
        xyz="0 0 0"
        rpy="0 0 0" />
      <geometry>
        <mesh
          filename="package://koko_description_sevendof_kin/meshes/shoulder_lift_link.STL" />
      </geometry>
    </collision>
  </link>
  <joint
    name="shoulder_lift_joint"
    type="revolute">
    <origin
      xyz="0.01143 4.0407E-05 0.20168"
      rpy="1.5708 -0.7854 0.0035351" />
    <parent
      link="shoulder_link" />
    <child
      link="shoulder_lift_link" />
    <axis
      xyz="0 0 1" />
    <limit
      lower="-1.54"
      upper="1.54"
      effort="0"
      velocity="0" />
  </joint>
  <link
    name="upper_arm_link">
    <inertial>
      <origin
        xyz="0.00883679554596856 -2.11277498238793E-05 0.0545707151946895"
        rpy="0 0 0" />
      <mass
        value="4.20793381703838" />
      <inertia
        ixx="0.00687957299890065"
        ixy="1.68633136481853E-06"
        ixz="-0.000316043095829341"
        iyy="0.00746096471617816"
        iyz="2.452867247077E-06"
        izz="0.00648399588129982" />
    </inertial>
    <visual>
      <origin
        xyz="0 0 0"
        rpy="0 0 0" />
      <geometry>
        <mesh
          filename="package://koko_description_sevendof_kin/meshes/upper_arm_link.STL" />
      </geometry>
      <material
        name="">
        <color
          rgba="0.843137254901961 0.815686274509804 0.752941176470588 1" />
      </material>
    </visual>
    <collision>
      <origin
        xyz="0 0 0"
        rpy="0 0 0" />
      <geometry>
        <mesh
          filename="package://koko_description_sevendof_kin/meshes/upper_arm_link.STL" />
      </geometry>
    </collision>
  </link>
  <joint
    name="shoulder_roll_joint"
    type="revolute">
    <origin
      xyz="0.024593 -0.066237 0"
      rpy="1.5708 -0.0026664 0.35551" />
    <parent
      link="shoulder_lift_link" />
    <child
      link="upper_arm_link" />
    <axis
      xyz="0 0 -1" />
    <limit
      lower="-1.54"
      upper="1.54"
      effort="0"
      velocity="0" />
  </joint>
  <link
    name="upper_arm_lift_link">
    <inertial>
      <origin
        xyz="-2.23127744058971E-08 -0.00196475262570617 4.92540209175441E-05"
        rpy="0 0 0" />
      <mass
        value="0.437261171586673" />
      <inertia
        ixx="0.000657523329263176"
        ixy="5.54132204601824E-07"
        ixz="-1.90210873488973E-06"
        iyy="0.00108632892754966"
        iyz="5.19348903733127E-07"
        izz="0.00102241938881713" />
    </inertial>
    <visual>
      <origin
        xyz="0 0 0"
        rpy="0 0 0" />
      <geometry>
        <mesh
          filename="package://koko_description_sevendof_kin/meshes/upper_arm_lift_link.STL" />
      </geometry>
      <material
        name="">
        <color
          rgba="1 0.501960784313725 0.501960784313725 1" />
      </material>
    </visual>
    <collision>
      <origin
        xyz="0 0 0"
        rpy="0 0 0" />
      <geometry>
        <mesh
          filename="package://koko_description_sevendof_kin/meshes/upper_arm_lift_link.STL" />
      </geometry>
    </collision>
  </link>
  <joint
    name="elbow_lift_joint"
    type="revolute">
    <origin
      xyz="-0.01143 3.0476E-05 0.18102"
      rpy="1.3257 5.4262E-15 1.5681" />
    <parent
      link="upper_arm_link" />
    <child
      link="upper_arm_lift_link" />
    <axis
      xyz="1 0 0" />
    <limit
      lower="-1.54"
      upper="1.54"
      effort="0"
      velocity="0" />
  </joint>
  <link
    name="forearm_link">
    <inertial>
      <origin
        xyz="0.054716145055094 -0.00731386885688606 -2.50579122951233E-06"
        rpy="0 0 0" />
      <mass
        value="4.12272376366605" />
      <inertia
        ixx="0.00596487037947693"
        ixy="3.3465370854769E-05"
        ixz="-1.6520431874159E-06"
        iyy="0.00664496809496918"
        iyz="1.07356949531632E-07"
        izz="0.0067924679519881" />
    </inertial>
    <visual>
      <origin
        xyz="0 0 0"
        rpy="0 0 0" />
      <geometry>
        <mesh
          filename="package://koko_description_sevendof_kin/meshes/forearm_link.STL" />
      </geometry>
      <material
        name="">
        <color
          rgba="0.843137254901961 0.815686274509804 0.752941176470588 1" />
      </material>
    </visual>
    <collision>
      <origin
        xyz="0 0 0"
        rpy="0 0 0" />
      <geometry>
        <mesh
          filename="package://koko_description_sevendof_kin/meshes/forearm_link.STL" />
      </geometry>
    </collision>
  </link>
  <joint
    name="elbow_roll_joint"
    type="revolute">
    <origin
      xyz="0 0.073871 0"
      rpy="-1.5708 1.6307E-15 1.5708" />
    <parent
      link="upper_arm_lift_link" />
    <child
      link="forearm_link" />
    <axis
      xyz="-1 0 0" />
    <limit
      lower="-1.54"
      upper="1.54"
      effort="0"
      velocity="0" />
  </joint>
  <link
    name="wrist_lift_link">
    <inertial>
      <origin
        xyz="0.000974827037374892 0.00171170705249171 -1.58073977241102E-08"
        rpy="0 0 0" />
      <mass
        value="0.437254818113419" />
      <inertia
        ixx="0.00103675800099548"
        ixy="2.62036694525063E-05"
        ixz="-1.86750583426283E-06"
        iyy="0.00107204394916679"
        iyz="2.46663119189851E-07"
        izz="0.000657515353995076" />
    </inertial>
    <visual>
      <origin
        xyz="0 0 0"
        rpy="0 0 0" />
      <geometry>
        <mesh
          filename="package://koko_description_sevendof_kin/meshes/wrist_lift_link.STL" />
      </geometry>
      <material
        name="">
        <color
          rgba="1 0.501960784313725 0.501960784313725 1" />
      </material>
    </visual>
    <collision>
      <origin
        xyz="0 0 0"
        rpy="0 0 0" />
      <geometry>
        <mesh
          filename="package://koko_description_sevendof_kin/meshes/wrist_lift_link.STL" />
      </geometry>
    </collision>
  </link>
  <joint
    name="wrist_lift_joint"
    type="revolute">
    <origin
      xyz="0.1778 0.01143 0"
      rpy="3.1416 -1.5135E-15 -1.4604" />
    <parent
      link="forearm_link" />
    <child
      link="wrist_lift_link" />
    <axis
      xyz="0 0 1" />
    <limit
      lower="-1.54"
      upper="1.54"
      effort="0"
      velocity="0" />
  </joint>
  <link
    name="wrist_roll_link">
    <inertial>
      <origin
        xyz="-1.83989391688844E-06 -0.00351222779119642 0.0747710456248225"
        rpy="0 0 0" />
      <mass
        value="1.49779120356007" />
      <inertia
        ixx="0.00172002556020135"
        ixy="1.94219358204812E-07"
        ixz="7.8734397438316E-07"
        iyy="0.00150079733965325"
        iyz="9.7553297998922E-05"
        izz="0.00168408131286982" />
    </inertial>
    <visual>
      <origin
        xyz="0 0 0"
        rpy="0 0 0" />
      <geometry>
        <mesh
          filename="package://koko_description_sevendof_kin/meshes/wrist_roll_link.STL" />
      </geometry>
      <material
        name="">
        <color
          rgba="0.752941176470588 0.752941176470588 0.752941176470588 1" />
      </material>
    </visual>
    <collision>
      <origin
        xyz="0 0 0"
        rpy="0 0 0" />
      <geometry>
        <mesh
          filename="package://koko_description_sevendof_kin/meshes/wrist_roll_link.STL" />
      </geometry>
    </collision>
  </link>
  <joint
    name="wrist_roll_joint"
    type="revolute">
    <origin
      xyz="-0.019428 -0.035935 0"
      rpy="-1.5708 -6.5009E-15 2.646" />
    <parent
      link="wrist_lift_link" />
    <child
      link="wrist_roll_link" />
    <axis
      xyz="0 0 -1" />
    <limit
      lower="-1.54"
      upper="1.54"
      effort="0"
      velocity="0" />
  </joint>
  <link
    name="forearm_tracker_link">
    <inertial>
      <origin
        xyz="-7.74192843389088E-07 3.04089992254827E-05 0.014311868103625"
        rpy="0 0 0" />
      <mass
        value="0.0852058022688794" />
      <inertia
        ixx="5.02600717286776E-05"
        ixy="3.55456081034354E-09"
        ixz="7.91264380027647E-10"
        iyy="5.05430652693332E-05"
        iyz="-1.54448659241162E-07"
        izz="8.48822157077333E-05" />
    </inertial>
    <visual>
      <origin
        xyz="0 0 0"
        rpy="0 0 0" />
      <geometry>
        <mesh
          filename="package://koko_description_sevendof_kin/meshes/forearm_tracker_link.STL" />
      </geometry>
      <material
        name="">
        <color
          rgba="0.698039215686274 0.698039215686274 0.698039215686274 1" />
      </material>
    </visual>
    <collision>
      <origin
        xyz="0 0 0"
        rpy="0 0 0" />
      <geometry>
        <mesh
          filename="package://koko_description_sevendof_kin/meshes/forearm_tracker_link.STL" />
      </geometry>
    </collision>
  </link>
  <joint
    name="forearm_tracker_joint"
    type="fixed">
    <origin
      xyz="0.093326996938786 -0.0683720755168485 0"
      rpy="1.57079632696237 1.57074964653677 0.310508528471775" />
    <parent
      link="forearm_link" />
    <child
      link="forearm_tracker_link" />
    <axis
      xyz="0 0 0" />
  </joint>
  <link
    name="upper_arm_tracker_link">
    <inertial>
      <origin
        xyz="-1.01609301339511E-06 0.0398004449236623 0.0669412785021228"
        rpy="0 0 0" />
      <mass
        value="0.0852060442329189" />
      <inertia
        ixx="5.02596761132747E-05"
        ixy="3.31551896111993E-09"
        ixz="9.86865890528454E-10"
        iyy="5.05436920555182E-05"
        iyz="-1.5442930295115E-07"
        izz="8.48824612895774E-05" />
    </inertial>
    <visual>
      <origin
        xyz="0 0 0"
        rpy="0 0 0" />
      <geometry>
        <mesh
          filename="package://koko_description_sevendof_kin/meshes/upper_arm_tracker_link.STL" />
      </geometry>
      <material
        name="">
        <color
          rgba="0.698039215686274 0.698039215686274 0.698039215686274 1" />
      </material>
    </visual>
    <collision>
      <origin
        xyz="0 0 0"
        rpy="0 0 0" />
      <geometry>
        <mesh
          filename="package://koko_description_sevendof_kin/meshes/upper_arm_tracker_link.STL" />
      </geometry>
    </collision>
  </link>
  <joint
    name="upper_arm_tracker_joint"
    type="fixed">
    <origin
      xyz="0.0304107993735892 -7.98469833864779E-05 0.0425939383117631"
      rpy="1.26028779840761 -2.27414328887753E-05 1.56813717846785" />
    <parent
      link="upper_arm_link" />
    <child
      link="upper_arm_tracker_link" />
    <axis
      xyz="0 0 0" />
  </joint>
  <link
    name="base_tracker_link">
    <inertial>
      <origin
        xyz="-1.0100229746457E-06 1.84420897696436E-05 0.0154315392996306"
        rpy="0 0 0" />
      <mass
        value="0.0852058039730557" />
      <inertia
        ixx="5.02595166773505E-05"
        ixy="3.41902509435331E-09"
        ixz="9.88592972730249E-10"
        iyy="5.05436854219069E-05"
        iyz="-1.54406892613585E-07"
        izz="8.48822662574294E-05" />
    </inertial>
    <visual>
      <origin
        xyz="0 0 0"
        rpy="0 0 0" />
      <geometry>
        <mesh
          filename="package://koko_description_sevendof_kin/meshes/base_tracker_link.STL" />
      </geometry>
      <material
        name="">
        <color
          rgba="0.698039215686274 0.698039215686274 0.698039215686274 1" />
      </material>
    </visual>
    <collision>
      <origin
        xyz="0 0 0"
        rpy="0 0 0" />
      <geometry>
        <mesh
          filename="package://koko_description_sevendof_kin/meshes/base_tracker_link.STL" />
      </geometry>
    </collision>
  </link>
  <joint
    name="base_tracker_joint"
    type="fixed">
    <origin
      xyz="-0.0498692449226366 -0.151716256860219 0.179829435830465"
      rpy="-0.785398286004807 -5.15847808661681E-07 1.5707968426427" />
    <parent
      link="base_link" />
    <child
      link="base_tracker_link" />
    <axis
      xyz="0 0 0" />
  </joint>
</robot>
