<robot
  name="koko_description_sevendof_kin">
  <link
    name="base_link">
    <inertial>
      <origin
        xyz="0.0560024374186662 0.000189445541681321 0.0201835602327798"
        rpy="0 0 0" />
      <mass
        value="0.284612172465311" />
      <inertia
        ixx="0.000716950374478633"
        ixy="-4.58477843167977E-06"
        ixz="4.20772050305918E-06"
        iyy="0.00197711566495113"
        iyz="9.13561852910004E-07"
        izz="0.00239705630031167" />
    </inertial>
    <visual>
      <origin
        xyz="0 0 0"
        rpy="0 0 0" />
      <geometry>
        <mesh
          filename="package://koko_description_sevendof_kin/meshes/base_link.STL" />
      </geometry>
      <material
        name="">
        <color
          rgba="0.792156862745098 0.819607843137255 0.933333333333333 1" />
      </material>
    </visual>
    <collision>
      <origin
        xyz="0 0 0"
        rpy="0 0 0" />
      <geometry>
        <mesh
          filename="package://koko_description_sevendof_kin/meshes/base_link.STL" />
      </geometry>
    </collision>
  </link>
  <link
    name="shoulder_link">
    <inertial>
      <origin
        xyz="0.00434775413891728 2.01234773867243E-05 -0.0764683318824378"
        rpy="0 0 0" />
      <mass
        value="1.80901122392277" />
      <inertia
        ixx="0.00919374569832913"
        ixy="1.2736226369809E-08"
        ixz="0.000102478650618865"
        iyy="0.0087191738814553"
        iyz="3.26622166776887E-06"
        izz="0.00388062453030108" />
    </inertial>
    <visual>
      <origin
        xyz="0 0 0"
        rpy="0 0 0" />
      <geometry>
        <mesh
          filename="package://koko_description_sevendof_kin/meshes/shoulder_link.STL" />
      </geometry>
      <material
        name="">
        <color
          rgba="0.843137254901961 0.815686274509804 0.752941176470588 1" />
      </material>
    </visual>
    <collision>
      <origin
        xyz="0 0 0"
        rpy="0 0 0" />
      <geometry>
        <mesh
          filename="package://koko_description_sevendof_kin/meshes/shoulder_link.STL" />
      </geometry>
    </collision>
  </link>
  <joint
    name="base_roll_joint"
    type="revolute">
    <origin
      xyz="0 0 0.054356"
      rpy="3.1416 -2.2011E-29 0" />
    <parent
      link="base_link" />
    <child
      link="shoulder_link" />
    <axis
      xyz="0 0 1" />
    <limit
      lower="-2.3412"
      upper="3.3999"
      effort="0"
      velocity="0" />
  </joint>
  <link
    name="shoulder_lift_link">
    <inertial>
      <origin
        xyz="-5.00835590801219E-06 0.000232928456050829 -1.77451392545103E-05"
        rpy="0 0 0" />
      <mass
        value="0.388307108622635" />
      <inertia
        ixx="0.000804272985961787"
        ixy="4.84548777861769E-08"
        ixz="2.09160815704299E-06"
        iyy="0.000818260636171892"
        iyz="-1.44954778547353E-08"
        izz="0.000550840705045093" />
    </inertial>
    <visual>
      <origin
        xyz="0 0 0"
        rpy="0 0 0" />
      <geometry>
        <mesh
          filename="package://koko_description_sevendof_kin/meshes/shoulder_lift_link.STL" />
      </geometry>
      <material
        name="">
        <color
          rgba="0.792156862745098 0.819607843137255 0.933333333333333 1" />
      </material>
    </visual>
    <collision>
      <origin
        xyz="0 0 0"
        rpy="0 0 0" />
      <geometry>
        <mesh
          filename="package://koko_description_sevendof_kin/meshes/shoulder_lift_link.STL" />
      </geometry>
    </collision>
  </link>
  <joint
    name="shoulder_lift_joint"
    type="revolute">
    <origin
      xyz="-0.01143 0 -0.21082"
      rpy="-1.5708 4.4409E-16 3.1416" />
    <parent
      link="shoulder_link" />
    <child
      link="shoulder_lift_link" />
    <axis
      xyz="0 0 1" />
    <limit
      lower="-2.2944"
      upper="0"
      effort="0"
      velocity="0" />
  </joint>
  <link
    name="upper_arm_link">
    <inertial>
      <origin
        xyz="0.00526564882010383 5.32997220916154E-05 -0.0641725544925976"
        rpy="0 0 0" />
      <mass
        value="1.52396434922932" />
      <inertia
        ixx="0.00578789299619112"
        ixy="1.90247544564575E-06"
        ixz="-6.31088150382613E-05"
        iyy="0.00530315640192364"
        iyz="1.26895334967034E-06"
        izz="0.00342501474672849" />
    </inertial>
    <visual>
      <origin
        xyz="0 0 0"
        rpy="0 0 0" />
      <geometry>
        <mesh
          filename="package://koko_description_sevendof_kin/meshes/upper_arm_link.STL" />
      </geometry>
      <material
        name="">
        <color
          rgba="1 1 1 1" />
      </material>
    </visual>
    <collision>
      <origin
        xyz="0 0 0"
        rpy="0 0 0" />
      <geometry>
        <mesh
          filename="package://koko_description_sevendof_kin/meshes/upper_arm_link.STL" />
      </geometry>
    </collision>
  </link>
  <joint
    name="shoulder_roll_joint"
    type="revolute">
    <origin
      xyz="0 0.070147 -6.25E-05"
      rpy="-1.5708 1.5673 -3.1416" />
    <parent
      link="shoulder_lift_link" />
    <child
      link="upper_arm_link" />
    <axis
      xyz="0 0 1" />
    <limit
      lower="-2.6761"
      upper="2.6761"
      effort="0"
      velocity="0" />
  </joint>
  <link
    name="upper_arm_lift_link">
    <inertial>
      <origin
        xyz="9.02313812556343E-09 -0.00233330223507322 -1.63699447163213E-05"
        rpy="0 0 0" />
      <mass
        value="0.336087766639304" />
      <inertia
        ixx="0.000748389835750991"
        ixy="-4.48808711468882E-12"
        ixz="2.09357125066285E-06"
        iyy="0.000805057710272214"
        iyz="-3.6140426110768E-08"
        izz="0.000495723702697915" />
    </inertial>
    <visual>
      <origin
        xyz="0 0 0"
        rpy="0 0 0" />
      <geometry>
        <mesh
          filename="package://koko_description_sevendof_kin/meshes/upper_arm_lift_link.STL" />
      </geometry>
      <material
        name="">
        <color
          rgba="1 0.501960784313725 0.501960784313725 1" />
      </material>
    </visual>
    <collision>
      <origin
        xyz="0 0 0"
        rpy="0 0 0" />
      <geometry>
        <mesh
          filename="package://koko_description_sevendof_kin/meshes/upper_arm_lift_link.STL" />
      </geometry>
    </collision>
  </link>
  <joint
    name="elbow_lift_joint"
    type="revolute">
    <origin
      xyz="-0.01143 -4.0407E-05 -0.18056"
      rpy="-1.5708 -8.5189E-16 -3.1381" />
    <parent
      link="upper_arm_link" />
    <child
      link="upper_arm_lift_link" />
    <axis
      xyz="0 0 1" />
    <limit
      lower="-2.2944"
      upper="0"
      effort="0"
      velocity="0" />
  </joint>
  <link
    name="forearm_link">
    <inertial>
      <origin
        xyz="0.00527282221737166 2.49933774366662E-05 -0.0641725728670135"
        rpy="0 0 0" />
      <mass
        value="1.52407731945949" />
      <inertia
        ixx="0.00578819901338735"
        ixy="5.17112689441557E-07"
        ixz="-6.28277548639294E-05"
        iyy="0.00530319085441348"
        iyz="1.13324488016115E-06"
        izz="0.003425664708797" />
    </inertial>
    <visual>
      <origin
        xyz="0 0 0"
        rpy="0 0 0" />
      <geometry>
        <mesh
          filename="package://koko_description_sevendof_kin/meshes/forearm_link.STL" />
      </geometry>
      <material
        name="">
        <color
          rgba="1 1 1 1" />
      </material>
    </visual>
    <collision>
      <origin
        xyz="0 0 0"
        rpy="0 0 0" />
      <geometry>
        <mesh
          filename="package://koko_description_sevendof_kin/meshes/forearm_link.STL" />
      </geometry>
    </collision>
  </link>
  <joint
    name="elbow_roll_joint"
    type="revolute">
    <origin
      xyz="0 0.070147 -6.25E-05"
      rpy="1.5708 -1.5708 0" />
    <parent
      link="upper_arm_lift_link" />
    <child
      link="forearm_link" />
    <axis
      xyz="0 0 1" />
    <limit
      lower="-2.6761"
      upper="2.6761"
      effort="0"
      velocity="0" />
  </joint>
  <link
    name="wrist_lift_link">
    <inertial>
      <origin
        xyz="-5.00411762238695E-06 0.000232915119171451 -1.7745294652205E-05"
        rpy="0 0 0" />
      <mass
        value="0.388307109282073" />
      <inertia
        ixx="0.000804243894521224"
        ixy="4.84475071376708E-08"
        ixz="2.09169568931598E-06"
        iyy="0.000818231333102983"
        iyz="-1.44598250552623E-08"
        izz="0.000550840471771904" />
    </inertial>
    <visual>
      <origin
        xyz="0 0 0"
        rpy="0 0 0" />
      <geometry>
        <mesh
          filename="package://koko_description_sevendof_kin/meshes/wrist_lift_link.STL" />
      </geometry>
      <material
        name="">
        <color
          rgba="0.792156862745098 0.819607843137255 0.933333333333333 1" />
      </material>
    </visual>
    <collision>
      <origin
        xyz="0 0 0"
        rpy="0 0 0" />
      <geometry>
        <mesh
          filename="package://koko_description_sevendof_kin/meshes/wrist_lift_link.STL" />
      </geometry>
    </collision>
  </link>
  <joint
    name="wrist_lift_joint"
    type="revolute">
    <origin
      xyz="-0.01143 0 -0.18056"
      rpy="-1.5708 6.6613E-16 -3.1416" />
    <parent
      link="forearm_link" />
    <child
      link="wrist_lift_link" />
    <axis
      xyz="0 0 1" />
    <limit
      lower="-2.2944"
      upper="0"
      effort="0"
      velocity="0" />
  </joint>
  <link
    name="wrist_roll_link">
    <inertial>
      <origin
        xyz="-7.00549073777146E-05 2.51271935266528E-05 -0.0523671181891625"
        rpy="0 0 0" />
      <mass
        value="0.247109755986862" />
      <inertia
        ixx="0.000916887873827195"
        ixy="-6.04547948816719E-08"
        ixz="1.67961333682177E-06"
        iyy="0.000877268801167164"
        iyz="5.6417290777793E-07"
        izz="0.000293333065172454" />
    </inertial>
    <visual>
      <origin
        xyz="0 0 0"
        rpy="0 0 0" />
      <geometry>
        <mesh
          filename="package://koko_description_sevendof_kin/meshes/wrist_roll_link.STL" />
      </geometry>
      <material
        name="">
        <color
          rgba="0.792156862745098 0.819607843137255 0.933333333333333 1" />
      </material>
    </visual>
    <collision>
      <origin
        xyz="0 0 0"
        rpy="0 0 0" />
      <geometry>
        <mesh
          filename="package://koko_description_sevendof_kin/meshes/wrist_roll_link.STL" />
      </geometry>
    </collision>
  </link>
  <joint
    name="wrist_roll_joint"
    type="revolute">
    <origin
      xyz="0 0.070147 -6.25E-05"
      rpy="-1.5708 -2.4803E-15 -3.1416" />
    <parent
      link="wrist_lift_link" />
    <child
      link="wrist_roll_link" />
    <axis
      xyz="0 0 1" />
    <limit
      lower="-2.6761"
      upper="2.6761"
      effort="0"
      velocity="0" />
  </joint>
  <link
    name="ee_tracker_link">
    <inertial>
      <origin
        xyz="-4.73940065248701E-07 3.04586797140738E-05 0.0143118417239115"
        rpy="0 0 0" />
      <mass
        value="0.0852058039712401" />
      <inertia
        ixx="5.0259516630547E-05"
        ixy="3.41903744941637E-09"
        ixz="9.8857833284579E-10"
        iyy="5.05436854509982E-05"
        iyz="-1.54406890921037E-07"
        izz="8.48822662474321E-05" />
    </inertial>
    <visual>
      <origin
        xyz="0 0 0"
        rpy="0 0 0" />
      <geometry>
        <mesh
          filename="package://koko_description_sevendof_kin/meshes/ee_tracker_link.STL" />
      </geometry>
      <material
        name="">
        <color
          rgba="0.698039215686274 0.698039215686274 0.698039215686274 1" />
      </material>
    </visual>
    <collision>
      <origin
        xyz="0 0 0"
        rpy="0 0 0" />
      <geometry>
        <mesh
          filename="package://koko_description_sevendof_kin/meshes/ee_tracker_link.STL" />
      </geometry>
    </collision>
  </link>
  <joint
    name="ee_tracker_joint"
    type="fixed">
    <origin
      xyz="0.046598 0 -0.063817"
      rpy="1.5708 -3.5235E-05 1.5708" />
    <parent
      link="wrist_roll_link" />
    <child
      link="ee_tracker_link" />
    <axis
      xyz="0 0 0" />
  </joint>
  <link
    name="forearm_tracker_link">
    <inertial>
      <origin
        xyz="-4.73830448044499E-07 3.04661652350546E-05 0.0143118347178398"
        rpy="0 0 0" />
      <mass
        value="0.0852058014578218" />
      <inertia
        ixx="5.02595074997048E-05"
        ixy="3.4435026332835E-09"
        ixz="9.88250535480481E-10"
        iyy="5.05436666423682E-05"
        iyz="-1.54400221407407E-07"
        izz="8.48822330921912E-05" />
    </inertial>
    <visual>
      <origin
        xyz="0 0 0"
        rpy="0 0 0" />
      <geometry>
        <mesh
          filename="package://koko_description_sevendof_kin/meshes/forearm_tracker_link.STL" />
      </geometry>
      <material
        name="">
        <color
          rgba="0.698039215686274 0.698039215686274 0.698039215686274 1" />
      </material>
    </visual>
    <collision>
      <origin
        xyz="0 0 0"
        rpy="0 0 0" />
      <geometry>
        <mesh
          filename="package://koko_description_sevendof_kin/meshes/forearm_tracker_link.STL" />
      </geometry>
    </collision>
  </link>
  <joint
    name="forearm_tracker_joint"
    type="fixed">
    <origin
      xyz="0.0687486075198113 2.87912553707526E-05 -0.0962935677600952"
      rpy="-1.88130485518218 2.27414328835253E-05 -1.57080362425475" />
    <parent
      link="forearm_link" />
    <child
      link="forearm_tracker_link" />
    <axis
      xyz="0 0 0" />
  </joint>
  <link
    name="upper_arm_tracker_link">
    <inertial>
      <origin
        xyz="-1.19505712214973E-06 3.05223737283589E-05 0.0143119706010131"
        rpy="0 0 0" />
      <mass
        value="0.0852087902897732" />
      <inertia
        ixx="5.02595864956216E-05"
        ixy="3.39166062366786E-09"
        ixz="1.48676133787704E-09"
        iyy="5.05469592107743E-05"
        iyz="-1.5446605587756E-07"
        izz="8.48854441225334E-05" />
    </inertial>
    <visual>
      <origin
        xyz="0 0 0"
        rpy="0 0 0" />
      <geometry>
        <mesh
          filename="package://koko_description_sevendof_kin/meshes/upper_arm_tracker_link.STL" />
      </geometry>
      <material
        name="">
        <color
          rgba="0.698039215686274 0.698039215686274 0.698039215686274 1" />
      </material>
    </visual>
    <collision>
      <origin
        xyz="0 0 0"
        rpy="0 0 0" />
      <geometry>
        <mesh
          filename="package://koko_description_sevendof_kin/meshes/upper_arm_tracker_link.STL" />
      </geometry>
    </collision>
  </link>
  <joint
    name="upper_arm_tracker_joint"
    type="fixed">
    <origin
      xyz="0.0687480716074886 0.000271826226759544 -0.0962935663002703"
      rpy="-1.88130485518218 2.2741432881685E-05 -1.56726848834151" />
    <parent
      link="upper_arm_link" />
    <child
      link="upper_arm_tracker_link" />
    <axis
      xyz="0 0 0" />
  </joint>
  <link
    name="base_tracker_link">
    <inertial>
      <origin
        xyz="-4.7347340514925E-07 3.04616810627573E-05 0.0143118364997656"
        rpy="0 0 0" />
      <mass
        value="0.0852057942640298" />
      <inertia
        ixx="5.0259498883008E-05"
        ixy="3.42092835535841E-09"
        ixz="9.8727999328487E-10"
        iyy="5.05436695272946E-05"
        iyz="-1.54423407632223E-07"
        izz="8.48822557420874E-05" />
    </inertial>
    <visual>
      <origin
        xyz="0 0 0"
        rpy="0 0 0" />
      <geometry>
        <mesh
          filename="package://koko_description_sevendof_kin/meshes/base_tracker_link.STL" />
      </geometry>
      <material
        name="">
        <color
          rgba="0.698039215686274 0.698039215686274 0.698039215686274 1" />
      </material>
    </visual>
    <collision>
      <origin
        xyz="0 0 0"
        rpy="0 0 0" />
      <geometry>
        <mesh
          filename="package://koko_description_sevendof_kin/meshes/base_tracker_link.STL" />
      </geometry>
    </collision>
  </link>
  <joint
    name="base_tracker_joint"
    type="fixed">
    <origin
      xyz="-0.0646197009318908 0 0.0403859991257779"
      rpy="-1.57079632679489 -3.56673679882293E-18 1.57079632679489" />
    <parent
      link="base_link" />
    <child
      link="base_tracker_link" />
    <axis
      xyz="0 0 0" />
  </joint>
  <link
    name="gripper_link">
    <inertial>
      <origin
        xyz="-7.00549073506807E-05 2.51271935254316E-05 -0.052367118189184"
        rpy="0 0 0" />
      <mass
        value="0.047109755986862" />
      <inertia
        ixx="0.000916887873826385"
        ixy="-6.04547948818479E-08"
        ixz="0.6796133363069E-06"
        iyy="0.000877268801166351"
        iyz="0.64172907801915E-07"
        izz="0.000293333065172452" />
    </inertial>
    <visual>
      <origin
        xyz="0 0 0"
        rpy="0 0 0" />
      <geometry>
        <mesh
          filename="package://koko_description_sevendof_dyn/meshes/wrist_roll_link.STL" />
      </geometry>
      <material
        name="">
        <color
          rgba="0.792156862745098 0.819607843137255 0.933333333333333 1" />
      </material>
    </visual>
    <collision>
      <origin
        xyz="0 0 0"
        rpy="0 0 0" />
      <geometry>
        <mesh
          filename="package://koko_description_sevendof_dyn/meshes/wrist_roll_link.STL" />
      </geometry>
    </collision>
  </link>
  <joint
    name="gripper_joint"
    type="revolute">
    <origin
      xyz="0 0.070147 -6.25E-05"
      rpy="-1.5708 -2.4803E-15 -3.1416" />
    <parent
      link="wrist_roll_link" />
    <child
      link="gripper_link" />
    <axis
      xyz="0 0 1" />
    <limit
      lower="-2.6761"
      upper="2.6761"
      effort="0"
      velocity="0" />
  </joint>
</robot>
