<robot
  name="koko_description_sevendof_kin">
  <link
    name="base_link">
    <inertial>
      <origin
        xyz="0.012870283424599 -0.146460771615818 0.201507269698043"
        rpy="0 0 0" />
      <mass
        value="5.30617493719281" />
      <inertia
        ixx="0.174648623457956"
        ixy="-0.0181596573247313"
        ixz="0.00377485804672849"
        iyy="0.162314368906565"
        iyz="-0.0318169278276485"
        izz="0.0830686215437385" />
    </inertial>
    <visual>
      <origin
        xyz="0 0 0"
        rpy="0 0 0" />
      <geometry>
        <mesh
          filename="package://koko_description_sevendof_kin/meshes/base_link.STL" />
      </geometry>
      <material
        name="">
        <color
          rgba="0.792156862745098 0.819607843137255 0.933333333333333 1" />
      </material>
    </visual>
    <collision>
      <origin
        xyz="0 0 0"
        rpy="0 0 0" />
      <geometry>
        <mesh
          filename="package://koko_description_sevendof_kin/meshes/base_link.STL" />
      </geometry>
    </collision>
  </link>
  <link
    name="shoulder_link">
    <inertial>
      <origin
        xyz="-0.0051832519269859 -1.10570459971315E-06 0.0778839085515859"
        rpy="0 0 0" />
      <mass
        value="2.01422165272683" />
      <inertia
        ixx="0.0104340077355253"
        ixy="1.28206988237664E-06"
        ixz="0.000187295521557691"
        iyy="0.00992174205669081"
        iyz="-3.07483957897016E-06"
        izz="0.00452466905504524" />
    </inertial>
    <visual>
      <origin
        xyz="0 0 0"
        rpy="0 0 0" />
      <geometry>
        <mesh
          filename="package://koko_description_sevendof_kin/meshes/shoulder_link.STL" />
      </geometry>
      <material
        name="">
        <color
          rgba="0.698039215686274 0.698039215686274 0.698039215686274 1" />
      </material>
    </visual>
    <collision>
      <origin
        xyz="0 0 0"
        rpy="0 0 0" />
      <geometry>
        <mesh
          filename="package://koko_description_sevendof_kin/meshes/shoulder_link.STL" />
      </geometry>
    </collision>
  </link>
  <joint
    name="base_roll_joint"
    type="continuous">
    <origin
      xyz="0.090179 -0.090805 0.21216"
      rpy="6.8385E-15 0.7854 4.8356E-15" />
    <parent
      link="base_link" />
    <child
      link="shoulder_link" />
    <axis
      xyz="0 0 1" />
  </joint>
  <link
    name="shoulder_lift_link">
    <inertial>
      <origin
        xyz="8.56635811739281E-05 0.000106586138373777 -2.98460660119737E-06"
        rpy="0 0 0" />
      <mass
        value="0.491670750547076" />
      <inertia
        ixx="0.00108091489195499"
        ixy="-6.67471059732482E-06"
        ixz="-6.13251629270335E-07"
        iyy="0.00110225855459191"
        iyz="-9.05602515792439E-07"
        izz="0.000715450958001597" />
    </inertial>
    <visual>
      <origin
        xyz="0 0 0"
        rpy="0 0 0" />
      <geometry>
        <mesh
          filename="package://koko_description_sevendof_kin/meshes/shoulder_lift_link.STL" />
      </geometry>
      <material
        name="">
        <color
          rgba="1 1 1 1" />
      </material>
    </visual>
    <collision>
      <origin
        xyz="0 0 0"
        rpy="0 0 0" />
      <geometry>
        <mesh
          filename="package://koko_description_sevendof_kin/meshes/shoulder_lift_link.STL" />
      </geometry>
    </collision>
  </link>
  <joint
    name="shoulder_lift_joint"
    type="continuous">
    <origin
      xyz="0.01143 4.0407E-05 0.21082"
      rpy="1.5708 -0.7854 0.0035351" />
    <parent
      link="shoulder_link" />
    <child
      link="shoulder_lift_link" />
    <axis
      xyz="0 0 1" />
  </joint>
  <link
    name="upper_arm_link">
    <inertial>
      <origin
        xyz="0.00609755693079939 -3.88093976420034E-05 0.0608281229321002"
        rpy="0 0 0" />
      <mass
        value="1.7476491152195" />
      <inertia
        ixx="0.00721843182930814"
        ixy="-1.39149269412178E-06"
        ixz="2.78269700907493E-06"
        iyy="0.00668693844103352"
        iyz="5.45799304460306E-06"
        izz="0.00408417542530308" />
    </inertial>
    <visual>
      <origin
        xyz="0 0 0"
        rpy="0 0 0" />
      <geometry>
        <mesh
          filename="package://koko_description_sevendof_kin/meshes/upper_arm_link.STL" />
      </geometry>
      <material
        name="">
        <color
          rgba="1 1 1 1" />
      </material>
    </visual>
    <collision>
      <origin
        xyz="0 0 0"
        rpy="0 0 0" />
      <geometry>
        <mesh
          filename="package://koko_description_sevendof_kin/meshes/upper_arm_link.STL" />
      </geometry>
    </collision>
  </link>
  <joint
    name="shoulder_roll_joint"
    type="continuous">
    <origin
      xyz="0.024593 -0.066237 0"
      rpy="1.5708 -0.0026664 0.35551" />
    <parent
      link="shoulder_lift_link" />
    <child
      link="upper_arm_link" />
    <axis
      xyz="0 0 -1" />
  </joint>
  <link
    name="upper_arm_lift_link">
    <inertial>
      <origin
        xyz="8.84356730235791E-05 0.000101387574038353 -3.00231459993139E-06"
        rpy="0 0 0" />
      <mass
        value="0.49109459100815" />
      <inertia
        ixx="0.00107947675103789"
        ixy="-2.63713535414869E-06"
        ixz="-1.86177709726168E-06"
        iyy="0.00110224777822463"
        iyz="-8.57651136241823E-07"
        izz="0.000713962570116537" />
    </inertial>
    <visual>
      <origin
        xyz="0 0 0"
        rpy="0 0 0" />
      <geometry>
        <mesh
          filename="package://koko_description_sevendof_kin/meshes/upper_arm_lift_link.STL" />
      </geometry>
      <material
        name="">
        <color
          rgba="1 1 1 1" />
      </material>
    </visual>
    <collision>
      <origin
        xyz="0 0 0"
        rpy="0 0 0" />
      <geometry>
        <mesh
          filename="package://koko_description_sevendof_kin/meshes/upper_arm_lift_link.STL" />
      </geometry>
    </collision>
  </link>
  <joint
    name="elbow_lift_joint"
    type="continuous">
    <origin
      xyz="-0.01143 3.0477E-05 0.18102"
      rpy="-1.5708 -0.3555 -0.0026664" />
    <parent
      link="upper_arm_link" />
    <child
      link="upper_arm_lift_link" />
    <axis
      xyz="0 0 1" />
  </joint>
  <link
    name="forearm_link">
    <inertial>
      <origin
        xyz="0.00609794820759607 -3.45327431294229E-05 0.0632167601388055"
        rpy="0 0 0" />
      <mass
        value="1.74772059406253" />
      <inertia
        ixx="0.00717580641499899"
        ixy="-1.61087769378131E-06"
        ixz="-3.38766786020847E-06"
        iyy="0.00664405421051897"
        iyz="5.38563822337051E-06"
        izz="0.00408394973893498" />
    </inertial>
    <visual>
      <origin
        xyz="0 0 0"
        rpy="0 0 0" />
      <geometry>
        <mesh
          filename="package://koko_description_sevendof_kin/meshes/forearm_link.STL" />
      </geometry>
      <material
        name="">
        <color
          rgba="0.698039215686274 0.698039215686274 0.698039215686274 1" />
      </material>
    </visual>
    <collision>
      <origin
        xyz="0 0 0"
        rpy="0 0 0" />
      <geometry>
        <mesh
          filename="package://koko_description_sevendof_kin/meshes/forearm_link.STL" />
      </geometry>
    </collision>
  </link>
  <joint
    name="elbow_roll_joint"
    type="continuous">
    <origin
      xyz="0.0077845 -0.070225 0"
      rpy="1.5708 -0.002515 0.1104" />
    <parent
      link="upper_arm_lift_link" />
    <child
      link="forearm_link" />
    <axis
      xyz="0 0 -1" />
  </joint>
  <link
    name="forearm_tracker_link">
    <inertial>
      <origin
        xyz="-7.7444425561346E-07 3.04089104029362E-05 0.014311867902741"
        rpy="0 0 0" />
      <mass
        value="0.0852058013520833" />
      <inertia
        ixx="5.02600713329448E-05"
        ixy="3.55475355543217E-09"
        ixz="7.91680266801643E-10"
        iyy="5.05430644100967E-05"
        iyz="-1.54448510968005E-07"
        izz="8.48822151046848E-05" />
    </inertial>
    <visual>
      <origin
        xyz="0 0 0"
        rpy="0 0 0" />
      <geometry>
        <mesh
          filename="package://koko_description_sevendof_kin/meshes/forearm_tracker_link.STL" />
      </geometry>
      <material
        name="">
        <color
          rgba="0.698039215686274 0.698039215686274 0.698039215686274 1" />
      </material>
    </visual>
    <collision>
      <origin
        xyz="0 0 0"
        rpy="0 0 0" />
      <geometry>
        <mesh
          filename="package://koko_description_sevendof_kin/meshes/forearm_tracker_link.STL" />
      </geometry>
    </collision>
  </link>
  <joint
    name="forearm_tracker_joint"
    type="fixed">
    <origin
      xyz="0.068372 -0.00017216 0.096543"
      rpy="1.2603 -4.4448E-05 1.5683" />
    <parent
      link="forearm_link" />
    <child
      link="forearm_tracker_link" />
    <axis
      xyz="0 0 0" />
  </joint>
  <link
    name="wrist_lift_link">
    <inertial>
      <origin
        xyz="0.000127836164895201 3.90137187457479E-05 -2.99280940935232E-06"
        rpy="0 0 0" />
      <mass
        value="0.491088159416964" />
      <inertia
        ixx="0.00108469359213903"
        ixy="9.48558790038613E-06"
        ixz="-1.9494510626206E-06"
        iyy="0.00109703339169181"
        iyz="1.8505189797619E-07"
        izz="0.000713962888794944" />
    </inertial>
    <visual>
      <origin
        xyz="0 0 0"
        rpy="0 0 0" />
      <geometry>
        <mesh
          filename="package://koko_description_sevendof_kin/meshes/wrist_lift_link.STL" />
      </geometry>
      <material
        name="">
        <color
          rgba="1 1 1 1" />
      </material>
    </visual>
    <collision>
      <origin
        xyz="0 0 0"
        rpy="0 0 0" />
      <geometry>
        <mesh
          filename="package://koko_description_sevendof_kin/meshes/wrist_lift_link.STL" />
      </geometry>
    </collision>
  </link>
  <joint
    name="wrist_lift_joint"
    type="continuous">
    <origin
      xyz="-0.0114299638605432 2.8746733649887E-05 0.181015691664515"
      rpy="-1.5707963267949 -0.110406053363127 -0.00251502707069052" />
    <parent
      link="forearm_link" />
    <child
      link="wrist_lift_link" />
    <axis
      xyz="0 0 1" />
  </joint>
  <link
    name="wrist_link">
    <inertial>
      <origin
        xyz="-0.000126163570522142 0.0433325381210396 0.0224239719688318"
        rpy="0 0 0" />
      <mass
        value="0.196389984697673" />
      <inertia
        ixx="0.000228576769838943"
        ixy="-5.49844066992486E-07"
        ixz="-5.71600741911434E-07"
        iyy="0.000212235873580426"
        iyz="-8.39385834294632E-05"
        izz="0.000234824588419469" />
    </inertial>
    <visual>
      <origin
        xyz="0 0 0"
        rpy="0 0 0" />
      <geometry>
        <mesh
          filename="package://koko_description_sevendof_kin/meshes/wrist_link.STL" />
      </geometry>
      <material
        name="">
        <color
          rgba="0.498039215686275 0.498039215686275 0.498039215686275 1" />
      </material>
    </visual>
    <collision>
      <origin
        xyz="0 0 0"
        rpy="0 0 0" />
      <geometry>
        <mesh
          filename="package://koko_description_sevendof_kin/meshes/wrist_link.STL" />
      </geometry>
    </collision>
  </link>
  <joint
    name="wrist_joint"
    type="continuous">
    <origin
      xyz="-0.0115762892877892 -0.0214116625791075 0"
      rpy="1.62543589699027E-15 -1.18308141061618E-15 2.64595360386185" />
    <parent
      link="wrist_lift_link" />
    <child
      link="wrist_link" />
    <axis
      xyz="0 -1 0" />
  </joint>
  <link
    name="ee_tracker_link">
    <inertial>
      <origin
        xyz="-1.43305547234407E-06 3.07686086425812E-05 0.0143119732879843"
        rpy="0 0 0" />
      <mass
        value="0.0852083038792347" />
      <inertia
        ixx="5.02597890613365E-05"
        ixy="3.05566589570854E-09"
        ixz="1.41676664956147E-09"
        iyy="5.05458638065493E-05"
        iyz="-1.54535044158342E-07"
        izz="8.4884681388761E-05" />
    </inertial>
    <visual>
      <origin
        xyz="0 0 0"
        rpy="0 0 0" />
      <geometry>
        <mesh
          filename="package://koko_description_sevendof_kin/meshes/ee_tracker_link.STL" />
      </geometry>
      <material
        name="">
        <color
          rgba="0.698039215686274 0.698039215686274 0.698039215686274 1" />
      </material>
    </visual>
    <collision>
      <origin
        xyz="0 0 0"
        rpy="0 0 0" />
      <geometry>
        <mesh
          filename="package://koko_description_sevendof_kin/meshes/ee_tracker_link.STL" />
      </geometry>
    </collision>
  </link>
  <joint
    name="ee_tracker_joint"
    type="fixed">
    <origin
      xyz="0 0.0796100008691862 0.058269700931892"
      rpy="1.09287578986539E-15 4.52676091056148E-15 3.52354834016303E-05" />
    <parent
      link="wrist_link" />
    <child
      link="ee_tracker_link" />
    <axis
      xyz="0 0 0" />
  </joint>
  <link
    name="catcher_link">
    <inertial>
      <origin
        xyz="5.81255052978236E-08 0.000436410728653802 0.00976103013063148"
        rpy="0 0 0" />
      <mass
        value="0.210387685533954" />
      <inertia
        ixx="0.000371032450273061"
        ixy="-8.08814210660857E-10"
        ixz="-4.14231480035706E-10"
        iyy="0.000431860327228922"
        iyz="-4.9925897640707E-06"
        izz="0.000730878214149319" />
    </inertial>
    <visual>
      <origin
        xyz="0 0 0"
        rpy="0 0 0" />
      <geometry>
        <mesh
          filename="package://koko_description_sevendof_kin/meshes/catcher_link.STL" />
      </geometry>
      <material
        name="">
        <color
          rgba="0.792156862745098 0.819607843137255 0.933333333333333 1" />
      </material>
    </visual>
    <collision>
      <origin
        xyz="0 0 0"
        rpy="0 0 0" />
      <geometry>
        <mesh
          filename="package://koko_description_sevendof_kin/meshes/catcher_link.STL" />
      </geometry>
    </collision>
  </link>
  <joint
    name="catcher_joint"
    type="fixed">
    <origin
      xyz="0 0.11096 -0.0318679796126602"
      rpy="1.5707963267949 -1.5707963267949 -3.14159265358979" />
    <parent
      link="wrist_link" />
    <child
      link="catcher_link" />
    <axis
      xyz="0 0 0" />
  </joint>
  <link
    name="upper_arm_tracker_link">
    <inertial>
      <origin
        xyz="-6.40073109958728E-07 3.14463846542712E-05 0.0154315412706681"
        rpy="0 0 0" />
      <mass
        value="0.0852060436498746" />
      <inertia
        ixx="5.02596610035676E-05"
        ixy="2.59830198492803E-09"
        ixz="1.37724964437226E-09"
        iyy="5.05437060521012E-05"
        iyz="-1.54426226404352E-07"
        izz="8.48824603298151E-05" />
    </inertial>
    <visual>
      <origin
        xyz="0 0 0"
        rpy="0 0 0" />
      <geometry>
        <mesh
          filename="package://koko_description_sevendof_kin/meshes/upper_arm_tracker_link.STL" />
      </geometry>
      <material
        name="">
        <color
          rgba="0.698039215686274 0.698039215686274 0.698039215686274 1" />
      </material>
    </visual>
    <collision>
      <origin
        xyz="0 0 0"
        rpy="0 0 0" />
      <geometry>
        <mesh
          filename="package://koko_description_sevendof_kin/meshes/upper_arm_tracker_link.STL" />
      </geometry>
    </collision>
  </link>
  <joint
    name="upper_arm_tracker_joint"
    type="fixed">
    <origin
      xyz="0.0673059857243459 -0.000179630611320147 0.0961996133169819"
      rpy="1.26028690822204 0.00238258736259419 1.56736533514145" />
    <parent
      link="upper_arm_link" />
    <child
      link="upper_arm_tracker_link" />
    <axis
      xyz="0 0 0" />
  </joint>
  <link
    name="base_tracker_link">
    <inertial>
      <origin
        xyz="-4.78839169260059E-07 3.04625040352391E-05 0.0154315278303753"
        rpy="0 0 0" />
      <mass
        value="0.0852057940282606" />
      <inertia
        ixx="5.02594988518076E-05"
        ixy="3.42114167052734E-09"
        ixz="9.87408726525647E-10"
        iyy="5.05436689038578E-05"
        iyz="-1.54423368123639E-07"
        izz="8.48822550106641E-05" />
    </inertial>
    <visual>
      <origin
        xyz="0 0 0"
        rpy="0 0 0" />
      <geometry>
        <mesh
          filename="package://koko_description_sevendof_kin/meshes/base_tracker_link.STL" />
      </geometry>
      <material
        name="">
        <color
          rgba="0.698039215686274 0.698039215686274 0.698039215686274 1" />
      </material>
    </visual>
    <collision>
      <origin
        xyz="0 0 0"
        rpy="0 0 0" />
      <geometry>
        <mesh
          filename="package://koko_description_sevendof_kin/meshes/base_tracker_link.STL" />
      </geometry>
    </collision>
  </link>
  <joint
    name="base_tracker_joint"
    type="fixed">
    <origin
      xyz="0.035399 -0.090805 0.24718"
      rpy="-0.7854 6.123E-17 1.5708" />
    <parent
      link="base_link" />
    <child
      link="base_tracker_link" />
    <axis
      xyz="0 0 0" />
  </joint>
  <link
    name="kinect_link">
    <inertial>
      <origin
        xyz="-0.0957642293220483 0.0240703125029598 -0.0159206435563999"
        rpy="0 0 0" />
      <mass
        value="0.141022435513688" />
      <inertia
        ixx="0.000104849169192228"
        ixy="-4.05149090254294E-06"
        ixz="2.53072301656499E-06"
        iyy="0.000592694473182305"
        iyz="2.36317515617587E-05"
        izz="0.000588007356245907" />
    </inertial>
    <visual>
      <origin
        xyz="0 0 0"
        rpy="0 0 0" />
      <geometry>
        <mesh
          filename="package://koko_description_sevendof_kin/meshes/kinect_link.STL" />
      </geometry>
      <material
        name="">
        <color
          rgba="0.101960784313725 0.101960784313725 0.101960784313725 1" />
      </material>
    </visual>
    <collision>
      <origin
        xyz="0 0 0"
        rpy="0 0 0" />
      <geometry>
        <mesh
          filename="package://koko_description_sevendof_kin/meshes/kinect_link.STL" />
      </geometry>
    </collision>
  </link>
  <joint
    name="kinect_joint"
    type="fixed">
    <origin
      xyz="0.0296663032719453 0.0534280083246517 0.680719999999998"
      rpy="-1.5707963267949 -1.5707963267949 -1.5707963267949" />
    <parent
      link="base_link" />
    <child
      link="kinect_link" />
    <axis
      xyz="0 0 0" />
  </joint>
</robot>