<robot
  name="koko_description_sevendof_kin">
  <link
    name="base_link">
    <inertial>
      <origin
        xyz="0.0636321357697409 -0.133866750511743 0.168051977033699"
        rpy="0 0 0" />
      <mass
        value="1.85567741361014" />
      <inertia
        ixx="0.0471658177482477"
        ixy="-0.00159312002637196"
        ixz="0.00607780252519082"
        iyy="0.0415108487642267"
        iyz="0.0046861274106972"
        izz="0.0158558120488083" />
    </inertial>
    <visual>
      <origin
        xyz="0 0 0"
        rpy="0 0 0" />
      <geometry>
        <mesh
          filename="package://koko_description_sevendof_kin/meshes/base_link.STL" />
      </geometry>
      <material
        name="">
        <color
          rgba="0.792156862745098 0.819607843137255 0.933333333333333 1" />
      </material>
    </visual>
    <collision>
      <origin
        xyz="0 0 0"
        rpy="0 0 0" />
      <geometry>
        <mesh
          filename="package://koko_description_sevendof_kin/meshes/base_link.STL" />
      </geometry>
    </collision>
  </link>
  <link
    name="shoulder_link">
    <inertial>
      <origin
        xyz="0.00434342559631115 1.27124870746842E-05 -0.0764609376252023"
        rpy="0 0 0" />
      <mass
        value="1.80875740468166" />
      <inertia
        ixx="0.00919231463733895"
        ixy="4.24505063115864E-07"
        ixz="0.000102004725397679"
        iyy="0.00871814222030842"
        iyz="2.55514959053428E-06"
        izz="0.0038795627920278" />
    </inertial>
    <visual>
      <origin
        xyz="0 0 0"
        rpy="0 0 0" />
      <geometry>
        <mesh
          filename="package://koko_description_sevendof_kin/meshes/shoulder_link.STL" />
      </geometry>
      <material
        name="">
        <color
          rgba="0.843137254901961 0.815686274509804 0.752941176470588 1" />
      </material>
    </visual>
    <collision>
      <origin
        xyz="0 0 0"
        rpy="0 0 0" />
      <geometry>
        <mesh
          filename="package://koko_description_sevendof_kin/meshes/shoulder_link.STL" />
      </geometry>
    </collision>
  </link>
  <joint
    name="base_roll_joint"
    type="revolute">
    <origin
      xyz="0.090179 -0.090805 0.21216"
      rpy="-3.1416 -0.7854 3.1416" />
    <parent
      link="base_link" />
    <child
      link="shoulder_link" />
    <axis
      xyz="0 0 1" />
    <limit
      lower="-2.3412"
      upper="3.3999"
      effort="0"
      velocity="0" />
  </joint>
  <link
    name="shoulder_lift_link">
    <inertial>
      <origin
        xyz="-5.00863820046549E-06 0.000232929106567359 -1.77456677609156E-05"
        rpy="0 0 0" />
      <mass
        value="0.388307110624734" />
      <inertia
        ixx="0.000804243248430512"
        ixy="4.84530698441972E-08"
        ixz="2.09161175347685E-06"
        iyy="0.000818230979540552"
        iyz="-1.44996116747813E-08"
        izz="0.000550840787833645" />
    </inertial>
    <visual>
      <origin
        xyz="0 0 0"
        rpy="0 0 0" />
      <geometry>
        <mesh
          filename="package://koko_description_sevendof_kin/meshes/shoulder_lift_link.STL" />
      </geometry>
      <material
        name="">
        <color
          rgba="0.792156862745098 0.819607843137255 0.933333333333333 1" />
      </material>
    </visual>
    <collision>
      <origin
        xyz="0 0 0"
        rpy="0 0 0" />
      <geometry>
        <mesh
          filename="package://koko_description_sevendof_kin/meshes/shoulder_lift_link.STL" />
      </geometry>
    </collision>
  </link>
  <joint
    name="shoulder_lift_joint"
    type="revolute">
    <origin
      xyz="-0.01143 0 -0.21082"
      rpy="-1.5708 4.4409E-16 3.1416" />
    <parent
      link="shoulder_link" />
    <child
      link="shoulder_lift_link" />
    <axis
      xyz="0 0 1" />
    <limit
      lower="-2.2944"
      upper="0"
      effort="0"
      velocity="0" />
  </joint>
  <link
    name="upper_arm_link">
    <inertial>
      <origin
        xyz="0.00526582900451056 5.26701755041159E-05 -0.0641723070964521"
        rpy="0 0 0" />
      <mass
        value="1.52398195258296" />
      <inertia
        ixx="0.00578794210807482"
        ixy="1.9159313302258E-06"
        ixz="-6.31167698984274E-05"
        iyy="0.00530317688204215"
        iyz="1.29025627683915E-06"
        izz="0.00342506142959889" />
    </inertial>
    <visual>
      <origin
        xyz="0 0 0"
        rpy="0 0 0" />
      <geometry>
        <mesh
          filename="package://koko_description_sevendof_kin/meshes/upper_arm_link.STL" />
      </geometry>
      <material
        name="">
        <color
          rgba="1 1 1 1" />
      </material>
    </visual>
    <collision>
      <origin
        xyz="0 0 0"
        rpy="0 0 0" />
      <geometry>
        <mesh
          filename="package://koko_description_sevendof_kin/meshes/upper_arm_link.STL" />
      </geometry>
    </collision>
  </link>
  <joint
    name="shoulder_roll_joint"
    type="revolute">
    <origin
      xyz="0 0.070147 -6.25E-05"
      rpy="-1.5708 1.5673 -3.1416" />
    <parent
      link="shoulder_lift_link" />
    <child
      link="upper_arm_link" />
    <axis
      xyz="0 0 1" />
    <limit
      lower="-2.6761"
      upper="2.6761"
      effort="0"
      velocity="0" />
  </joint>
  <link
    name="upper_arm_lift_link">
    <inertial>
      <origin
        xyz="9.02395508317611E-09 -0.00233330219200323 -1.63698482013586E-05"
        rpy="0 0 0" />
      <mass
        value="0.336087766195304" />
      <inertia
        ixx="0.000748390133454925"
        ixy="-3.98190842469128E-12"
        ixz="2.09357347846198E-06"
        iyy="0.000805057601316457"
        iyz="-3.6144068874078E-08"
        izz="0.000495723293934989" />
    </inertial>
    <visual>
      <origin
        xyz="0 0 0"
        rpy="0 0 0" />
      <geometry>
        <mesh
          filename="package://koko_description_sevendof_kin/meshes/upper_arm_lift_link.STL" />
      </geometry>
      <material
        name="">
        <color
          rgba="1 0.501960784313725 0.501960784313725 1" />
      </material>
    </visual>
    <collision>
      <origin
        xyz="0 0 0"
        rpy="0 0 0" />
      <geometry>
        <mesh
          filename="package://koko_description_sevendof_kin/meshes/upper_arm_lift_link.STL" />
      </geometry>
    </collision>
  </link>
  <joint
    name="elbow_lift_joint"
    type="revolute">
    <origin
      xyz="-0.01143 -4.0407E-05 -0.18056"
      rpy="-1.5708 -8.5189E-16 -3.1381" />
    <parent
      link="upper_arm_link" />
    <child
      link="upper_arm_lift_link" />
    <axis
      xyz="0 0 1" />
    <limit
      lower="-2.2944"
      upper="0"
      effort="0"
      velocity="0" />
  </joint>
  <link
    name="forearm_link">
    <inertial>
      <origin
        xyz="0.00526736167122444 3.29723754633471E-05 -0.0641690050421939"
        rpy="0 0 0" />
      <mass
        value="1.52388327118307" />
      <inertia
        ixx="0.00578756937142458"
        ixy="1.21150391917905E-07"
        ixz="-6.2987809153925E-05"
        iyy="0.00530277515502149"
        iyz="1.37302468929392E-06"
        izz="0.00342480008974915" />
    </inertial>
    <visual>
      <origin
        xyz="0 0 0"
        rpy="0 0 0" />
      <geometry>
        <mesh
          filename="package://koko_description_sevendof_kin/meshes/forearm_link.STL" />
      </geometry>
      <material
        name="">
        <color
          rgba="1 1 1 1" />
      </material>
    </visual>
    <collision>
      <origin
        xyz="0 0 0"
        rpy="0 0 0" />
      <geometry>
        <mesh
          filename="package://koko_description_sevendof_kin/meshes/forearm_link.STL" />
      </geometry>
    </collision>
  </link>
  <joint
    name="elbow_roll_joint"
    type="revolute">
    <origin
      xyz="0 0.070147 -6.25E-05"
      rpy="1.5708 -1.5708 0" />
    <parent
      link="upper_arm_lift_link" />
    <child
      link="forearm_link" />
    <axis
      xyz="0 0 1" />
    <limit
      lower="-2.6761"
      upper="2.6761"
      effort="0"
      velocity="0" />
  </joint>
  <link
    name="wrist_lift_link">
    <inertial>
      <origin
        xyz="-5.00427837291095E-06 0.000232915142959755 -1.77453641017622E-05"
        rpy="0 0 0" />
      <mass
        value="0.38830711159216" />
      <inertia
        ixx="0.000804245381341393"
        ixy="4.84492785619053E-08"
        ixz="2.09169506709714E-06"
        iyy="0.000818232890872385"
        iyz="-1.44703302873814E-08"
        izz="0.000550840544656167" />
    </inertial>
    <visual>
      <origin
        xyz="0 0 0"
        rpy="0 0 0" />
      <geometry>
        <mesh
          filename="package://koko_description_sevendof_kin/meshes/wrist_lift_link.STL" />
      </geometry>
      <material
        name="">
        <color
          rgba="0.792156862745098 0.819607843137255 0.933333333333333 1" />
      </material>
    </visual>
    <collision>
      <origin
        xyz="0 0 0"
        rpy="0 0 0" />
      <geometry>
        <mesh
          filename="package://koko_description_sevendof_kin/meshes/wrist_lift_link.STL" />
      </geometry>
    </collision>
  </link>
  <joint
    name="wrist_lift_joint"
    type="revolute">
    <origin
      xyz="-0.01143 0 -0.18056"
      rpy="-1.5708 6.6613E-16 -3.1416" />
    <parent
      link="forearm_link" />
    <child
      link="wrist_lift_link" />
    <axis
      xyz="0 0 1" />
    <limit
      lower="-2.2944"
      upper="0"
      effort="0"
      velocity="0" />
  </joint>
  <link
    name="wrist_roll_link">
    <inertial>
      <origin
        xyz="-7.00556399929053E-05 2.51272753575837E-05 -0.0523671181686589"
        rpy="0 0 0" />
      <mass
        value="0.247109756122906" />
      <inertia
        ixx="0.000916887873116215"
        ixy="-6.04384035406345E-08"
        ixz="1.67961783600399E-06"
        iyy="0.000877268802194641"
        iyz="5.6417208855379E-07"
        izz="0.000293333065094271" />
    </inertial>
    <visual>
      <origin
        xyz="0 0 0"
        rpy="0 0 0" />
      <geometry>
        <mesh
          filename="package://koko_description_sevendof_kin/meshes/wrist_roll_link.STL" />
      </geometry>
      <material
        name="">
        <color
          rgba="0.792156862745098 0.819607843137255 0.933333333333333 1" />
      </material>
    </visual>
    <collision>
      <origin
        xyz="0 0 0"
        rpy="0 0 0" />
      <geometry>
        <mesh
          filename="package://koko_description_sevendof_kin/meshes/wrist_roll_link.STL" />
      </geometry>
    </collision>
  </link>
  <joint
    name="wrist_roll_joint"
    type="revolute">
    <origin
      xyz="0 0.070147 -6.25E-05"
      rpy="-1.5708 -2.4803E-15 -3.1416" />
    <parent
      link="wrist_lift_link" />
    <child
      link="wrist_roll_link" />
    <axis
      xyz="0 0 1" />
    <limit
      lower="-2.6761"
      upper="2.6761"
      effort="0"
      velocity="0" />
  </joint>
  <link
    name="ee_tracker_link">
    <inertial>
      <origin
        xyz="-4.73939730794015E-07 3.04586800976558E-05 0.0143118417241794"
        rpy="0 0 0" />
      <mass
        value="0.0852058039725329" />
      <inertia
        ixx="5.02595166317689E-05"
        ixy="3.41903671763198E-09"
        ixz="9.88577823458017E-10"
        iyy="5.05436854520427E-05"
        iyz="-1.54406891493077E-07"
        izz="8.48822662488917E-05" />
    </inertial>
    <visual>
      <origin
        xyz="0 0 0"
        rpy="0 0 0" />
      <geometry>
        <mesh
          filename="package://koko_description_sevendof_kin/meshes/ee_tracker_link.STL" />
      </geometry>
      <material
        name="">
        <color
          rgba="0.698039215686274 0.698039215686274 0.698039215686274 1" />
      </material>
    </visual>
    <collision>
      <origin
        xyz="0 0 0"
        rpy="0 0 0" />
      <geometry>
        <mesh
          filename="package://koko_description_sevendof_kin/meshes/ee_tracker_link.STL" />
      </geometry>
    </collision>
  </link>
  <joint
    name="ee_tracker_joint"
    type="fixed">
    <origin
      xyz="0.046598 0 -0.063817"
      rpy="1.5708 -3.5235E-05 1.5708" />
    <parent
      link="wrist_roll_link" />
    <child
      link="ee_tracker_link" />
    <axis
      xyz="0 0 0" />
  </joint>
  <link
    name="forearm_tracker_link">
    <inertial>
      <origin
        xyz="-4.74133496464191E-07 3.04660690206848E-05 0.0143118346031817"
        rpy="0 0 0" />
      <mass
        value="0.0852058007160938" />
      <inertia
        ixx="5.02595072681093E-05"
        ixy="3.44381368240915E-09"
        ixz="9.88599453888935E-10"
        iyy="5.0543665560464E-05"
        iyz="-1.54400109029889E-07"
        izz="8.4882232037176E-05" />
    </inertial>
    <visual>
      <origin
        xyz="0 0 0"
        rpy="0 0 0" />
      <geometry>
        <mesh
          filename="package://koko_description_sevendof_kin/meshes/forearm_tracker_link.STL" />
      </geometry>
      <material
        name="">
        <color
          rgba="0.698039215686274 0.698039215686274 0.698039215686274 1" />
      </material>
    </visual>
    <collision>
      <origin
        xyz="0 0 0"
        rpy="0 0 0" />
      <geometry>
        <mesh
          filename="package://koko_description_sevendof_kin/meshes/forearm_tracker_link.STL" />
      </geometry>
    </collision>
  </link>
  <joint
    name="forearm_tracker_joint"
    type="fixed">
    <origin
      xyz="0.068749 2.8791E-05 -0.096294"
      rpy="-1.8813 2.2741E-05 -1.5708" />
    <parent
      link="forearm_link" />
    <child
      link="forearm_tracker_link" />
    <axis
      xyz="0 0 0" />
  </joint>
  <link
    name="upper_arm_tracker_link">
    <inertial>
      <origin
        xyz="-1.19534844905678E-06 3.0522272923994E-05 0.0143119704893782"
        rpy="0 0 0" />
      <mass
        value="0.0852087895742651" />
      <inertia
        ixx="5.02595862576797E-05"
        ixy="3.39197985149157E-09"
        ixz="1.4871009903621E-09"
        iyy="5.05469581642251E-05"
        iyz="-1.54465938353775E-07"
        izz="8.4885443092325E-05" />
    </inertial>
    <visual>
      <origin
        xyz="0 0 0"
        rpy="0 0 0" />
      <geometry>
        <mesh
          filename="package://koko_description_sevendof_kin/meshes/upper_arm_tracker_link.STL" />
      </geometry>
      <material
        name="">
        <color
          rgba="0.698039215686274 0.698039215686274 0.698039215686274 1" />
      </material>
    </visual>
    <collision>
      <origin
        xyz="0 0 0"
        rpy="0 0 0" />
      <geometry>
        <mesh
          filename="package://koko_description_sevendof_kin/meshes/upper_arm_tracker_link.STL" />
      </geometry>
    </collision>
  </link>
  <joint
    name="upper_arm_tracker_joint"
    type="fixed">
    <origin
      xyz="0.068748 0.00027183 -0.096294"
      rpy="-1.8813 2.2741E-05 -1.5673" />
    <parent
      link="upper_arm_link" />
    <child
      link="upper_arm_tracker_link" />
    <axis
      xyz="0 0 0" />
  </joint>
  <link
    name="base_tracker_link">
    <inertial>
      <origin
        xyz="-4.73473404483116E-07 3.04616810626324E-05 0.0143118364997656"
        rpy="0 0 0" />
      <mass
        value="0.0852057942640312" />
      <inertia
        ixx="5.02594988830078E-05"
        ixy="3.42092835550052E-09"
        ixz="9.8727999349403E-10"
        iyy="5.05436695272967E-05"
        iyz="-1.54423407632237E-07"
        izz="8.48822557420891E-05" />
    </inertial>
    <visual>
      <origin
        xyz="0 0 0"
        rpy="0 0 0" />
      <geometry>
        <mesh
          filename="package://koko_description_sevendof_kin/meshes/base_tracker_link.STL" />
      </geometry>
      <material
        name="">
        <color
          rgba="0.698039215686274 0.698039215686274 0.698039215686274 1" />
      </material>
    </visual>
    <collision>
      <origin
        xyz="0 0 0"
        rpy="0 0 0" />
      <geometry>
        <mesh
          filename="package://koko_description_sevendof_kin/meshes/base_tracker_link.STL" />
      </geometry>
    </collision>
  </link>
  <joint
    name="base_tracker_joint"
    type="fixed">
    <origin
      xyz="0.034608 -0.090805 0.24797"
      rpy="-0.7854 1.4478E-14 1.5708" />
    <parent
      link="base_link" />
    <child
      link="base_tracker_link" />
    <axis
      xyz="0 0 0" />
  </joint>
</robot>
