<robot
  name="fivedof_tracker_kin_v5">
  <link
    name="base_link">
    <inertial>
      <origin
        xyz="0.132232011329379 0.0889379900322127 0.0454629969863035"
        rpy="0 0 0" />
      <mass
        value="0.36203358916215" />
      <inertia
        ixx="0.00333357657753587"
        ixy="-0.000609653639341485"
        ixz="-3.26886318270678E-05"
        iyy="0.00135449484031022"
        iyz="-0.000631078537292462"
        izz="0.00374390627127203" />
    </inertial>
    <visual>
      <origin
        xyz="0 0 0"
        rpy="0 0 0" />
      <geometry>
        <mesh
          filename="package://fivedof_tracker_kin_v5/meshes/base_link.STL" />
      </geometry>
      <material
        name="">
        <color
          rgba="0.792156862745098 0.819607843137255 0.933333333333333 1" />
      </material>
    </visual>
    <collision>
      <origin
        xyz="0 0 0"
        rpy="0 0 0" />
      <geometry>
        <mesh
          filename="package://fivedof_tracker_kin_v5/meshes/base_link.STL" />
      </geometry>
    </collision>
  </link>
  <link
    name="broll_link">
    <inertial>
      <origin
        xyz="-4.4605E-05 -0.0069001 0.12907"
        rpy="0 0 0" />
      <mass
        value="4.3526" />
      <inertia
        ixx="0.0099679"
        ixy="-1.4761E-07"
        ixz="1.2544E-06"
        iyy="0.0098321"
        iyz="0.00021511"
        izz="0.0063676" />
    </inertial>
    <visual>
      <origin
        xyz="0 0 0"
        rpy="0 0 0" />
      <geometry>
        <mesh
          filename="package://fivedof_tracker_kin_v5/meshes/broll_link.STL" />
      </geometry>
      <material
        name="">
        <color
          rgba="0.79216 0.81961 0.93333 1" />
      </material>
    </visual>
    <collision>
      <origin
        xyz="0 0 0"
        rpy="0 0 0" />
      <geometry>
        <mesh
          filename="package://fivedof_tracker_kin_v5/meshes/broll_link.STL" />
      </geometry>
    </collision>
  </link>
  <joint
    name="broll_joint"
    type="continuous">
    <origin
      xyz="0.15882 0.21908 0.070046"
      rpy="0.7854 2.4961E-17 1.5708" />
    <parent
      link="base_link" />
    <child
      link="broll_link" />
    <axis
      xyz="0 0 1" />
  </joint>
  <link
    name="lift_link">
    <inertial>
      <origin
        xyz="1.3434E-08 -0.0018891 -5.3509E-05"
        rpy="0 0 0" />
      <mass
        value="0.37612" />
      <inertia
        ixx="0.0005493"
        ixy="-7.9738E-07"
        ixz="1.5825E-07"
        iyy="0.00096214"
        iyz="4.2975E-08"
        izz="0.00094932" />
    </inertial>
    <visual>
      <origin
        xyz="0 0 0"
        rpy="0 0 0" />
      <geometry>
        <mesh
          filename="package://fivedof_tracker_kin_v5/meshes/lift_link.STL" />
      </geometry>
      <material
        name="">
        <color
          rgba="1 0.50196 0.50196 1" />
      </material>
    </visual>
    <collision>
      <origin
        xyz="0 0 0"
        rpy="0 0 0" />
      <geometry>
        <mesh
          filename="package://fivedof_tracker_kin_v5/meshes/lift_link.STL" />
      </geometry>
    </collision>
  </link>
  <joint
    name="lift_joint"
    type="continuous">
    <origin
      xyz="0.00044422 0.01143 0.25883"
      rpy="1.7611 -1.1184E-16 -3.1416" />
    <parent
      link="broll_link" />
    <child
      link="lift_link" />
    <axis
      xyz="1 0 0" />
  </joint>
  <link
    name="sroll_link">
    <inertial>
      <origin
        xyz="0.00091497 0.10429 -0.0073071"
        rpy="0 0 0" />
      <mass
        value="4.0838" />
      <inertia
        ixx="0.0067221"
        ixy="-7.4513E-06"
        ixz="7.2311E-07"
        iyy="0.0059238"
        iyz="3.7797E-05"
        izz="0.0066022" />
    </inertial>
    <visual>
      <origin
        xyz="0 0 0"
        rpy="0 0 0" />
      <geometry>
        <mesh
          filename="package://fivedof_tracker_kin_v5/meshes/sroll_link.STL" />
      </geometry>
      <material
        name="">
        <color
          rgba="0.79216 0.81961 0.93333 1" />
      </material>
    </visual>
    <collision>
      <origin
        xyz="0 0 0"
        rpy="0 0 0" />
      <geometry>
        <mesh
          filename="package://fivedof_tracker_kin_v5/meshes/sroll_link.STL" />
      </geometry>
    </collision>
  </link>
  <joint
    name="sroll_joint"
    type="continuous">
    <origin
      xyz="0 0.024341 0"
      rpy="-8.8872E-16 -0.034786 2.7772E-17" />
    <parent
      link="lift_link" />
    <child
      link="sroll_link" />
    <axis
      xyz="0 1 0" />
  </joint>
  <link
    name="elbow_link">
    <inertial>
      <origin
        xyz="1.9529E-08 -0.0018891 -5.3512E-05"
        rpy="0 0 0" />
      <mass
        value="0.37612" />
      <inertia
        ixx="0.0005493"
        ixy="-7.973E-07"
        ixz="1.5828E-07"
        iyy="0.00096214"
        iyz="4.2989E-08"
        izz="0.00094932" />
    </inertial>
    <visual>
      <origin
        xyz="0 0 0"
        rpy="0 0 0" />
      <geometry>
        <mesh
          filename="package://fivedof_tracker_kin_v5/meshes/elbow_link.STL" />
      </geometry>
      <material
        name="">
        <color
          rgba="1 0.50196 0.50196 1" />
      </material>
    </visual>
    <collision>
      <origin
        xyz="0 0 0"
        rpy="0 0 0" />
      <geometry>
        <mesh
          filename="package://fivedof_tracker_kin_v5/meshes/elbow_link.STL" />
      </geometry>
    </collision>
  </link>
  <joint
    name="elbow_joint"
    type="continuous">
    <origin
      xyz="0.00044422 0.22733 0.01143"
      rpy="0.19028 7.8013E-12 -6.5919E-17" />
    <parent
      link="sroll_link" />
    <child
      link="elbow_link" />
    <axis
      xyz="1 0 0" />
  </joint>
  <link
    name="eroll_link">
    <inertial>
      <origin
        xyz="0.0005003 0.096087 -0.0017002"
        rpy="0 0 0" />
      <mass
        value="0.30436" />
      <inertia
        ixx="0.0028257"
        ixy="1.0617E-05"
        ixz="-4.0385E-07"
        iyy="8.4482E-05"
        iyz="4.157E-05"
        izz="0.002821" />
    </inertial>
    <visual>
      <origin
        xyz="0 0 0"
        rpy="0 0 0" />
      <geometry>
        <mesh
          filename="package://fivedof_tracker_kin_v5/meshes/eroll_link.STL" />
      </geometry>
      <material
        name="">
        <color
          rgba="0.79216 0.81961 0.93333 1" />
      </material>
    </visual>
    <collision>
      <origin
        xyz="0 0 0"
        rpy="0 0 0" />
      <geometry>
        <mesh
          filename="package://fivedof_tracker_kin_v5/meshes/eroll_link.STL" />
      </geometry>
    </collision>
  </link>
  <joint
    name="eroll_joint"
    type="continuous">
    <origin
      xyz="0 0.024341 0"
      rpy="-3.8326E-15 -0.034786 -9.6624E-13" />
    <parent
      link="elbow_link" />
    <child
      link="eroll_link" />
    <axis
      xyz="0 1 0" />
  </joint>
  <link
    name="ee_tracker_link">
    <inertial>
      <origin
        xyz="-4.5649E-07 3.0452E-05 0.014312"
        rpy="0 0 0" />
      <mass
        value="0.085206" />
      <inertia
        ixx="5.0259E-05"
        ixy="3.4917E-09"
        ixz="9.6848E-10"
        iyy="5.0544E-05"
        iyz="-1.5439E-07"
        izz="8.4882E-05" />
    </inertial>
    <visual>
      <origin
        xyz="0 0 0"
        rpy="0 0 0" />
      <geometry>
        <mesh
          filename="package://fivedof_tracker_kin_v5/meshes/ee_tracker_link.STL" />
      </geometry>
      <material
        name="">
        <color
          rgba="0.69804 0.69804 0.69804 1" />
      </material>
    </visual>
    <collision>
      <origin
        xyz="0 0 0"
        rpy="0 0 0" />
      <geometry>
        <mesh
          filename="package://fivedof_tracker_kin_v5/meshes/ee_tracker_link.STL" />
      </geometry>
    </collision>
  </link>
  <joint
    name="ee_tracker_joint"
    type="fixed">
    <origin
      xyz="-0.00035532 0.17018 -0.017257"
      rpy="-3.1416 -1.9117E-13 3.1209" />
    <parent
      link="eroll_link" />
    <child
      link="ee_tracker_link" />
    <axis
      xyz="0 0 1" />
  </joint>
  <link
    name="base_tracker_link">
    <inertial>
      <origin
        xyz="-4.7301E-07 3.0458E-05 0.014312"
        rpy="0 0 0" />
      <mass
        value="0.085206" />
      <inertia
        ixx="5.026E-05"
        ixy="3.4215E-09"
        ixz="9.8772E-10"
        iyy="5.0544E-05"
        iyz="-1.5441E-07"
        izz="8.4882E-05" />
    </inertial>
    <visual>
      <origin
        xyz="0 0 0"
        rpy="0 0 0" />
      <geometry>
        <mesh
          filename="package://fivedof_tracker_kin_v5/meshes/base_tracker_link.STL" />
      </geometry>
      <material
        name="">
        <color
          rgba="0.69804 0.69804 0.69804 1" />
      </material>
    </visual>
    <collision>
      <origin
        xyz="0 0 0"
        rpy="0 0 0" />
      <geometry>
        <mesh
          filename="package://fivedof_tracker_kin_v5/meshes/base_tracker_link.STL" />
      </geometry>
    </collision>
  </link>
  <joint
    name="base_tracker_joint"
    type="fixed">
    <origin
      xyz="0.077314 0.12028 0.14416"
      rpy="-0.7854 0.001526 -1.5693" />
    <parent
      link="base_link" />
    <child
      link="base_tracker_link" />
    <axis
      xyz="0 0 0" />
  </joint>
</robot>