<robot
  name="koko_description_fivedof_kin">
  <link
    name="base_link">
    <inertial>
      <origin
        xyz="0.0128424654307168 -0.162261711643048 0.155657622910268"
        rpy="0 0 0" />
      <mass
        value="2.50668095471534" />
      <inertia
        ixx="0.0599827724543488"
        ixy="-0.00761117858508908"
        ixz="0.000334029187700718"
        iyy="0.0597504740015784"
        iyz="-0.000387733898574592"
        izz="0.0375364118295859" />
    </inertial>
    <visual>
      <origin
        xyz="0 0 0"
        rpy="0 0 0" />
      <geometry>
        <mesh
          filename="package://koko_description_fivedof_kin/meshes/base_link.STL" />
      </geometry>
      <material
        name="">
        <color
          rgba="0.792156862745098 0.819607843137255 0.933333333333333 1" />
      </material>
    </visual>
    <collision>
      <origin
        xyz="0 0 0"
        rpy="0 0 0" />
      <geometry>
        <mesh
          filename="package://koko_description_fivedof_kin/meshes/base_link.STL" />
      </geometry>
    </collision>
  </link>
  <link
    name="shoulder_link">
    <inertial>
      <origin
        xyz="-0.00747857928130133 -2.49194120865437E-05 0.0799282586928382"
        rpy="0 0 0" />
      <mass
        value="4.07268031053917" />
      <inertia
        ixx="0.00617143795854479"
        ixy="-6.35746532027821E-07"
        ixz="-7.28585946612186E-06"
        iyy="0.00633184740729349"
        iyz="-4.26811662563041E-07"
        izz="0.0059399912337155" />
    </inertial>
    <visual>
      <origin
        xyz="0 0 0"
        rpy="0 0 0" />
      <geometry>
        <mesh
          filename="package://koko_description_fivedof_kin/meshes/shoulder_link.STL" />
      </geometry>
      <material
        name="">
        <color
          rgba="0.6 0.6 0.6 1" />
      </material>
    </visual>
    <collision>
      <origin
        xyz="0 0 0"
        rpy="0 0 0" />
      <geometry>
        <mesh
          filename="package://koko_description_fivedof_kin/meshes/shoulder_link.STL" />
      </geometry>
    </collision>
  </link>
  <joint
    name="base_roll_joint"
    type="continuous">
    <origin
      xyz="0.0966447291250239 -0.0908049999999999 0.218621617367798"
      rpy="6.83851519316138E-15 0.785398163397447 4.83556046633164E-15" />
    <parent
      link="base_link" />
    <child
      link="shoulder_link" />
    <axis
      xyz="0 0 1" />
  </joint>
  <link
    name="shoulder_lift_link">
    <inertial>
      <origin
        xyz="-0.00050941837756377 0.00189435004391486 -3.43465409446964E-08"
        rpy="0 0 0" />
      <mass
        value="0.437261345246881" />
      <inertia
        ixx="0.00102610376988145"
        ixy="-1.55407229811396E-05"
        ixz="-6.48315328100395E-07"
        iyy="0.00108268516791602"
        iyz="-6.869263520968E-07"
        izz="0.000657530165361203" />
    </inertial>
    <visual>
      <origin
        xyz="0 0 0"
        rpy="0 0 0" />
      <geometry>
        <mesh
          filename="package://koko_description_fivedof_kin/meshes/shoulder_lift_link.STL" />
      </geometry>
      <material
        name="">
        <color
          rgba="1 0.501960784313725 0.501960784313725 1" />
      </material>
    </visual>
    <collision>
      <origin
        xyz="0 0 0"
        rpy="0 0 0" />
      <geometry>
        <mesh
          filename="package://koko_description_fivedof_kin/meshes/shoulder_lift_link.STL" />
      </geometry>
    </collision>
  </link>
  <joint
    name="shoulder_lift_joint"
    type="continuous">
    <origin
      xyz="0.0114299285786579 4.04065193964076E-05 0.201676000000001"
      rpy="1.5707963267949 -0.785395039094458 0.0035351359132397" />
    <parent
      link="shoulder_link" />
    <child
      link="shoulder_lift_link" />
    <axis
      xyz="0 0 1" />
  </joint>
  <link
    name="upper_arm_link">
    <inertial>
      <origin
        xyz="0.0071539392870133 -1.68573131459349E-05 0.0548011173337356"
        rpy="0 0 0" />
      <mass
        value="4.18907370537364" />
      <inertia
        ixx="0.00782694806513304"
        ixy="4.93162874925591E-07"
        ixz="0.000134846912278907"
        iyy="0.00801358654939988"
        iyz="1.56716813961893E-06"
        izz="0.00601991405955648" />
    </inertial>
    <visual>
      <origin
        xyz="0 0 0"
        rpy="0 0 0" />
      <geometry>
        <mesh
          filename="package://koko_description_fivedof_kin/meshes/upper_arm_link.STL" />
      </geometry>
      <material
        name="">
        <color
          rgba="0.298039215686275 0.298039215686275 0.298039215686275 1" />
      </material>
    </visual>
    <collision>
      <origin
        xyz="0 0 0"
        rpy="0 0 0" />
      <geometry>
        <mesh
          filename="package://koko_description_fivedof_kin/meshes/upper_arm_link.STL" />
      </geometry>
    </collision>
  </link>
  <joint
    name="shoulder_roll_joint"
    type="continuous">
    <origin
      xyz="0.0185369354147557 -0.0681800006921313 0"
      rpy="1.5707963267949 -0.00259045364213944 0.265465420981425" />
    <parent
      link="shoulder_lift_link" />
    <child
      link="upper_arm_link" />
    <axis
      xyz="0 0 -1" />
  </joint>
  <link
    name="upper_arm_lift_link">
    <inertial>
      <origin
        xyz="-0.000218842262255881 0.00199077302431142 2.88498979705842E-08"
        rpy="0 0 0" />
      <mass
        value="0.424523142313433" />
      <inertia
        ixx="0.00101023991051721"
        ixy="-1.07390769836644E-05"
        ixz="-1.81536740952194E-06"
        iyy="0.00107184608421791"
        iyz="-8.37681703321027E-07"
        izz="0.000658498963913288" />
    </inertial>
    <visual>
      <origin
        xyz="0 0 0"
        rpy="0 0 0" />
      <geometry>
        <mesh
          filename="package://koko_description_fivedof_kin/meshes/upper_arm_lift_link.STL" />
      </geometry>
      <material
        name="">
        <color
          rgba="1 0.501960784313725 0.501960784313725 1" />
      </material>
    </visual>
    <collision>
      <origin
        xyz="0 0 0"
        rpy="0 0 0" />
      <geometry>
        <mesh
          filename="package://koko_description_fivedof_kin/meshes/upper_arm_lift_link.STL" />
      </geometry>
    </collision>
  </link>
  <joint
    name="elbow_lift_joint"
    type="continuous">
    <origin
      xyz="-0.0114299606048832 2.96084406938846E-05 0.181015691671218"
      rpy="-1.5707963267949 -0.265459172375448 -0.00259045364213955" />
    <parent
      link="upper_arm_link" />
    <child
      link="upper_arm_lift_link" />
    <axis
      xyz="0 0 1" />
  </joint>
  <link
    name="forearm_link">
    <inertial>
      <origin
        xyz="0.00474985548204007 -5.32571640061708E-05 0.0730980120124444"
        rpy="0 0 0" />
      <mass
        value="4.66605873777198" />
      <inertia
        ixx="0.0158343232786075"
        ixy="-4.83291933339679E-07"
        ixz="0.00140172468299471"
        iyy="0.015906388412809"
        iyz="-7.27024540810356E-06"
        izz="0.0073657034904474" />
    </inertial>
    <visual>
      <origin
        xyz="0 0 0"
        rpy="0 0 0" />
      <geometry>
        <mesh
          filename="package://koko_description_fivedof_kin/meshes/forearm_link.STL" />
      </geometry>
      <material
        name="">
        <color
          rgba="0.298039215686275 0.298039215686275 0.298039215686275 1" />
      </material>
    </visual>
    <collision>
      <origin
        xyz="0 0 0"
        rpy="0 0 0" />
      <geometry>
        <mesh
          filename="package://koko_description_fivedof_kin/meshes/forearm_link.STL" />
      </geometry>
    </collision>
  </link>
  <joint
    name="elbow_roll_joint"
    type="continuous">
    <origin
      xyz="0.0118025765508603 -0.0696622541660661 0"
      rpy="1.5707963267949 -0.00253533924781029 0.167831940552949" />
    <parent
      link="upper_arm_lift_link" />
    <child
      link="forearm_link" />
    <axis
      xyz="0 0 -1" />
  </joint>
  <link
    name="forearm_tracker_link">
    <inertial>
      <origin
        xyz="-7.78112474064674E-07 3.04102563280194E-05 0.014311863530617"
        rpy="0 0 0" />
      <mass
        value="0.0852058630561248" />
      <inertia
        ixx="5.02601180298056E-05"
        ixy="3.54406064372797E-09"
        ixz="7.90416884357265E-10"
        iyy="5.05430565473139E-05"
        iyz="-1.5445675030937E-07"
        izz="8.48822590393088E-05" />
    </inertial>
    <visual>
      <origin
        xyz="0 0 0"
        rpy="0 0 0" />
      <geometry>
        <mesh
          filename="package://koko_description_fivedof_kin/meshes/forearm_tracker_link.STL" />
      </geometry>
      <material
        name="">
        <color
          rgba="0.698039215686274 0.698039215686274 0.698039215686274 1" />
      </material>
    </visual>
    <collision>
      <origin
        xyz="0 0 0"
        rpy="0 0 0" />
      <geometry>
        <mesh
          filename="package://koko_description_fivedof_kin/meshes/forearm_tracker_link.STL" />
      </geometry>
    </collision>
  </link>
  <joint
    name="forearm_tracker_joint"
    type="fixed">
    <origin
      xyz="0.0683718553549543 -0.000173551450839082 0.0965426886757189"
      rpy="1.2602877982261 -4.06012139668227E-05 1.56827401600182" />
    <parent
      link="forearm_link" />
    <child
      link="forearm_tracker_link" />
    <axis
      xyz="0 0 0" />
  </joint>
  <link
    name="upper_arm_tracker_link">
    <inertial>
      <origin
        xyz="-7.95430838251843E-07 3.04140221774329E-05 0.0143118605448434"
        rpy="0 0 0" />
      <mass
        value="0.0852058724544114" />
      <inertia
        ixx="5.0260134924051E-05"
        ixy="3.5401689425363E-09"
        ixz="7.98393811757983E-10"
        iyy="5.05430365322614E-05"
        iyz="-1.54474115414265E-07"
        izz="8.4882269874301E-05" />
    </inertial>
    <visual>
      <origin
        xyz="0 0 0"
        rpy="0 0 0" />
      <geometry>
        <mesh
          filename="package://koko_description_fivedof_kin/meshes/upper_arm_tracker_link.STL" />
      </geometry>
      <material
        name="">
        <color
          rgba="0.698039215686274 0.698039215686274 0.698039215686274 1" />
      </material>
    </visual>
    <collision>
      <origin
        xyz="0 0 0"
        rpy="0 0 0" />
      <geometry>
        <mesh
          filename="package://koko_description_fivedof_kin/meshes/upper_arm_tracker_link.STL" />
      </geometry>
    </collision>
  </link>
  <joint
    name="upper_arm_tracker_joint"
    type="fixed">
    <origin
      xyz="0.068372 -0.00017732 0.096543"
      rpy="1.2603 -2.2741E-05 1.5682" />
    <parent
      link="upper_arm_link" />
    <child
      link="upper_arm_tracker_link" />
    <axis
      xyz="0 0 0" />
  </joint>
  <link
    name="base_tracker_link">
    <inertial>
      <origin
        xyz="4.43507453540271E-08 3.09552203211494E-05 0.0143117399037371"
        rpy="0 0 0" />
      <mass
        value="0.0852031301907352" />
      <inertia
        ixx="5.02578521392565E-05"
        ixy="4.7925897537491E-09"
        ixz="9.20656645295695E-10"
        iyy="5.05426153010017E-05"
        iyz="-1.54378610465991E-07"
        izz="8.48796208959856E-05" />
    </inertial>
    <visual>
      <origin
        xyz="0 0 0"
        rpy="0 0 0" />
      <geometry>
        <mesh
          filename="package://koko_description_fivedof_kin/meshes/base_tracker_link.STL" />
      </geometry>
      <material
        name="">
        <color
          rgba="0.698039215686274 0.698039215686274 0.698039215686274 1" />
      </material>
    </visual>
    <collision>
      <origin
        xyz="0 0 0"
        rpy="0 0 0" />
      <geometry>
        <mesh
          filename="package://koko_description_fivedof_kin/meshes/base_tracker_link.STL" />
      </geometry>
    </collision>
  </link>
  <joint
    name="base_tracker_joint"
    type="fixed">
    <origin
      xyz="0.122544343576621 0.0211413433675803 0.104502933199187"
      rpy="-0.00215895279379528 -0.78539656263699 -3.1385396042896" />
    <parent
      link="base_link" />
    <child
      link="base_tracker_link" />
    <axis
      xyz="0 0 0" />
  </joint>
</robot>