<?xml version="1.0" ?>
<!-- =================================================================================== -->
<!-- |    This document was autogenerated by xacro from blue_right_no_gripper.urdf.xacro | -->
<!-- |    EDITING THIS FILE BY HAND IS NOT RECOMMENDED                                 | -->
<!-- =================================================================================== -->
<robot name="blue_descriptions_right" xmlns:xacro="http://ros.org/wiki/xacro">
  <link name="right_base_link">
    <inertial>
      <origin rpy="0 0 0" xyz="0.0560024374186662 0.000189445541681321 0.0201835602327798"/>
      <mass value="0.284612172465311"/>
      <inertia ixx="0.000716950374478633" ixy="-4.58477843167981E-06" ixz="4.20772050305934E-06" iyy="0.00197711566495113" iyz="9.13561852910017E-07" izz="0.00239705630031167"/>
    </inertial>
    <visual>
      <origin rpy="0 0 0" xyz="0 0 0"/>
      <geometry>
        <mesh filename="package://blue_descriptions/meshes/arm_base_link.STL"/>
      </geometry>
      <material name="">
        <color rgba="0.792156862745098 0.819607843137255 0.933333333333333 1"/>
      </material>
    </visual>
    <collision>
      <origin rpy="0 0 0" xyz="0 0 0"/>
      <geometry>
        <mesh filename="package://blue_descriptions/meshes/arm_base_link.STL"/>
      </geometry>
    </collision>
  </link>
  <joint name="right_base_roll_joint" type="revolute">
    <origin rpy="3.1416 -2.2011E-29 0.0" xyz="0 0 0.087371"/>
    <parent link="right_base_link"/>
    <child link="right_shoulder_roll_link"/>
    <axis xyz="0 0 1"/>
    <limit effort="80" lower="-3.3999" upper="2.3412" velocity="50"/>
  </joint>
  <link name="right_shoulder_roll_link">
    <inertial>
      <origin rpy="0 0 0" xyz="0.00526385736219506 2.70691865020822E-05 -0.0641638075944594"/>
      <mass value="1.91396434923"/>
      <inertia ixx="0.0057866591250737" ixy="3.71515699629511E-07" ixz="-6.32890111626103E-05" iyy="0.00530223654324281" iyz="8.9999884666805E-07" izz="0.00342399181200673"/>
    </inertial>
    <visual>
      <origin rpy="0 0 0" xyz="0 0 0"/>
      <geometry>
        <mesh filename="package://blue_descriptions/meshes/roll_link.STL"/>
      </geometry>
      <material name="">
        <color rgba="1 1 1 1"/>
      </material>
    </visual>
    <collision>
      <origin rpy="0 0 0" xyz="0 0 0"/>
      <geometry>
        <mesh filename="package://blue_descriptions/meshes/roll_link.STL"/>
      </geometry>
    </collision>
  </link>
  <joint name="right_shoulder_lift_joint" type="revolute">
    <origin rpy="-1.5708 4.4409E-16 3.1416" xyz="-0.01143 0 -0.18056"/>
    <parent link="right_shoulder_roll_link"/>
    <child link="right_shoulder_lift_link"/>
    <axis xyz="0 0 1"/>
    <limit effort="80" lower="-2.2944" upper="0" velocity="50"/>
  </joint>
  <link name="right_shoulder_lift_link">
    <inertial>
      <origin rpy="0 0 0" xyz="-5.0083559080677E-06 0.000232928456050885 -1.77451392545103E-05"/>
      <mass value="0.448307108622636"/>
      <inertia ixx="0.000804272985961788" ixy="4.84548777859872E-08" ixz="2.09160815704306E-06" iyy="0.000818260636171894" iyz="-1.44954778549764E-08" izz="0.000550840705045094"/>
    </inertial>
    <visual>
      <origin rpy="0 0 0" xyz="0 0 0"/>
      <geometry>
        <mesh filename="package://blue_descriptions/meshes/lift_link.STL"/>
      </geometry>
      <material name="">
        <color rgba="0.116747 0.862745 1.0 1"/>
      </material>
    </visual>
    <collision>
      <origin rpy="0 0 0" xyz="0 0 0"/>
      <geometry>
        <mesh filename="package://blue_descriptions/meshes/lift_link.STL"/>
      </geometry>
    </collision>
  </link>
  <joint name="right_shoulder_roll_joint" type="revolute">
    <origin rpy="-1.5708 -1.5673 -3.1416" xyz="0 0.070147 -6.25E-05"/>
    <parent link="right_shoulder_lift_link"/>
    <child link="right_elbow_roll_link"/>
    <axis xyz="0 0 1"/>
    <limit effort="80" lower="-2.6761" upper="2.6761" velocity="50"/>
  </joint>
  <link name="right_elbow_roll_link">
    <inertial>
      <origin rpy="0 0 0" xyz="0.00526385736219506 2.70691865020822E-05 -0.0641638075944594"/>
      <mass value="1.91396434923"/>
      <inertia ixx="0.0057866591250737" ixy="3.71515699629511E-07" ixz="-6.32890111626103E-05" iyy="0.00530223654324281" iyz="8.9999884666805E-07" izz="0.00342399181200673"/>
    </inertial>
    <visual>
      <origin rpy="0 0 0" xyz="0 0 0"/>
      <geometry>
        <mesh filename="package://blue_descriptions/meshes/roll_link.STL"/>
      </geometry>
      <material name="">
        <color rgba="1 1 1 1"/>
      </material>
    </visual>
    <collision>
      <origin rpy="0 0 0" xyz="0 0 0"/>
      <geometry>
        <mesh filename="package://blue_descriptions/meshes/roll_link.STL"/>
      </geometry>
    </collision>
  </link>
  <joint name="right_elbow_lift_joint" type="revolute">
    <origin rpy="-1.5708 4.4409E-16 3.1416" xyz="-0.01143 0 -0.18056"/>
    <parent link="right_elbow_roll_link"/>
    <child link="right_elbow_lift_link"/>
    <axis xyz="0 0 1"/>
    <limit effort="80" lower="-2.2944" upper="0" velocity="50"/>
  </joint>
  <link name="right_elbow_lift_link">
    <inertial>
      <origin rpy="0 0 0" xyz="-5.0083559080677E-06 0.000232928456050885 -1.77451392545103E-05"/>
      <mass value="0.448307108622636"/>
      <inertia ixx="0.000804272985961788" ixy="4.84548777859872E-08" ixz="2.09160815704306E-06" iyy="0.000818260636171894" iyz="-1.44954778549764E-08" izz="0.000550840705045094"/>
    </inertial>
    <visual>
      <origin rpy="0 0 0" xyz="0 0 0"/>
      <geometry>
        <mesh filename="package://blue_descriptions/meshes/lift_link.STL"/>
      </geometry>
      <material name="">
        <color rgba="0.116747 0.862745 1.0 1"/>
      </material>
    </visual>
    <collision>
      <origin rpy="0 0 0" xyz="0 0 0"/>
      <geometry>
        <mesh filename="package://blue_descriptions/meshes/lift_link.STL"/>
      </geometry>
    </collision>
  </link>
  <joint name="right_elbow_roll_joint" type="revolute">
    <origin rpy="-1.5708 1.5673 -3.1416" xyz="0 0.070147 -6.25E-05"/>
    <parent link="right_elbow_lift_link"/>
    <child link="right_wrist_roll_link"/>
    <axis xyz="0 0 1"/>
    <limit effort="80" lower="-2.6761" upper="2.6761" velocity="50"/>
  </joint>
  <link name="right_wrist_roll_link">
    <inertial>
      <origin rpy="0 0 0" xyz="0.00526385736219506 2.70691865020822E-05 -0.0641638075944594"/>
      <mass value="1.41368434923"/>
      <inertia ixx="0.0057866591250737" ixy="3.71515699629511E-07" ixz="-6.32890111626103E-05" iyy="0.00530223654324281" iyz="8.9999884666805E-07" izz="0.00342399181200673"/>
    </inertial>
    <visual>
      <origin rpy="0 0 0" xyz="0 0 0"/>
      <geometry>
        <mesh filename="package://blue_descriptions/meshes/roll_link.STL"/>
      </geometry>
      <material name="">
        <color rgba="1 1 1 1"/>
      </material>
    </visual>
    <collision>
      <origin rpy="0 0 0" xyz="0 0 0"/>
      <geometry>
        <mesh filename="package://blue_descriptions/meshes/roll_link.STL"/>
      </geometry>
    </collision>
  </link>
  <joint name="right_wrist_lift_joint" type="revolute">
    <origin rpy="-1.5708 4.4409E-16 3.1416" xyz="-0.01143 0 -0.18056"/>
    <parent link="right_wrist_roll_link"/>
    <child link="right_wrist_lift_link"/>
    <axis xyz="0 0 1"/>
    <limit effort="80" lower="-2.2944" upper="0" velocity="50"/>
  </joint>
  <link name="right_wrist_lift_link">
    <inertial>
      <origin rpy="0 0 0" xyz="-5.0083559080677E-06 0.000232928456050885 -1.77451392545103E-05"/>
      <mass value="0.448307108622636"/>
      <inertia ixx="0.000804272985961788" ixy="4.84548777859872E-08" ixz="2.09160815704306E-06" iyy="0.000818260636171894" iyz="-1.44954778549764E-08" izz="0.000550840705045094"/>
    </inertial>
    <visual>
      <origin rpy="0 0 0" xyz="0 0 0"/>
      <geometry>
        <mesh filename="package://blue_descriptions/meshes/lift_link.STL"/>
      </geometry>
      <material name="">
        <color rgba="0.116747 0.862745 1.0 1"/>
      </material>
    </visual>
    <collision>
      <origin rpy="0 0 0" xyz="0 0 0"/>
      <geometry>
        <mesh filename="package://blue_descriptions/meshes/lift_link.STL"/>
      </geometry>
    </collision>
  </link>
  <joint name="right_wrist_roll_joint" type="revolute">
    <origin rpy="-1.5708 0.0 -3.1416" xyz="0 0.070147 -6.25E-05"/>
    <parent link="right_wrist_lift_link"/>
    <child link="right_end_roll_link"/>
    <axis xyz="0 0 1"/>
    <limit effort="80" lower="-2.6761" upper="2.6761" velocity="50"/>
  </joint>
  <link name="right_end_roll_link">
    <inertial>
      <origin rpy="0 0 0" xyz="0.00526385736219506 2.70691865020822E-05 -0.0641638075944594"/>
      <mass value="0.657109755986862"/>
      <inertia ixx="0.0057866591250737" ixy="3.71515699629511E-07" ixz="-6.32890111626103E-05" iyy="0.00530223654324281" iyz="8.9999884666805E-07" izz="0.00342399181200673"/>
    </inertial>
    <visual>
      <origin rpy="0 0 0" xyz="0 0 0"/>
      <geometry>
        <mesh filename="package://blue_descriptions/meshes/wrist_roll_link_open.STL"/>
      </geometry>
      <material name="">
        <color rgba="1 1 1 1"/>
      </material>
    </visual>
    <collision>
      <origin rpy="0 0 0" xyz="0 0 0"/>
      <geometry>
        <mesh filename="package://blue_descriptions/meshes/wrist_roll_link_open.STL"/>
      </geometry>
    </collision>
  </link>
</robot>

