<?xml version="1.0" ?>
<!-- =================================================================================== -->
<!-- |    This document was autogenerated by xacro from blue_full.urdf.xacro           | -->
<!-- |    EDITING THIS FILE BY HAND IS NOT RECOMMENDED                                 | -->
<!-- =================================================================================== -->
<robot name="blue_descriptions_right" xmlns:xacro="http://ros.org/wiki/xacro">
  <link name="world"/>
  <joint name="world_joint" type="fixed">
    <origin rpy="0 0 0" xyz="0 0 1.4"/>
    <parent link="world"/>
    <child link="base_link"/>
  </joint>
  <link name="base_link">
    <inertial>
      <origin rpy="0 0 0" xyz="-0.0340720710868516 -5.82248094938009E-06 -0.701353347324681"/>
      <mass value="16.2841622231049"/>
      <inertia ixx="2.14925955046191" ixy="-1.29716552583247E-05" ixz="0.0350729990773796" iyy="1.86082991311609" iyz="6.6571955031526E-05" izz="0.793500351133606"/>
    </inertial>
    <visual>
      <origin rpy="0 0 0" xyz="0 0 0"/>
      <geometry>
        <mesh filename="package://blue_descriptions/meshes/robot_base_link.STL"/>
      </geometry>
      <material name="">
        <color rgba="0.792156862745098 0.819607843137255 0.933333333333333 1"/>
      </material>
    </visual>
    <collision>
      <origin rpy="0 0 0" xyz="0 0 0"/>
      <geometry>
        <mesh filename="package://blue_descriptions/meshes/robot_base_link.STL"/>
      </geometry>
    </collision>
  </link>
  <joint name="left_fixed_joint" type="fixed">
    <origin rpy="0.61087 -0.5236 3.1416" xyz="-0.01409 0.11289 0"/>
    <parent link="base_link"/>
    <child link="left_base_link"/>
    <axis xyz="0.5 0.49673 0.70941"/>
  </joint>
  <joint name="right_fixed_joint" type="fixed">
    <origin rpy="-0.61087 -0.5236 3.1416" xyz="-0.01409 -0.11289 0"/>
    <parent link="base_link"/>
    <child link="right_base_link"/>
    <axis xyz="0.5 -0.49673 0.70941"/>
  </joint>
  <link name="camera_link">
    <inertial>
      <origin rpy="0 0 0" xyz="-0.00759217244323041 0.0650724306353812 0.000615586148610126"/>
      <mass value="0.274759207683782"/>
      <inertia ixx="0.000597466918447966" ixy="-1.22023781832195E-06" ixz="-7.19559686887802E-07" iyy="0.000569118421202202" iyz="-2.24460961567124E-07" izz="0.000184848568794368"/>
    </inertial>
    <visual>
      <origin rpy="0 0 0" xyz="0 0 0"/>
      <geometry>
        <mesh filename="package://blue_descriptions/meshes/camera_link.STL"/>
      </geometry>
      <material name="">
        <color rgba="0.792156862745098 0.819607843137255 0.933333333333333 1"/>
      </material>
    </visual>
    <collision>
      <origin rpy="0 0 0" xyz="0 0 0"/>
      <geometry>
        <mesh filename="package://blue_descriptions/meshes/camera_link.STL"/>
      </geometry>
    </collision>
  </link>
  <joint name="camera_rotation_joint" type="fixed">
    <origin rpy="1.5707963267949 -5.91437301648455E-15 0.0" xyz="-0.0190500000000001 0 0.303506965012"/>
    <parent link="base_link"/>
    <child link="camera_link"/>
    <axis xyz="0 1 0"/>
  </joint>
  <link name="camera_view_link"/>
  <joint name="camera_view_joint" type="fixed">
    <origin rpy="0 -1.5707963267949 0" xyz="0.0190500000000003 0.0727749999999998 0"/>
    <parent link="camera_link"/>
    <child link="camera_view_link"/>
    <axis xyz="0 0 0"/>
  </joint>
  <link name="right_base_link">
    <inertial>
      <origin rpy="0 0 0" xyz="0.0560024374186662 0.000189445541681321 0.0201835602327798"/>
      <mass value="0.284612172465311"/>
      <inertia ixx="0.000716950374478633" ixy="-4.58477843167981E-06" ixz="4.20772050305934E-06" iyy="0.00197711566495113" iyz="9.13561852910017E-07" izz="0.00239705630031167"/>
    </inertial>
    <visual>
      <origin rpy="0 0 0" xyz="0 0 0"/>
      <geometry>
        <mesh filename="package://blue_descriptions/meshes/arm_base_link.STL"/>
      </geometry>
      <material name="">
        <color rgba="0.792156862745098 0.819607843137255 0.933333333333333 1"/>
      </material>
    </visual>
    <collision>
      <origin rpy="0 0 0" xyz="0 0 0"/>
      <geometry>
        <mesh filename="package://blue_descriptions/meshes/arm_base_link.STL"/>
      </geometry>
    </collision>
  </link>
  <joint name="right_base_roll_joint" type="revolute">
    <origin rpy="3.1416 -2.2011E-29 0.0" xyz="0 0 0.087371"/>
    <parent link="right_base_link"/>
    <child link="right_shoulder_roll_link"/>
    <axis xyz="0 0 1"/>
    <limit effort="0" lower="-3.3999" upper="2.3412" velocity="0"/>
  </joint>
  <transmission name="right_base_roll_joint_transmission">
    <type>transmission_interface/SimpleTransmission</type>
    <joint name="right_base_roll_joint">
      <hardwareInterface>EffortJointInterface</hardwareInterface>
    </joint>
    <actuator name="{side}_base_roll_motor">
      <hardwareInterface>EffortJointInterface</hardwareInterface>
      <mechanicalReduction>1</mechanicalReduction>
    </actuator>
  </transmission>
  <link name="right_shoulder_roll_link">
    <inertial>
      <origin rpy="0 0 0" xyz="0.00526385736219506 2.70691865020822E-05 -0.0641638075944594"/>
      <mass value="1.91396434923"/>
      <inertia ixx="0.0057866591250737" ixy="3.71515699629511E-07" ixz="-6.32890111626103E-05" iyy="0.00530223654324281" iyz="8.9999884666805E-07" izz="0.00342399181200673"/>
    </inertial>
    <visual>
      <origin rpy="0 0 0" xyz="0 0 0"/>
      <geometry>
        <mesh filename="package://blue_descriptions/meshes/roll_link.STL"/>
      </geometry>
      <material name="">
        <color rgba="1 1 1 1"/>
      </material>
    </visual>
    <collision>
      <origin rpy="0 0 0" xyz="0 0 0"/>
      <geometry>
        <mesh filename="package://blue_descriptions/meshes/roll_link.STL"/>
      </geometry>
    </collision>
  </link>
  <joint name="right_shoulder_lift_joint" type="revolute">
    <origin rpy="-1.5708 4.4409E-16 3.1416" xyz="-0.01143 0 -0.18056"/>
    <parent link="right_shoulder_roll_link"/>
    <child link="right_shoulder_lift_link"/>
    <axis xyz="0 0 1"/>
    <limit effort="0" lower="-2.2944" upper="0" velocity="0"/>
  </joint>
  <link name="right_shoulder_lift_link">
    <inertial>
      <origin rpy="0 0 0" xyz="-5.0083559080677E-06 0.000232928456050885 -1.77451392545103E-05"/>
      <mass value="0.448307108622636"/>
      <inertia ixx="0.000804272985961788" ixy="4.84548777859872E-08" ixz="2.09160815704306E-06" iyy="0.000818260636171894" iyz="-1.44954778549764E-08" izz="0.000550840705045094"/>
    </inertial>
    <visual>
      <origin rpy="0 0 0" xyz="0 0 0"/>
      <geometry>
        <mesh filename="package://blue_descriptions/meshes/lift_link.STL"/>
      </geometry>
      <material name="">
        <color rgba="0.792156862745098 0.819607843137255 0.933333333333333 1"/>
      </material>
    </visual>
    <collision>
      <origin rpy="0 0 0" xyz="0 0 0"/>
      <geometry>
        <mesh filename="package://blue_descriptions/meshes/lift_link.STL"/>
      </geometry>
    </collision>
  </link>
  <joint name="right_shoulder_roll_joint" type="revolute">
    <origin rpy="-1.5708 -1.5673 -3.1416" xyz="0 0.070147 -6.25E-05"/>
    <parent link="right_shoulder_lift_link"/>
    <child link="right_elbow_roll_link"/>
    <axis xyz="0 0 1"/>
    <limit effort="0" lower="-2.6761" upper="2.6761" velocity="0"/>
  </joint>
  <link name="right_elbow_roll_link">
    <inertial>
      <origin rpy="0 0 0" xyz="0.00526385736219506 2.70691865020822E-05 -0.0641638075944594"/>
      <mass value="1.91396434923"/>
      <inertia ixx="0.0057866591250737" ixy="3.71515699629511E-07" ixz="-6.32890111626103E-05" iyy="0.00530223654324281" iyz="8.9999884666805E-07" izz="0.00342399181200673"/>
    </inertial>
    <visual>
      <origin rpy="0 0 0" xyz="0 0 0"/>
      <geometry>
        <mesh filename="package://blue_descriptions/meshes/roll_link.STL"/>
      </geometry>
      <material name="">
        <color rgba="1 1 1 1"/>
      </material>
    </visual>
    <collision>
      <origin rpy="0 0 0" xyz="0 0 0"/>
      <geometry>
        <mesh filename="package://blue_descriptions/meshes/roll_link.STL"/>
      </geometry>
    </collision>
  </link>
  <joint name="right_elbow_lift_joint" type="revolute">
    <origin rpy="-1.5708 4.4409E-16 3.1416" xyz="-0.01143 0 -0.18056"/>
    <parent link="right_elbow_roll_link"/>
    <child link="right_elbow_lift_link"/>
    <axis xyz="0 0 1"/>
    <limit effort="0" lower="-2.2944" upper="0" velocity="0"/>
  </joint>
  <link name="right_elbow_lift_link">
    <inertial>
      <origin rpy="0 0 0" xyz="-5.0083559080677E-06 0.000232928456050885 -1.77451392545103E-05"/>
      <mass value="0.448307108622636"/>
      <inertia ixx="0.000804272985961788" ixy="4.84548777859872E-08" ixz="2.09160815704306E-06" iyy="0.000818260636171894" iyz="-1.44954778549764E-08" izz="0.000550840705045094"/>
    </inertial>
    <visual>
      <origin rpy="0 0 0" xyz="0 0 0"/>
      <geometry>
        <mesh filename="package://blue_descriptions/meshes/lift_link.STL"/>
      </geometry>
      <material name="">
        <color rgba="0.792156862745098 0.819607843137255 0.933333333333333 1"/>
      </material>
    </visual>
    <collision>
      <origin rpy="0 0 0" xyz="0 0 0"/>
      <geometry>
        <mesh filename="package://blue_descriptions/meshes/lift_link.STL"/>
      </geometry>
    </collision>
  </link>
  <joint name="right_elbow_roll_joint" type="revolute">
    <origin rpy="-1.5708 1.5673 -3.1416" xyz="0 0.070147 -6.25E-05"/>
    <parent link="right_elbow_lift_link"/>
    <child link="right_wrist_roll_link"/>
    <axis xyz="0 0 1"/>
    <limit effort="0" lower="-2.6761" upper="2.6761" velocity="0"/>
  </joint>
  <link name="right_wrist_roll_link">
    <inertial>
      <origin rpy="0 0 0" xyz="0.00526385736219506 2.70691865020822E-05 -0.0641638075944594"/>
      <mass value="1.41368434923"/>
      <inertia ixx="0.0057866591250737" ixy="3.71515699629511E-07" ixz="-6.32890111626103E-05" iyy="0.00530223654324281" iyz="8.9999884666805E-07" izz="0.00342399181200673"/>
    </inertial>
    <visual>
      <origin rpy="0 0 0" xyz="0 0 0"/>
      <geometry>
        <mesh filename="package://blue_descriptions/meshes/roll_link.STL"/>
      </geometry>
      <material name="">
        <color rgba="1 1 1 1"/>
      </material>
    </visual>
    <collision>
      <origin rpy="0 0 0" xyz="0 0 0"/>
      <geometry>
        <mesh filename="package://blue_descriptions/meshes/roll_link.STL"/>
      </geometry>
    </collision>
  </link>
  <joint name="right_wrist_lift_joint" type="revolute">
    <origin rpy="-1.5708 4.4409E-16 3.1416" xyz="-0.01143 0 -0.18056"/>
    <parent link="right_wrist_roll_link"/>
    <child link="right_wrist_lift_link"/>
    <axis xyz="0 0 1"/>
    <limit effort="0" lower="-2.2944" upper="0" velocity="0"/>
  </joint>
  <link name="right_wrist_lift_link">
    <inertial>
      <origin rpy="0 0 0" xyz="-5.0083559080677E-06 0.000232928456050885 -1.77451392545103E-05"/>
      <mass value="0.448307108622636"/>
      <inertia ixx="0.000804272985961788" ixy="4.84548777859872E-08" ixz="2.09160815704306E-06" iyy="0.000818260636171894" iyz="-1.44954778549764E-08" izz="0.000550840705045094"/>
    </inertial>
    <visual>
      <origin rpy="0 0 0" xyz="0 0 0"/>
      <geometry>
        <mesh filename="package://blue_descriptions/meshes/lift_link.STL"/>
      </geometry>
      <material name="">
        <color rgba="0.792156862745098 0.819607843137255 0.933333333333333 1"/>
      </material>
    </visual>
    <collision>
      <origin rpy="0 0 0" xyz="0 0 0"/>
      <geometry>
        <mesh filename="package://blue_descriptions/meshes/lift_link.STL"/>
      </geometry>
    </collision>
  </link>
  <joint name="right_wrist_roll_joint" type="revolute">
    <origin rpy="-1.5708 0.0 -3.1416" xyz="0 0.070147 -6.25E-05"/>
    <parent link="right_wrist_lift_link"/>
    <child link="right_end_roll_link"/>
    <axis xyz="0 0 1"/>
    <limit effort="0" lower="-2.6761" upper="2.6761" velocity="0"/>
  </joint>
  <link name="right_end_roll_link">
    <inertial>
      <origin rpy="0 0 0" xyz="0.00526385736219506 2.70691865020822E-05 -0.0641638075944594"/>
      <mass value="0.657109755986862"/>
      <inertia ixx="0.0057866591250737" ixy="3.71515699629511E-07" ixz="-6.32890111626103E-05" iyy="0.00530223654324281" iyz="8.9999884666805E-07" izz="0.00342399181200673"/>
    </inertial>
    <visual>
      <origin rpy="0 0 0" xyz="0 0 0"/>
      <geometry>
        <mesh filename="package://blue_descriptions/meshes/wrist_roll_link.STL"/>
      </geometry>
      <material name="">
        <color rgba="1 1 1 1"/>
      </material>
    </visual>
    <collision>
      <origin rpy="0 0 0" xyz="0 0 0"/>
      <geometry>
        <mesh filename="package://blue_descriptions/meshes/wrist_roll_link.STL"/>
      </geometry>
    </collision>
  </link>
  <link name="right_gripper_link">
    <inertial>
      <origin rpy="0 0 0" xyz="-7.00549073506807E-05 2.51271935254316E-05 -0.052367118189184"/>
      <mass value="0.0047109755986862"/>
      <inertia ixx="0.000916887873826385" ixy="-6.04547948818479E-08" ixz="0.6796133363069E-06" iyy="0.000877268801166351" iyz="0.64172907801915E-07" izz="0.000293333065172452"/>
    </inertial>
    <visual>
      <origin rpy="0 0 0" xyz="0 0 0"/>
      <geometry>
        <mesh filename="package://blue_descriptions/meshes/wrist_roll_link.STL"/>
      </geometry>
      <material name="">
        <color rgba="0.792156862745098 0.819607843137255 0.933333333333333 1"/>
      </material>
    </visual>
    <collision>
      <origin rpy="0 0 0" xyz="0 0 0"/>
      <geometry>
        <mesh filename="package://blue_descriptions/meshes/wrist_roll_link.STL"/>
      </geometry>
    </collision>
  </link>
  <joint name="right_gripper_joint" type="revolute">
    <origin rpy="-1.5708 -2.4803E-15 -3.1416" xyz="0 0.070147 -6.25E-05"/>
    <parent link="right_end_roll_link"/>
    <child link="right_gripper_link"/>
    <axis xyz="0 0 1"/>
    <limit effort="0" lower="-2.6761" upper="2.6761" velocity="0"/>
  </joint>
  <link name="left_base_link">
    <inertial>
      <origin rpy="0 0 0" xyz="0.0560024374186662 0.000189445541681321 0.0201835602327798"/>
      <mass value="0.284612172465311"/>
      <inertia ixx="0.000716950374478633" ixy="-4.58477843167981E-06" ixz="4.20772050305934E-06" iyy="0.00197711566495113" iyz="9.13561852910017E-07" izz="0.00239705630031167"/>
    </inertial>
    <visual>
      <origin rpy="0 0 0" xyz="0 0 0"/>
      <geometry>
        <mesh filename="package://blue_descriptions/meshes/arm_base_link.STL"/>
      </geometry>
      <material name="">
        <color rgba="0.792156862745098 0.819607843137255 0.933333333333333 1"/>
      </material>
    </visual>
    <collision>
      <origin rpy="0 0 0" xyz="0 0 0"/>
      <geometry>
        <mesh filename="package://blue_descriptions/meshes/arm_base_link.STL"/>
      </geometry>
    </collision>
  </link>
  <joint name="left_base_roll_joint" type="revolute">
    <origin rpy="3.1416 -2.2011E-29 0.0" xyz="0 0 0.087371"/>
    <parent link="left_base_link"/>
    <child link="left_shoulder_roll_link"/>
    <axis xyz="0 0 1"/>
    <limit effort="0" lower="-2.3412" upper="3.3999" velocity="0"/>
  </joint>
  <transmission name="left_base_roll_joint_transmission">
    <type>transmission_interface/SimpleTransmission</type>
    <joint name="left_base_roll_joint">
      <hardwareInterface>EffortJointInterface</hardwareInterface>
    </joint>
    <actuator name="{side}_base_roll_motor">
      <hardwareInterface>EffortJointInterface</hardwareInterface>
      <mechanicalReduction>1</mechanicalReduction>
    </actuator>
  </transmission>
  <link name="left_shoulder_roll_link">
    <inertial>
      <origin rpy="0 0 0" xyz="0.00526385736219506 2.70691865020822E-05 -0.0641638075944594"/>
      <mass value="1.91396434923"/>
      <inertia ixx="0.0057866591250737" ixy="3.71515699629511E-07" ixz="-6.32890111626103E-05" iyy="0.00530223654324281" iyz="8.9999884666805E-07" izz="0.00342399181200673"/>
    </inertial>
    <visual>
      <origin rpy="0 0 0" xyz="0 0 0"/>
      <geometry>
        <mesh filename="package://blue_descriptions/meshes/roll_link.STL"/>
      </geometry>
      <material name="">
        <color rgba="1 1 1 1"/>
      </material>
    </visual>
    <collision>
      <origin rpy="0 0 0" xyz="0 0 0"/>
      <geometry>
        <mesh filename="package://blue_descriptions/meshes/roll_link.STL"/>
      </geometry>
    </collision>
  </link>
  <joint name="left_shoulder_lift_joint" type="revolute">
    <origin rpy="-1.5708 4.4409E-16 3.1416" xyz="-0.01143 0 -0.18056"/>
    <parent link="left_shoulder_roll_link"/>
    <child link="left_shoulder_lift_link"/>
    <axis xyz="0 0 1"/>
    <limit effort="0" lower="-2.2944" upper="0" velocity="0"/>
  </joint>
  <link name="left_shoulder_lift_link">
    <inertial>
      <origin rpy="0 0 0" xyz="-5.0083559080677E-06 0.000232928456050885 -1.77451392545103E-05"/>
      <mass value="0.448307108622636"/>
      <inertia ixx="0.000804272985961788" ixy="4.84548777859872E-08" ixz="2.09160815704306E-06" iyy="0.000818260636171894" iyz="-1.44954778549764E-08" izz="0.000550840705045094"/>
    </inertial>
    <visual>
      <origin rpy="0 0 0" xyz="0 0 0"/>
      <geometry>
        <mesh filename="package://blue_descriptions/meshes/lift_link.STL"/>
      </geometry>
      <material name="">
        <color rgba="0.792156862745098 0.819607843137255 0.933333333333333 1"/>
      </material>
    </visual>
    <collision>
      <origin rpy="0 0 0" xyz="0 0 0"/>
      <geometry>
        <mesh filename="package://blue_descriptions/meshes/lift_link.STL"/>
      </geometry>
    </collision>
  </link>
  <joint name="left_shoulder_roll_joint" type="revolute">
    <origin rpy="-1.5708 1.5673 -3.1416" xyz="0 0.070147 -6.25E-05"/>
    <parent link="left_shoulder_lift_link"/>
    <child link="left_elbow_roll_link"/>
    <axis xyz="0 0 1"/>
    <limit effort="0" lower="-2.6761" upper="2.6761" velocity="0"/>
  </joint>
  <link name="left_elbow_roll_link">
    <inertial>
      <origin rpy="0 0 0" xyz="0.00526385736219506 2.70691865020822E-05 -0.0641638075944594"/>
      <mass value="1.91396434923"/>
      <inertia ixx="0.0057866591250737" ixy="3.71515699629511E-07" ixz="-6.32890111626103E-05" iyy="0.00530223654324281" iyz="8.9999884666805E-07" izz="0.00342399181200673"/>
    </inertial>
    <visual>
      <origin rpy="0 0 0" xyz="0 0 0"/>
      <geometry>
        <mesh filename="package://blue_descriptions/meshes/roll_link.STL"/>
      </geometry>
      <material name="">
        <color rgba="1 1 1 1"/>
      </material>
    </visual>
    <collision>
      <origin rpy="0 0 0" xyz="0 0 0"/>
      <geometry>
        <mesh filename="package://blue_descriptions/meshes/roll_link.STL"/>
      </geometry>
    </collision>
  </link>
  <joint name="left_elbow_lift_joint" type="revolute">
    <origin rpy="-1.5708 4.4409E-16 3.1416" xyz="-0.01143 0 -0.18056"/>
    <parent link="left_elbow_roll_link"/>
    <child link="left_elbow_lift_link"/>
    <axis xyz="0 0 1"/>
    <limit effort="0" lower="-2.2944" upper="0" velocity="0"/>
  </joint>
  <link name="left_elbow_lift_link">
    <inertial>
      <origin rpy="0 0 0" xyz="-5.0083559080677E-06 0.000232928456050885 -1.77451392545103E-05"/>
      <mass value="0.448307108622636"/>
      <inertia ixx="0.000804272985961788" ixy="4.84548777859872E-08" ixz="2.09160815704306E-06" iyy="0.000818260636171894" iyz="-1.44954778549764E-08" izz="0.000550840705045094"/>
    </inertial>
    <visual>
      <origin rpy="0 0 0" xyz="0 0 0"/>
      <geometry>
        <mesh filename="package://blue_descriptions/meshes/lift_link.STL"/>
      </geometry>
      <material name="">
        <color rgba="0.792156862745098 0.819607843137255 0.933333333333333 1"/>
      </material>
    </visual>
    <collision>
      <origin rpy="0 0 0" xyz="0 0 0"/>
      <geometry>
        <mesh filename="package://blue_descriptions/meshes/lift_link.STL"/>
      </geometry>
    </collision>
  </link>
  <joint name="left_elbow_roll_joint" type="revolute">
    <origin rpy="-1.5708 -1.5673 -3.1416" xyz="0 0.070147 -6.25E-05"/>
    <parent link="left_elbow_lift_link"/>
    <child link="left_wrist_roll_link"/>
    <axis xyz="0 0 1"/>
    <limit effort="0" lower="-2.6761" upper="2.6761" velocity="0"/>
  </joint>
  <link name="left_wrist_roll_link">
    <inertial>
      <origin rpy="0 0 0" xyz="0.00526385736219506 2.70691865020822E-05 -0.0641638075944594"/>
      <mass value="1.41368434923"/>
      <inertia ixx="0.0057866591250737" ixy="3.71515699629511E-07" ixz="-6.32890111626103E-05" iyy="0.00530223654324281" iyz="8.9999884666805E-07" izz="0.00342399181200673"/>
    </inertial>
    <visual>
      <origin rpy="0 0 0" xyz="0 0 0"/>
      <geometry>
        <mesh filename="package://blue_descriptions/meshes/roll_link.STL"/>
      </geometry>
      <material name="">
        <color rgba="1 1 1 1"/>
      </material>
    </visual>
    <collision>
      <origin rpy="0 0 0" xyz="0 0 0"/>
      <geometry>
        <mesh filename="package://blue_descriptions/meshes/roll_link.STL"/>
      </geometry>
    </collision>
  </link>
  <joint name="left_wrist_lift_joint" type="revolute">
    <origin rpy="-1.5708 4.4409E-16 3.1416" xyz="-0.01143 0 -0.18056"/>
    <parent link="left_wrist_roll_link"/>
    <child link="left_wrist_lift_link"/>
    <axis xyz="0 0 1"/>
    <limit effort="0" lower="-2.2944" upper="0" velocity="0"/>
  </joint>
  <link name="left_wrist_lift_link">
    <inertial>
      <origin rpy="0 0 0" xyz="-5.0083559080677E-06 0.000232928456050885 -1.77451392545103E-05"/>
      <mass value="0.448307108622636"/>
      <inertia ixx="0.000804272985961788" ixy="4.84548777859872E-08" ixz="2.09160815704306E-06" iyy="0.000818260636171894" iyz="-1.44954778549764E-08" izz="0.000550840705045094"/>
    </inertial>
    <visual>
      <origin rpy="0 0 0" xyz="0 0 0"/>
      <geometry>
        <mesh filename="package://blue_descriptions/meshes/lift_link.STL"/>
      </geometry>
      <material name="">
        <color rgba="0.792156862745098 0.819607843137255 0.933333333333333 1"/>
      </material>
    </visual>
    <collision>
      <origin rpy="0 0 0" xyz="0 0 0"/>
      <geometry>
        <mesh filename="package://blue_descriptions/meshes/lift_link.STL"/>
      </geometry>
    </collision>
  </link>
  <joint name="left_wrist_roll_joint" type="revolute">
    <origin rpy="-1.5708 0.0 -3.1416" xyz="0 0.070147 -6.25E-05"/>
    <parent link="left_wrist_lift_link"/>
    <child link="left_end_roll_link"/>
    <axis xyz="0 0 1"/>
    <limit effort="0" lower="-2.6761" upper="2.6761" velocity="0"/>
  </joint>
  <link name="left_end_roll_link">
    <inertial>
      <origin rpy="0 0 0" xyz="0.00526385736219506 2.70691865020822E-05 -0.0641638075944594"/>
      <mass value="0.657109755986862"/>
      <inertia ixx="0.0057866591250737" ixy="3.71515699629511E-07" ixz="-6.32890111626103E-05" iyy="0.00530223654324281" iyz="8.9999884666805E-07" izz="0.00342399181200673"/>
    </inertial>
    <visual>
      <origin rpy="0 0 0" xyz="0 0 0"/>
      <geometry>
        <mesh filename="package://blue_descriptions/meshes/wrist_roll_link.STL"/>
      </geometry>
      <material name="">
        <color rgba="1 1 1 1"/>
      </material>
    </visual>
    <collision>
      <origin rpy="0 0 0" xyz="0 0 0"/>
      <geometry>
        <mesh filename="package://blue_descriptions/meshes/wrist_roll_link.STL"/>
      </geometry>
    </collision>
  </link>
  <link name="left_gripper_link">
    <inertial>
      <origin rpy="0 0 0" xyz="-7.00549073506807E-05 2.51271935254316E-05 -0.052367118189184"/>
      <mass value="0.0047109755986862"/>
      <inertia ixx="0.000916887873826385" ixy="-6.04547948818479E-08" ixz="0.6796133363069E-06" iyy="0.000877268801166351" iyz="0.64172907801915E-07" izz="0.000293333065172452"/>
    </inertial>
    <visual>
      <origin rpy="0 0 0" xyz="0 0 0"/>
      <geometry>
        <mesh filename="package://blue_descriptions/meshes/wrist_roll_link.STL"/>
      </geometry>
      <material name="">
        <color rgba="0.792156862745098 0.819607843137255 0.933333333333333 1"/>
      </material>
    </visual>
    <collision>
      <origin rpy="0 0 0" xyz="0 0 0"/>
      <geometry>
        <mesh filename="package://blue_descriptions/meshes/wrist_roll_link.STL"/>
      </geometry>
    </collision>
  </link>
  <joint name="left_gripper_joint" type="revolute">
    <origin rpy="-1.5708 -2.4803E-15 -3.1416" xyz="0 0.070147 -6.25E-05"/>
    <parent link="left_end_roll_link"/>
    <child link="left_gripper_link"/>
    <axis xyz="0 0 1"/>
    <limit effort="0" lower="-2.6761" upper="2.6761" velocity="0"/>
  </joint>
</robot>

