<robot
  name="koko_description_sevendof_dyn">
  <link
    name="base_link">
    <inertial>
      <origin
        xyz="0.061912726070498 -0.131976338016041 0.172003773309897"
        rpy="0 0 0" />
      <mass
        value="1.94088320787417" />
      <inertia
        ixx="0.0480445534654547"
        ixy="-0.00145572884627457"
        ixz="0.00634784793954399"
        iyy="0.0423461925754069"
        iyz="0.00437034622659849"
        izz="0.0161997040881344" />
    </inertial>
    <visual>
      <origin
        xyz="0 0 0"
        rpy="0 0 0" />
      <geometry>
        <mesh
          filename="package://koko_description_sevendof_dyn/meshes/base_link.STL" />
      </geometry>
      <material
        name="">
        <color
          rgba="0.792156862745098 0.819607843137255 0.933333333333333 1" />
      </material>
    </visual>
    <collision>
      <origin
        xyz="0 0 0"
        rpy="0 0 0" />
      <geometry>
        <mesh
          filename="package://koko_description_sevendof_dyn/meshes/base_link.STL" />
      </geometry>
    </collision>
  </link>
  <link
    name="shoulder_link">
    <inertial>
      <origin
        xyz="0.00434342559631096 1.27124870743511E-05 -0.0764609376252017"
        rpy="0 0 0" />
      <mass
        value="1.80875740468163" />
      <inertia
        ixx="0.00919231463720921"
        ixy="4.24505063128799E-07"
        ixz="0.00010200472553235"
        iyy="0.00871814222028264"
        iyz="2.5551495904983E-06"
        izz="0.0038795627921337" />
    </inertial>
    <visual>
      <origin
        xyz="0 0 0"
        rpy="0 0 0" />
      <geometry>
        <mesh
          filename="package://koko_description_sevendof_dyn/meshes/shoulder_link.STL" />
      </geometry>
      <material
        name="">
        <color
          rgba="0.843137254901961 0.815686274509804 0.752941176470588 1" />
      </material>
    </visual>
    <collision>
      <origin
        xyz="0 0 0"
        rpy="0 0 0" />
      <geometry>
        <mesh
          filename="package://koko_description_sevendof_dyn/meshes/shoulder_link.STL" />
      </geometry>
    </collision>
  </link>
  <joint
    name="base_roll_joint"
    type="revolute">
    <origin
      xyz="0.090179 -0.090805 0.21216"
      rpy="-3.1416 -0.7854 3.1416" />
    <parent
      link="base_link" />
    <child
      link="shoulder_link" />
    <axis
      xyz="0 0 1" />
    <limit
      lower="-2.3412"
      upper="3.3999"
      effort="0"
      velocity="0" />
  </joint>
  <link
    name="shoulder_lift_link">
    <inertial>
      <origin
        xyz="-5.00863820010466E-06 0.000232929106567414 -1.77456683619348E-05"
        rpy="0 0 0" />
      <mass
        value="0.488307110624732" />
      <inertia
        ixx="0.000804243037161081"
        ixy="4.84530841153607E-08"
        ixz="2.09161175082308E-06"
        iyy="0.000818230768279185"
        iyz="-1.4499612416288E-08"
        izz="0.00055084078789417" />
    </inertial>
    <visual>
      <origin
        xyz="0 0 0"
        rpy="0 0 0" />
      <geometry>
        <mesh
          filename="package://koko_description_sevendof_dyn/meshes/shoulder_lift_link.STL" />
      </geometry>
      <material
        name="">
        <color
          rgba="0.792156862745098 0.819607843137255 0.933333333333333 1" />
      </material>
    </visual>
    <collision>
      <origin
        xyz="0 0 0"
        rpy="0 0 0" />
      <geometry>
        <mesh
          filename="package://koko_description_sevendof_dyn/meshes/shoulder_lift_link.STL" />
      </geometry>
    </collision>
  </link>
  <joint
    name="shoulder_lift_joint"
    type="revolute">
    <origin
      xyz="-0.01143 0 -0.21082"
      rpy="-1.5708 4.4409E-16 3.1416" />
    <parent
      link="shoulder_link" />
    <child
      link="shoulder_lift_link" />
    <axis
      xyz="0 0 1" />
    <limit
      lower="-2.2944"
      upper="0"
      effort="0"
      velocity="0" />
  </joint>
  <link
    name="upper_arm_link">
    <inertial>
      <origin
        xyz="0.00934839640309615 6.68873049121943E-05 -0.0661062613570598"
        rpy="0 0 0" />
      <mass
        value="1.80875740468163" />
      <inertia
        ixx="0.00919231463720921"
        ixy="4.24505063128799E-07"
        ixz="0.00010200472553235"
        iyy="0.00871814222028264"
        iyz="2.5551495904983E-06"
        izz="0.0038795627921337" />
    </inertial>
    <visual>
      <origin
        xyz="0 0 0"
        rpy="0 0 0" />
      <geometry>
        <mesh
          filename="package://koko_description_sevendof_dyn/meshes/upper_arm_link.STL" />
      </geometry>
      <material
        name="">
        <color
          rgba="0.698039215686274 0.698039215686274 0.698039215686274 1" />
      </material>
    </visual>
    <collision>
      <origin
        xyz="0 0 0"
        rpy="0 0 0" />
      <geometry>
        <mesh
          filename="package://koko_description_sevendof_dyn/meshes/upper_arm_link.STL" />
      </geometry>
    </collision>
  </link>
  <joint
    name="shoulder_roll_joint"
    type="revolute">
    <origin
      xyz="0 0.070147 -6.25E-05"
      rpy="-1.5708 1.5673 -3.1416" />
    <parent
      link="shoulder_lift_link" />
    <child
      link="upper_arm_link" />
    <axis
      xyz="0 0 1" />
    <limit
      lower="-2.6761"
      upper="2.6761"
      effort="0"
      velocity="0" />
  </joint>
  <link
    name="upper_arm_lift_link">
    <inertial>
      <origin
        xyz="8.90642415374288E-09 -0.00233330243097829 -1.63703075876653E-05"
        rpy="0 0 0" />
      <mass
        value="0.488307110624732" />
      <inertia
        ixx="0.000804243037161081"
        ixy="4.84530841153607E-08"
        ixz="2.09161175082308E-06"
        iyy="0.000818230768279185"
        iyz="-1.4499612416288E-08"
        izz="0.00055084078789417" />
    </inertial>
    <visual>
      <origin
        xyz="0 0 0"
        rpy="0 0 0" />
      <geometry>
        <mesh
          filename="package://koko_description_sevendof_dyn/meshes/upper_arm_lift_link.STL" />
      </geometry>
      <material
        name="">
        <color
          rgba="1 0.501960784313725 0.501960784313725 1" />
      </material>
    </visual>
    <collision>
      <origin
        xyz="0 0 0"
        rpy="0 0 0" />
      <geometry>
        <mesh
          filename="package://koko_description_sevendof_dyn/meshes/upper_arm_lift_link.STL" />
      </geometry>
    </collision>
  </link>
  <joint
    name="elbow_lift_joint"
    type="revolute">
    <origin
      xyz="-0.01143 -4.0407E-05 -0.18056"
      rpy="-1.5708 -8.5189E-16 -3.1381" />
    <parent
      link="upper_arm_link" />
    <child
      link="upper_arm_lift_link" />
    <axis
      xyz="0 0 1" />
    <limit
      lower="-2.2944"
      upper="0"
      effort="0"
      velocity="0" />
  </joint>
  <link
    name="forearm_link">
    <inertial>
      <origin
        xyz="0.00934998982051749 3.27761186069697E-05 -0.0661031835571719"
        rpy="0 0 0" />
      <mass
        value="1.60908907189915" />
      <inertia
        ixx="0.00597699605445767"
        ixy="1.44314016958643E-07"
        ixz="0.000154395040971567"
        iyy="0.00594036468970244"
        iyz="1.36567647958003E-06"
        izz="0.00395812933427153" />
    </inertial>
    <visual>
      <origin
        xyz="0 0 0"
        rpy="0 0 0" />
      <geometry>
        <mesh
          filename="package://koko_description_sevendof_dyn/meshes/forearm_link.STL" />
      </geometry>
      <material
        name="">
        <color
          rgba="0.698039215686274 0.698039215686274 0.698039215686274 1" />
      </material>
    </visual>
    <collision>
      <origin
        xyz="0 0 0"
        rpy="0 0 0" />
      <geometry>
        <mesh
          filename="package://koko_description_sevendof_dyn/meshes/forearm_link.STL" />
      </geometry>
    </collision>
  </link>
  <joint
    name="elbow_roll_joint"
    type="revolute">
    <origin
      xyz="0 0.070147 -6.25E-05"
      rpy="1.5708 -1.5708 0" />
    <parent
      link="upper_arm_lift_link" />
    <child
      link="forearm_link" />
    <axis
      xyz="0 0 1" />
    <limit
      lower="-2.6761"
      upper="2.6761"
      effort="0"
      velocity="0" />
  </joint>
  <link
    name="wrist_lift_link">
    <inertial>
      <origin
        xyz="-5.00422220223173E-06 0.000232915164728009 -1.77453514126902E-05"
        rpy="0 0 0" />
      <mass
        value="0.488307111938316" />
      <inertia
        ixx="0.000804244516684997"
        ixy="4.84491534221792E-08"
        ixz="2.09169530430157E-06"
        iyy="0.000818232034965877"
        iyz="-1.44701984277169E-08"
        izz="0.000550840554091768" />
    </inertial>
    <visual>
      <origin
        xyz="0 0 0"
        rpy="0 0 0" />
      <geometry>
        <mesh
          filename="package://koko_description_sevendof_dyn/meshes/wrist_lift_link.STL" />
      </geometry>
      <material
        name="">
        <color
          rgba="0.792156862745098 0.819607843137255 0.933333333333333 1" />
      </material>
    </visual>
    <collision>
      <origin
        xyz="0 0 0"
        rpy="0 0 0" />
      <geometry>
        <mesh
          filename="package://koko_description_sevendof_dyn/meshes/wrist_lift_link.STL" />
      </geometry>
    </collision>
  </link>
  <joint
    name="wrist_lift_joint"
    type="revolute">
    <origin
      xyz="-0.01143 0 -0.18056"
      rpy="-1.5708 6.6613E-16 -3.1416" />
    <parent
      link="forearm_link" />
    <child
      link="wrist_lift_link" />
    <axis
      xyz="0 0 1" />
    <limit
      lower="-2.2944"
      upper="0"
      effort="0"
      velocity="0" />
  </joint>
  <link
    name="wrist_roll_link">
    <inertial>
      <origin
        xyz="0.0155651397472545 1.85611654753837E-05 -0.0552951185087998"
        rpy="0 0 0" />
      <mass
        value="0.752315567506482" />
      <inertia
        ixx="0.00101003273372069"
        ixy="3.9469330287074E-08"
        ixz="4.56462825935364E-05"
        iyy="0.00117139240026558"
        iyz="5.49055314735547E-07"
        izz="0.000579478321956063" />
    </inertial>
    <visual>
      <origin
        xyz="0 0 0"
        rpy="0 0 0" />
      <geometry>
        <mesh
          filename="package://koko_description_sevendof_dyn/meshes/wrist_roll_link.STL" />
      </geometry>
      <material
        name="">
        <color
          rgba="0.792156862745098 0.819607843137255 0.933333333333333 1" />
      </material>
    </visual>
    <collision>
      <origin
        xyz="0 0 0"
        rpy="0 0 0" />
      <geometry>
        <mesh
          filename="package://koko_description_sevendof_dyn/meshes/wrist_roll_link.STL" />
      </geometry>
    </collision>
  </link>
  <joint
    name="wrist_roll_joint"
    type="revolute">
    <origin
      xyz="0 0.070147 -6.25E-05"
      rpy="-1.5708 -2.4803E-15 -3.1416" />
    <parent
      link="wrist_lift_link" />
    <child
      link="wrist_roll_link" />
    <axis
      xyz="0 0 1" />
    <limit
      lower="-2.6761"
      upper="2.6761"
      effort="0"
      velocity="0" />
  </joint>
</robot>
