<robot
  name="koko_description_sevendof_dyn">
  <link
    name="base_link">
    <inertial>
      <origin
        xyz="0.0560024374186662 0.000189445541681321 0.0201835602327798"
        rpy="0 0 0" />
      <mass
        value="0.284612172465311" />
      <inertia
        ixx="0.000716950374478633"
        ixy="-4.58477843167981E-06"
        ixz="4.20772050305934E-06"
        iyy="0.00197711566495113"
        iyz="9.13561852910017E-07"
        izz="0.00239705630031167" />
    </inertial>
    <visual>
      <origin
        xyz="0 0 0"
        rpy="0 0 0" />
      <geometry>
        <mesh
          filename="package://koko_description_sevendof_dyn/meshes/base_link.STL" />
      </geometry>
      <material
        name="">
        <color
          rgba="0.792156862745098 0.819607843137255 0.933333333333333 1" />
      </material>
    </visual>
    <collision>
      <origin
        xyz="0 0 0"
        rpy="0 0 0" />
      <geometry>
        <mesh
          filename="package://koko_description_sevendof_dyn/meshes/base_link.STL" />
      </geometry>
    </collision>
  </link>
  <link
    name="shoulder_link">
    <inertial>
      <origin
        xyz="0.0043477541389173 2.01234773878345E-05 -0.0764683318824377"
        rpy="0 0 0" />
      <mass
        value="1.90901122392276" />
      <inertia
        ixx="0.0091937456982913"
        ixy="1.27362263865398E-08"
        ixz="0.00010247865043886"
        iyy="0.00871917388181738"
        iyz="3.26622166777351E-06"
        izz="0.00388062453070139" />
    </inertial>
    <visual>
      <origin
        xyz="0 0 0"
        rpy="0 0 0" />
      <geometry>
        <mesh
          filename="package://koko_description_sevendof_dyn/meshes/shoulder_link.STL" />
      </geometry>
      <material
        name="">
        <color
          rgba="0.843137254901961 0.815686274509804 0.752941176470588 1" />
      </material>
    </visual>
    <collision>
      <origin
        xyz="0 0 0"
        rpy="0 0 0" />
      <geometry>
        <mesh
          filename="package://koko_description_sevendof_dyn/meshes/shoulder_link.STL" />
      </geometry>
    </collision>
  </link>
  <joint
    name="base_roll_joint"
    type="revolute">
    <origin
      xyz="0 0 0.054356"
      rpy="3.1416 -2.2011E-29 0.0" />
    <parent
      link="base_link" />
    <child
      link="shoulder_link" />
    <axis
      xyz="0 0 1" />
    <limit
      lower="-3.3999"
      upper="2.3412"
      effort="0"
      velocity="0" />
  </joint>
  <link
    name="shoulder_lift_link">
    <inertial>
      <origin
        xyz="-5.0083559080677E-06 0.000232928456050885 -1.77451392545103E-05"
        rpy="0 0 0" />
      <mass
        value="0.488307108622636" />
      <inertia
        ixx="0.000804272985961788"
        ixy="4.84548777859872E-08"
        ixz="2.09160815704306E-06"
        iyy="0.000818260636171894"
        iyz="-1.44954778549764E-08"
        izz="0.000550840705045094" />
    </inertial>
    <visual>
      <origin
        xyz="0 0 0"
        rpy="0 0 0" />
      <geometry>
        <mesh
          filename="package://koko_description_sevendof_dyn/meshes/shoulder_lift_link.STL" />
      </geometry>
      <material
        name="">
        <color
          rgba="0.792156862745098 0.819607843137255 0.933333333333333 1" />
      </material>
    </visual>
    <collision>
      <origin
        xyz="0 0 0"
        rpy="0 0 0" />
      <geometry>
        <mesh
          filename="package://koko_description_sevendof_dyn/meshes/shoulder_lift_link.STL" />
      </geometry>
    </collision>
  </link>
  <joint
    name="shoulder_lift_joint"
    type="revolute">
    <origin
      xyz="-0.01143 0 -0.21082"
      rpy="-1.5708 4.4409E-16 3.1416" />
    <parent
      link="shoulder_link" />
    <child
      link="shoulder_lift_link" />
    <axis
      xyz="0 0 1" />
    <limit
      lower="-2.2944"
      upper="0"
      effort="0"
      velocity="0" />
  </joint>
  <link
    name="upper_arm_link">
    <inertial>
      <origin
        xyz="0.0052656488201055 5.32997221069781E-05 -0.0641725544925586"
        rpy="0 0 0" />
      <mass
        value="1.92396434922939" />
      <inertia
        ixx="0.00578789299599043"
        ixy="1.90247522695056E-06"
        ixz="-6.31088143287672E-05"
        iyy="0.00530315640050716"
        iyz="1.26895335190205E-06"
        izz="0.00342501474546171" />
    </inertial>
    <visual>
      <origin
        xyz="0 0 0"
        rpy="0 0 0" />
      <geometry>
        <mesh
          filename="package://koko_description_sevendof_dyn/meshes/upper_arm_link.STL" />
      </geometry>
      <material
        name="">
        <color
          rgba="1 1 1 1" />
      </material>
    </visual>
    <collision>
      <origin
        xyz="0 0 0"
        rpy="0 0 0" />
      <geometry>
        <mesh
          filename="package://koko_description_sevendof_dyn/meshes/upper_arm_link.STL" />
      </geometry>
    </collision>
  </link>
  <joint
    name="shoulder_roll_joint"
    type="revolute">
    <origin
      xyz="0 0.070147 -6.25E-05"
      rpy="-1.5708 -1.5673 -3.1416" />
    <parent
      link="shoulder_lift_link" />
    <child
      link="upper_arm_link" />
    <axis
      xyz="0 0 1" />
    <limit
      lower="-2.6761"
      upper="2.6761"
      effort="0"
      velocity="0" />
  </joint>
  <link
    name="upper_arm_lift_link">
    <inertial>
      <origin
        xyz="9.06307628945058E-09 -0.00233330219603445 -1.63700112519316E-05"
        rpy="0 0 0" />
      <mass
        value="0.436087767400233" />
      <inertia
        ixx="0.000748389205107341"
        ixy="-4.35589119855736E-12"
        ixz="2.09357080801154E-06"
        iyy="0.00080505708271284"
        iyz="-3.61399621116489E-08"
        izz="0.000495723704552229" />
    </inertial>
    <visual>
      <origin
        xyz="0 0 0"
        rpy="0 0 0" />
      <geometry>
        <mesh
          filename="package://koko_description_sevendof_dyn/meshes/upper_arm_lift_link.STL" />
      </geometry>
      <material
        name="">
        <color
          rgba="1 0.501960784313725 0.501960784313725 1" />
      </material>
    </visual>
    <collision>
      <origin
        xyz="0 0 0"
        rpy="0 0 0" />
      <geometry>
        <mesh
          filename="package://koko_description_sevendof_dyn/meshes/upper_arm_lift_link.STL" />
      </geometry>
    </collision>
  </link>
  <joint
    name="elbow_lift_joint"
    type="revolute">
    <origin
      xyz="-0.01143 -4.0407E-05 -0.18056"
      rpy="-1.5708 -8.5189E-16 -3.1381" />
    <parent
      link="upper_arm_link" />
    <child
      link="upper_arm_lift_link" />
    <axis
      xyz="0 0 1" />
    <limit
      lower="-2.2944"
      upper="0"
      effort="0"
      velocity="0" />
  </joint>
  <link
    name="forearm_link">
    <inertial>
      <origin
        xyz="0.00526385736219506 2.70691865020822E-05 -0.0641638075944594"
        rpy="0 0 0" />
      <mass
        value="1.52367945216034" />
      <inertia
        ixx="0.0057866591250737"
        ixy="3.71515699629511E-07"
        ixz="-6.32890111626103E-05"
        iyy="0.00530223654324281"
        iyz="8.9999884666805E-07"
        izz="0.00342399181200673" />
    </inertial>
    <visual>
      <origin
        xyz="0 0 0"
        rpy="0 0 0" />
      <geometry>
        <mesh
          filename="package://koko_description_sevendof_dyn/meshes/forearm_link.STL" />
      </geometry>
      <material
        name="">
        <color
          rgba="1 1 1 1" />
      </material>
    </visual>
    <collision>
      <origin
        xyz="0 0 0"
        rpy="0 0 0" />
      <geometry>
        <mesh
          filename="package://koko_description_sevendof_dyn/meshes/forearm_link.STL" />
      </geometry>
    </collision>
  </link>
  <joint
    name="elbow_roll_joint"
    type="revolute">
    <origin
      xyz="0 0.070147 -6.25E-05"
      rpy="1.5708 1.5708 0" />
    <parent
      link="upper_arm_lift_link" />
    <child
      link="forearm_link" />
    <axis
      xyz="0 0 1" />
    <limit
      lower="-2.6761"
      upper="2.6761"
      effort="0"
      velocity="0" />
  </joint>
  <link
    name="wrist_lift_link">
    <inertial>
      <origin
        xyz="-5.0041305142412E-06 0.000232915126013089 -1.77452141933987E-05"
        rpy="0 0 0" />
      <mass
        value="0.488307111315058" />
      <inertia
        ixx="0.000804244148456861"
        ixy="4.84475098854999E-08"
        ixz="2.09169561517307E-06"
        iyy="0.00081823161778444"
        iyz="-1.44597555369205E-08"
        izz="0.000550840502999506" />
    </inertial>
    <visual>
      <origin
        xyz="0 0 0"
        rpy="0 0 0" />
      <geometry>
        <mesh
          filename="package://koko_description_sevendof_dyn/meshes/wrist_lift_link.STL" />
      </geometry>
      <material
        name="">
        <color
          rgba="0.792156862745098 0.819607843137255 0.933333333333333 1" />
      </material>
    </visual>
    <collision>
      <origin
        xyz="0 0 0"
        rpy="0 0 0" />
      <geometry>
        <mesh
          filename="package://koko_description_sevendof_dyn/meshes/wrist_lift_link.STL" />
      </geometry>
    </collision>
  </link>
  <joint
    name="wrist_lift_joint"
    type="revolute">
    <origin
      xyz="-0.01143 0 -0.18056"
      rpy="-1.5708 6.6613E-16 -3.1416" />
    <parent
      link="forearm_link" />
    <child
      link="wrist_lift_link" />
    <axis
      xyz="0 0 1" />
    <limit
      lower="-2.2944"
      upper="0"
      effort="0"
      velocity="0" />
  </joint>
  <link
    name="wrist_roll_link">
    <inertial>
      <origin
        xyz="-7.00549073506807E-05 2.51271935254316E-05 0.052367118189184"
        rpy="0 0 0" />
      <mass
        value="0.657109755986862" />
      <inertia
        ixx="0.001916887873826385"
        ixy="-12.04547948818479E-08"
        ixz="2.8796133363069E-06"
        iyy="0.001877268801166351"
        iyz="9.64172907801915E-07"
        izz="0.000693333065172452" />
    </inertial>
    <visual>
      <origin
        xyz="0 0 0.1"
        rpy="0 0 0" />
      <geometry>
        <mesh
          filename="package://koko_description_sevendof_dyn/meshes/wrist_roll_link.STL" />
      </geometry>
      <material
        name="">
        <color
          rgba="0.792156862745098 0.819607843137255 0.933333333333333 1" />
      </material>
    </visual>
    <collision>
      <origin
        xyz="0 0 0.1"
        rpy="0 0 0" />
      <geometry>
        <mesh
          filename="package://koko_description_sevendof_dyn/meshes/wrist_roll_link.STL" />
      </geometry>
    </collision>
  </link>
  <joint
    name="wrist_roll_joint"
    type="revolute">
    <origin
      xyz="0 0.170147 -6.25E-05"
      rpy="-1.5708 -2.4803E-15 -3.1416" />
    <parent
      link="wrist_lift_link" />
    <child
      link="wrist_roll_link" />
    <axis
      xyz="0 0 1" />
    <limit
      lower="-2.6761"
      upper="2.6761"
      effort="0"
      velocity="0" />
  </joint>

  <link
    name="gripper_link">
    <inertial>
      <origin
        xyz="-7.00549073506807E-05 2.51271935254316E-05 -0.052367118189184"
        rpy="0 0 0" />
      <mass
        value="0.0047109755986862" />
      <inertia
        ixx="0.000916887873826385"
        ixy="-6.04547948818479E-08"
        ixz="0.6796133363069E-06"
        iyy="0.000877268801166351"
        iyz="0.64172907801915E-07"
        izz="0.000293333065172452" />
    </inertial>
    <visual>
      <origin
        xyz="0 0 0"
        rpy="0 0 0" />
      <geometry>
        <mesh
          filename="package://koko_description_sevendof_dyn/meshes/wrist_roll_link.STL" />
      </geometry>
      <material
        name="">
        <color
          rgba="0.792156862745098 0.819607843137255 0.933333333333333 1" />
      </material>
    </visual>
    <collision>
      <origin
        xyz="0 0 0"
        rpy="0 0 0" />
      <geometry>
        <mesh
          filename="package://koko_description_sevendof_dyn/meshes/wrist_roll_link.STL" />
      </geometry>
    </collision>
  </link>
  <joint
    name="gripper_joint"
    type="revolute">
    <origin
      xyz="0 0.070147 -6.25E-05"
      rpy="-1.5708 -2.4803E-15 -3.1416" />
    <parent
      link="wrist_roll_link" />
    <child
      link="gripper_link" />
    <axis
      xyz="0 0 1" />
    <limit
      lower="-2.6761"
      upper="2.6761"
      effort="0"
      velocity="0" />
  </joint>
</robot>
