<robot
  name="koko_description_sevendof_dyn">
  <link
    name="base_link">
    <inertial>
      <origin
        xyz="-0.00237523347377377 -0.151716508000078 0.133562829732358"
        rpy="0 0 0" />
      <mass
        value="0.210349130857436" />
      <inertia
        ixx="0.00131121369995894"
        ixy="-3.09612215629085E-09"
        ixz="0.000877219836284733"
        iyy="0.00192535968443975"
        iyz="-4.97712053712446E-09"
        izz="0.00130019808275353" />
    </inertial>
    <visual>
      <origin
        xyz="0 0 0"
        rpy="0 0 0" />
      <geometry>
        <mesh
          filename="package://koko_description_sevendof_dyn/meshes/base_link.STL" />
      </geometry>
      <material
        name="">
        <color
          rgba="0.792156862745098 0.819607843137255 0.933333333333333 1" />
      </material>
    </visual>
    <collision>
      <origin
        xyz="0 0 0"
        rpy="0 0 0" />
      <geometry>
        <mesh
          filename="package://koko_description_sevendof_dyn/meshes/base_link.STL" />
      </geometry>
    </collision>
  </link>
  <link
    name="shoulder_link">
    <inertial>
      <origin
        xyz="-0.00743517471170177 -2.54851470225526E-05 0.0801698853492558"
        rpy="0 0 0" />
      <mass
        value="4.06056876982499" />
      <inertia
        ixx="0.00615620942382813"
        ixy="-5.46011663772249E-07"
        ixz="-3.97587440578392E-06"
        iyy="0.00629834775099024"
        iyz="-3.0177055223955E-07"
        izz="0.0059208626070329" />
    </inertial>
    <visual>
      <origin
        xyz="0 0 0"
        rpy="0 0 0" />
      <geometry>
        <mesh
          filename="package://koko_description_sevendof_dyn/meshes/shoulder_link.STL" />
      </geometry>
      <material
        name="">
        <color
          rgba="0.843137254901961 0.815686274509804 0.752941176470588 1" />
      </material>
    </visual>
    <collision>
      <origin
        xyz="0 0 0"
        rpy="0 0 0" />
      <geometry>
        <mesh
          filename="package://koko_description_sevendof_dyn/meshes/shoulder_link.STL" />
      </geometry>
    </collision>
  </link>
  <joint
    name="base_roll_joint"
    type="revolute">
    <origin
      xyz="0.011376 -0.15172 0.15127"
      rpy="6.8694E-15 0.7854 4.8574E-15" />
    <parent
      link="base_link" />
    <child
      link="shoulder_link" />
    <axis
      xyz="0 0 1" />
    <limit
      lower="-3"
      upper="3"
      effort="0"
      velocity="0" />
  </joint>
  <link
    name="shoulder_lift_link">
    <inertial>
      <origin
        xyz="-0.000649360001133747 0.0018341698280111 -4.86294034485191E-08"
        rpy="0 0 0" />
      <mass
        value="0.437261741071288" />
      <inertia
        ixx="0.00102928990774849"
        ixy="-2.02340993424991E-05"
        ixz="-6.06474525717958E-07"
        iyy="0.00107938293233553"
        iyz="-8.02767235050571E-07"
        izz="0.000657422305858597" />
    </inertial>
    <visual>
      <origin
        xyz="0 0 0"
        rpy="0 0 0" />
      <geometry>
        <mesh
          filename="package://koko_description_sevendof_dyn/meshes/shoulder_lift_link.STL" />
      </geometry>
      <material
        name="">
        <color
          rgba="1 0.501960784313725 0.501960784313725 1" />
      </material>
    </visual>
    <collision>
      <origin
        xyz="0 0 0"
        rpy="0 0 0" />
      <geometry>
        <mesh
          filename="package://koko_description_sevendof_dyn/meshes/shoulder_lift_link.STL" />
      </geometry>
    </collision>
  </link>
  <joint
    name="shoulder_lift_joint"
    type="revolute">
    <origin
      xyz="0.01143 4.0407E-05 0.20168"
      rpy="1.5708 -0.7854 0.0035351" />
    <parent
      link="shoulder_link" />
    <child
      link="shoulder_lift_link" />
    <axis
      xyz="0 0 1" />
    <limit
      lower="-3"
      upper="3"
      effort="0"
      velocity="0" />
  </joint>
  <link
    name="upper_arm_link">
    <inertial>
      <origin
        xyz="0.00896272457599723 -2.14489447046828E-05 0.0544760545145281"
        rpy="0 0 0" />
      <mass
        value="4.20793381363064" />
      <inertia
        ixx="0.00687796890152346"
        ixy="1.69039874989105E-06"
        ixz="-0.000316640900899954"
        iyy="0.00746043696792995"
        iyz="2.45296955518709E-06"
        izz="0.00648506964310533" />
    </inertial>
    <visual>
      <origin
        xyz="0 0 0"
        rpy="0 0 0" />
      <geometry>
        <mesh
          filename="package://koko_description_sevendof_dyn/meshes/upper_arm_link.STL" />
      </geometry>
      <material
        name="">
        <color
          rgba="0.843137254901961 0.815686274509804 0.752941176470588 1" />
      </material>
    </visual>
    <collision>
      <origin
        xyz="0 0 0"
        rpy="0 0 0" />
      <geometry>
        <mesh
          filename="package://koko_description_sevendof_dyn/meshes/upper_arm_link.STL" />
      </geometry>
    </collision>
  </link>
  <joint
    name="shoulder_roll_joint"
    type="revolute">
    <origin
      xyz="0.024591 -0.066323 0"
      rpy="1.5708 -0.0026647 0.35378" />
    <parent
      link="shoulder_lift_link" />
    <child
      link="upper_arm_link" />
    <axis
      xyz="0 0 -1" />
    <limit
      lower="-3"
      upper="3"
      effort="0"
      velocity="0" />
  </joint>
  <link
    name="upper_arm_lift_link">
    <inertial>
      <origin
        xyz="-3.46975874698785E-08 -0.00196475010062194 4.92542544648922E-05"
        rpy="0 0 0" />
      <mass
        value="0.437261171596556" />
      <inertia
        ixx="0.00065752278966404"
        ixy="5.54164283688298E-07"
        ixz="-1.90213496564035E-06"
        iyy="0.00108636200010352"
        iyz="5.1934407024919E-07"
        izz="0.0010224529431372" />
    </inertial>
    <visual>
      <origin
        xyz="0 0 0"
        rpy="0 0 0" />
      <geometry>
        <mesh
          filename="package://koko_description_sevendof_dyn/meshes/upper_arm_lift_link.STL" />
      </geometry>
      <material
        name="">
        <color
          rgba="1 0.501960784313725 0.501960784313725 1" />
      </material>
    </visual>
    <collision>
      <origin
        xyz="0 0 0"
        rpy="0 0 0" />
      <geometry>
        <mesh
          filename="package://koko_description_sevendof_dyn/meshes/upper_arm_lift_link.STL" />
      </geometry>
    </collision>
  </link>
  <joint
    name="elbow_lift_joint"
    type="revolute">
    <origin
      xyz="-0.011086 2.954E-05 0.18096"
      rpy="1.3274 -1.0278E-15 1.5681" />
    <parent
      link="upper_arm_link" />
    <child
      link="upper_arm_lift_link" />
    <axis
      xyz="1 0 0" />
    <limit
      lower="-3"
      upper="3"
      effort="0"
      velocity="0" />
  </joint>
  <link
    name="forearm_link">
    <inertial>
      <origin
        xyz="0.0547161453432255 -0.0073138686745316 -2.50594403333748E-06"
        rpy="0 0 0" />
      <mass
        value="4.12272375893646" />
      <inertia
        ixx="0.00596487038810557"
        ixy="3.34654290283856E-05"
        ixz="-1.65209690691498E-06"
        iyy="0.00664496792638479"
        iyz="1.07361459430677E-07"
        izz="0.00679246779103773" />
    </inertial>
    <visual>
      <origin
        xyz="0 0 0"
        rpy="0 0 0" />
      <geometry>
        <mesh
          filename="package://koko_description_sevendof_dyn/meshes/forearm_link.STL" />
      </geometry>
      <material
        name="">
        <color
          rgba="0.843137254901961 0.815686274509804 0.752941176470588 1" />
      </material>
    </visual>
    <collision>
      <origin
        xyz="0 0 0"
        rpy="0 0 0" />
      <geometry>
        <mesh
          filename="package://koko_description_sevendof_dyn/meshes/forearm_link.STL" />
      </geometry>
    </collision>
  </link>
  <joint
    name="elbow_roll_joint"
    type="revolute">
    <origin
      xyz="0 0.073871 0"
      rpy="-1.5708 1.6307E-15 1.5708" />
    <parent
      link="upper_arm_lift_link" />
    <child
      link="forearm_link" />
    <axis
      xyz="-1 0 0" />
    <limit
      lower="-3"
      upper="3"
      effort="0"
      velocity="0" />
  </joint>
  <link
    name="wrist_lift_link">
    <inertial>
      <origin
        xyz="0.000974827037374726 0.00171170705249171 -1.58073987788221E-08"
        rpy="0 0 0" />
      <mass
        value="0.437254818113419" />
      <inertia
        ixx="0.0010367580014318"
        ixy="2.62036693551772E-05"
        ixz="-1.86750583187411E-06"
        iyy="0.00107204394966706"
        iyz="2.46663117427703E-07"
        izz="0.000657515354066945" />
    </inertial>
    <visual>
      <origin
        xyz="0 0 0"
        rpy="0 0 0" />
      <geometry>
        <mesh
          filename="package://koko_description_sevendof_dyn/meshes/wrist_lift_link.STL" />
      </geometry>
      <material
        name="">
        <color
          rgba="1 0.501960784313725 0.501960784313725 1" />
      </material>
    </visual>
    <collision>
      <origin
        xyz="0 0 0"
        rpy="0 0 0" />
      <geometry>
        <mesh
          filename="package://koko_description_sevendof_dyn/meshes/wrist_lift_link.STL" />
      </geometry>
    </collision>
  </link>
  <joint
    name="wrist_lift_joint"
    type="revolute">
    <origin
      xyz="0.1778 0.01143 0"
      rpy="3.1416 -1.5135E-15 -1.4604" />
    <parent
      link="forearm_link" />
    <child
      link="wrist_lift_link" />
    <axis
      xyz="0 0 1" />
    <limit
      lower="-3"
      upper="3"
      effort="0"
      velocity="0" />
  </joint>
  <link
    name="wrist_roll_link">
    <inertial>
      <origin
        xyz="-1.83990520818966E-06 -0.00351222783041255 0.0747710456300801"
        rpy="0 0 0" />
      <mass
        value="1.49779120433657" />
      <inertia
        ixx="0.00172002556474907"
        ixy="1.94218046155549E-07"
        ixz="7.87344114839229E-07"
        iyy="0.00150079734019341"
        iyz="9.75532985830733E-05"
        izz="0.00168408131777438" />
    </inertial>
    <visual>
      <origin
        xyz="0 0 0"
        rpy="0 0 0" />
      <geometry>
        <mesh
          filename="package://koko_description_sevendof_dyn/meshes/wrist_roll_link.STL" />
      </geometry>
      <material
        name="">
        <color
          rgba="0.752941176470588 0.752941176470588 0.752941176470588 1" />
      </material>
    </visual>
    <collision>
      <origin
        xyz="0 0 0"
        rpy="0 0 0" />
      <geometry>
        <mesh
          filename="package://koko_description_sevendof_dyn/meshes/wrist_roll_link.STL" />
      </geometry>
    </collision>
  </link>
  <joint
    name="wrist_roll_joint"
    type="revolute">
    <origin
      xyz="-0.019428 -0.035935 0"
      rpy="-1.5708 -6.5009E-15 2.646" />
    <parent
      link="wrist_lift_link" />
    <child
      link="wrist_roll_link" />
    <axis
      xyz="0 0 -1" />
    <limit
      lower="-3"
      upper="3"
      effort="0"
      velocity="0" />
  </joint>
</robot>
