<robot
  name="koko_description_sevendof_dyn">
  <link
    name="base_link">
    <inertial>
      <origin
        xyz="0.012870283424599 -0.146460771615818 0.199851243077833"
        rpy="0 0 0" />
      <mass
        value="5.30617493719281" />
      <inertia
        ixx="0.167859643379242"
        ixy="-0.0181596573247313"
        ixz="0.00370892628271695"
        iyy="0.155525388827852"
        iyz="-0.0306003369765197"
        izz="0.0830686215437386" />
    </inertial>
    <visual>
      <origin
        xyz="0 0 0"
        rpy="0 0 0" />
      <geometry>
        <mesh
          filename="package://koko_description_sevendof_dyn/meshes/base_link.STL" />
      </geometry>
      <material
        name="">
        <color
          rgba="0.792156862745098 0.819607843137255 0.933333333333333 1" />
      </material>
    </visual>
    <collision>
      <origin
        xyz="0 0 0"
        rpy="0 0 0" />
      <geometry>
        <mesh
          filename="package://koko_description_sevendof_dyn/meshes/base_link.STL" />
      </geometry>
    </collision>
  </link>
  <link
    name="shoulder_link">
    <inertial>
      <origin
        xyz="-0.0051887420876425 7.89464121064842E-06 0.077892118978285"
        rpy="0 0 0" />
      <mass
        value="2.01456842992022" />
      <inertia
        ixx="0.0104358312007897"
        ixy="1.86087956696659E-06"
        ixz="0.000187864874535148"
        iyy="0.00992302072037356"
        iyz="-3.95000358598578E-06"
        izz="0.00452604302596495" />
    </inertial>
    <visual>
      <origin
        xyz="0 0 0"
        rpy="0 0 0" />
      <geometry>
        <mesh
          filename="package://koko_description_sevendof_dyn/meshes/shoulder_link.STL" />
      </geometry>
      <material
        name="">
        <color
          rgba="0.698039215686274 0.698039215686274 0.698039215686274 1" />
      </material>
    </visual>
    <collision>
      <origin
        xyz="0 0 0"
        rpy="0 0 0" />
      <geometry>
        <mesh
          filename="package://koko_description_sevendof_dyn/meshes/shoulder_link.STL" />
      </geometry>
    </collision>
  </link>
  <joint
    name="base_roll_joint"
    type="continuous">
    <origin
      xyz="0.0901789447182363 -0.0908049999999997 0.212155832960628"
      rpy="6.83851519316138E-15 0.785398163397447 4.83556046633164E-15" />
    <parent
      link="base_link" />
    <child
      link="shoulder_link" />
    <axis
      xyz="0 0 1" />
  </joint>
  <link
    name="shoulder_lift_link">
    <inertial>
      <origin
        xyz="8.56700605421368E-05 0.000106540481090378 -2.99716314028364E-06"
        rpy="0 0 0" />
      <mass
        value="0.491671117187525" />
      <inertia
        ixx="0.00108091574465868"
        ixy="-6.67463044213569E-06"
        ixz="-6.1326515432463E-07"
        iyy="0.00110225729603076"
        iyz="-9.06027727283294E-07"
        izz="0.000715451465545286" />
    </inertial>
    <visual>
      <origin
        xyz="0 0 0"
        rpy="0 0 0" />
      <geometry>
        <mesh
          filename="package://koko_description_sevendof_dyn/meshes/shoulder_lift_link.STL" />
      </geometry>
      <material
        name="">
        <color
          rgba="1 1 1 1" />
      </material>
    </visual>
    <collision>
      <origin
        xyz="0 0 0"
        rpy="0 0 0" />
      <geometry>
        <mesh
          filename="package://koko_description_sevendof_dyn/meshes/shoulder_lift_link.STL" />
      </geometry>
    </collision>
  </link>
  <joint
    name="shoulder_lift_joint"
    type="continuous">
    <origin
      xyz="0.0114299285786579 4.04065193964076E-05 0.210820000000001"
      rpy="1.5707963267949 -0.785395039094458 0.0035351359132397" />
    <parent
      link="shoulder_link" />
    <child
      link="shoulder_lift_link" />
    <axis
      xyz="0 0 1" />
  </joint>
  <link
    name="upper_arm_link">
    <inertial>
      <origin
        xyz="0.00962775541061939 -4.36779395476261E-05 0.0626949593105972"
        rpy="0 0 0" />
      <mass
        value="1.83297890764661" />
      <inertia
        ixx="0.00743141946531307"
        ixy="-5.63952182972037E-07"
        ixz="-0.000234811893243792"
        iyy="0.00733612977545853"
        iyz="5.84228167021854E-06"
        izz="0.00460629048201174" />
    </inertial>
    <visual>
      <origin
        xyz="0 0 0"
        rpy="0 0 0" />
      <geometry>
        <mesh
          filename="package://koko_description_sevendof_dyn/meshes/upper_arm_link.STL" />
      </geometry>
      <material
        name="">
        <color
          rgba="1 1 1 1" />
      </material>
    </visual>
    <collision>
      <origin
        xyz="0 0 0"
        rpy="0 0 0" />
      <geometry>
        <mesh
          filename="package://koko_description_sevendof_dyn/meshes/upper_arm_link.STL" />
      </geometry>
    </collision>
  </link>
  <joint
    name="shoulder_roll_joint"
    type="continuous">
    <origin
      xyz="0.0245928594422891 -0.0662368608700259 0"
      rpy="1.5707963267949 -0.00266644576657517 0.355511126450564" />
    <parent
      link="shoulder_lift_link" />
    <child
      link="upper_arm_link" />
    <axis
      xyz="0 0 -1" />
  </joint>
  <link
    name="upper_arm_lift_link">
    <inertial>
      <origin
        xyz="8.84357648046064E-05 0.000101387692328536 -3.00235832179085E-06"
        rpy="0 0 0" />
      <mass
        value="0.491094590998026" />
      <inertia
        ixx="0.0010794567879069"
        ixy="-2.63718814428902E-06"
        ixz="-1.86177664318738E-06"
        iyy="0.00110222828580888"
        iyz="-8.57650093565724E-07"
        izz="0.000713963052496043" />
    </inertial>
    <visual>
      <origin
        xyz="0 0 0"
        rpy="0 0 0" />
      <geometry>
        <mesh
          filename="package://koko_description_sevendof_dyn/meshes/upper_arm_lift_link.STL" />
      </geometry>
      <material
        name="">
        <color
          rgba="1 1 1 1" />
      </material>
    </visual>
    <collision>
      <origin
        xyz="0 0 0"
        rpy="0 0 0" />
      <geometry>
        <mesh
          filename="package://koko_description_sevendof_dyn/meshes/upper_arm_lift_link.STL" />
      </geometry>
    </collision>
  </link>
  <joint
    name="elbow_lift_joint"
    type="continuous">
    <origin
      xyz="-0.011429954204372 3.04766769116949E-05 0.181015691885107"
      rpy="-1.5707963267949 -0.355504877844586 -0.0026664457665753" />
    <parent
      link="upper_arm_link" />
    <child
      link="upper_arm_lift_link" />
    <axis
      xyz="0 0 1" />
  </joint>
  <link
    name="forearm_link">
    <inertial>
      <origin
        xyz="0.0096237771371514 -4.56517051862781E-05 0.0649688773415412"
        rpy="0 0 0" />
      <mass
        value="1.83280962903355" />
      <inertia
        ixx="0.00737281835898244"
        ixy="-4.33954514358567E-07"
        ixz="-0.000226046640171192"
        iyy="0.00727767044006759"
        iyz="6.04410217387482E-06"
        izz="0.0046050936248077" />
    </inertial>
    <visual>
      <origin
        xyz="0 0 0"
        rpy="0 0 0" />
      <geometry>
        <mesh
          filename="package://koko_description_sevendof_dyn/meshes/forearm_link.STL" />
      </geometry>
      <material
        name="">
        <color
          rgba="0.698039215686274 0.698039215686274 0.698039215686274 1" />
      </material>
    </visual>
    <collision>
      <origin
        xyz="0 0 0"
        rpy="0 0 0" />
      <geometry>
        <mesh
          filename="package://koko_description_sevendof_dyn/meshes/forearm_link.STL" />
      </geometry>
    </collision>
  </link>
  <joint
    name="elbow_roll_joint"
    type="continuous">
    <origin
      xyz="0.00778446397719376 -0.070224872016303 0"
      rpy="1.5707963267949 -0.00251502707069075 0.11039980475715" />
    <parent
      link="upper_arm_lift_link" />
    <child
      link="forearm_link" />
    <axis
      xyz="0 0 -1" />
  </joint>
  <link
    name="wrist_lift_link">
    <inertial>
      <origin
        xyz="0.000127836166482376 3.90137178882116E-05 -2.99279241472439E-06"
        rpy="0 0 0" />
      <mass
        value="0.491088159417007" />
      <inertia
        ixx="0.00108470229868548"
        ixy="9.48573539218779E-06"
        ixz="-1.94944946315306E-06"
        iyy="0.0010970422911688"
        iyz="1.85051907729155E-07"
        izz="0.000713963241196343" />
    </inertial>
    <visual>
      <origin
        xyz="0 0 0"
        rpy="0 0 0" />
      <geometry>
        <mesh
          filename="package://koko_description_sevendof_dyn/meshes/wrist_lift_link.STL" />
      </geometry>
      <material
        name="">
        <color
          rgba="1 1 1 1" />
      </material>
    </visual>
    <collision>
      <origin
        xyz="0 0 0"
        rpy="0 0 0" />
      <geometry>
        <mesh
          filename="package://koko_description_sevendof_dyn/meshes/wrist_lift_link.STL" />
      </geometry>
    </collision>
  </link>
  <joint
    name="wrist_lift_joint"
    type="continuous">
    <origin
      xyz="-0.011429964001298 2.8746722190276E-05 0.181015690796442"
      rpy="-1.5707963267949 -0.110406053363127 -0.00251502707069052" />
    <parent
      link="forearm_link" />
    <child
      link="wrist_lift_link" />
    <axis
      xyz="0 0 1" />
  </joint>
  <link
    name="wrist_link">
    <inertial>
      <origin
        xyz="-8.84239932047448E-05 0.0543189775985217 0.0376010969825167"
        rpy="0 0 0" />
      <mass
        value="0.28159829590899" />
      <inertia
        ixx="0.00050667802634078"
        ixy="-8.15911422809642E-07"
        ixz="-9.41941888432487E-07"
        iyy="0.0004122845100503"
        iyz="-0.000192314734338328"
        izz="0.000398049822393887" />
    </inertial>
    <visual>
      <origin
        xyz="0 0 0"
        rpy="0 0 0" />
      <geometry>
        <mesh
          filename="package://koko_description_sevendof_dyn/meshes/wrist_link.STL" />
      </geometry>
      <material
        name="">
        <color
          rgba="0.498039215686275 0.498039215686275 0.498039215686275 1" />
      </material>
    </visual>
    <collision>
      <origin
        xyz="0 0 0"
        rpy="0 0 0" />
      <geometry>
        <mesh
          filename="package://koko_description_sevendof_dyn/meshes/wrist_link.STL" />
      </geometry>
    </collision>
  </link>
  <joint
    name="wrist_joint"
    type="continuous">
    <origin
      xyz="-0.0115762893061741 -0.0214116626131124 0"
      rpy="1.62543589699027E-15 -1.18308141061618E-15 2.64595360386185" />
    <parent
      link="wrist_lift_link" />
    <child
      link="wrist_link" />
    <axis
      xyz="0 -1 0" />
  </joint>
</robot>