<robot
  name="fivedof_tracker_dyn_v4">
  <link
    name="base_link">
    <inertial>
      <origin
        xyz="0.132232011329379 0.0889379900322127 0.0454629969863035"
        rpy="0 0 0" />
      <mass
        value="0.36203358916215" />
      <inertia
        ixx="0.00333357657753587"
        ixy="-0.000609653639341485"
        ixz="-3.26886318270678E-05"
        iyy="0.00135449484031022"
        iyz="-0.000631078537292462"
        izz="0.00374390627127203" />
    </inertial>
    <visual>
      <origin
        xyz="0 0 0"
        rpy="0 0 0" />
      <geometry>
        <mesh
          filename="package://fivedof_tracker_dyn_v4/meshes/base_link.STL" />
      </geometry>
      <material
        name="">
        <color
          rgba="0.792156862745098 0.819607843137255 0.933333333333333 1" />
      </material>
    </visual>
    <collision>
      <origin
        xyz="0 0 0"
        rpy="0 0 0" />
      <geometry>
        <mesh
          filename="package://fivedof_tracker_dyn_v4/meshes/base_link.STL" />
      </geometry>
    </collision>
  </link>
  <link
    name="broll_link">
    <inertial>
      <origin
        xyz="-4.46054735467605E-05 -0.00690005721720016 0.129072203183588"
        rpy="0 0 0" />
      <mass
        value="4.35259352451056" />
      <inertia
        ixx="0.0099679109661456"
        ixy="-1.47611706520471E-07"
        ixz="1.25442074335569E-06"
        iyy="0.00983205687194457"
        iyz="0.000215106387593619"
        izz="0.00636760795174226" />
    </inertial>
    <visual>
      <origin
        xyz="0 0 0"
        rpy="0 0 0" />
      <geometry>
        <mesh
          filename="package://fivedof_tracker_dyn_v4/meshes/broll_link.STL" />
      </geometry>
      <material
        name="">
        <color
          rgba="0.792156862745098 0.819607843137255 0.933333333333333 1" />
      </material>
    </visual>
    <collision>
      <origin
        xyz="0 0 0"
        rpy="0 0 0" />
      <geometry>
        <mesh
          filename="package://fivedof_tracker_dyn_v4/meshes/broll_link.STL" />
      </geometry>
    </collision>
  </link>
  <joint
    name="broll_joint"
    type="continuous">
    <origin
      xyz="0.158823797126682 0.219075 0.0700459976351885"
      rpy="0.785398163397454 2.49612139226362E-17 1.5707963267949" />
    <parent
      link="base_link" />
    <child
      link="broll_link" />
    <axis
      xyz="0 0 1" />
  </joint>
  <link
    name="lift_link">
    <inertial>
      <origin
        xyz="1.24052087768778E-08 -0.00188906413908307 -5.35092899947576E-05"
        rpy="0 0 0" />
      <mass
        value="0.376118026540361" />
      <inertia
        ixx="0.000549299625161153"
        ixy="-7.97376933297374E-07"
        ixz="1.58259045905509E-07"
        iyy="0.000962137460349973"
        iyz="4.29750559687297E-08"
        izz="0.000949314685927898" />
    </inertial>
    <visual>
      <origin
        xyz="0 0 0"
        rpy="0 0 0" />
      <geometry>
        <mesh
          filename="package://fivedof_tracker_dyn_v4/meshes/lift_link.STL" />
      </geometry>
      <material
        name="">
        <color
          rgba="1 0.501960784313725 0.501960784313725 1" />
      </material>
    </visual>
    <collision>
      <origin
        xyz="0 0 0"
        rpy="0 0 0" />
      <geometry>
        <mesh
          filename="package://fivedof_tracker_dyn_v4/meshes/lift_link.STL" />
      </geometry>
    </collision>
  </link>
  <joint
    name="lift_joint"
    type="continuous">
    <origin
      xyz="0.00044422 0.01143 0.25883"
      rpy="1.7611 -1.1184E-16 -3.1416" />
    <parent
      link="broll_link" />
    <child
      link="lift_link" />
    <axis
      xyz="1 0 0" />
  </joint>
  <link
    name="sroll_link">
    <inertial>
      <origin
        xyz="0.000914973983909662 0.10429088939146 -0.00730705956377714"
        rpy="0 0 0" />
      <mass
        value="4.08383062765031" />
      <inertia
        ixx="0.00672213736562578"
        ixy="-7.45133136582914E-06"
        ixz="7.23122870680616E-07"
        iyy="0.00592378389797537"
        iyz="3.77969911558827E-05"
        izz="0.00660219957513478" />
    </inertial>
    <visual>
      <origin
        xyz="0 0 0"
        rpy="0 0 0" />
      <geometry>
        <mesh
          filename="package://fivedof_tracker_dyn_v4/meshes/sroll_link.STL" />
      </geometry>
      <material
        name="">
        <color
          rgba="0.792156862745098 0.819607843137255 0.933333333333333 1" />
      </material>
    </visual>
    <collision>
      <origin
        xyz="0 0 0"
        rpy="0 0 0" />
      <geometry>
        <mesh
          filename="package://fivedof_tracker_dyn_v4/meshes/sroll_link.STL" />
      </geometry>
    </collision>
  </link>
  <joint
    name="sroll_joint"
    type="continuous">
    <origin
      xyz="0 0.0243407018824063 0"
      rpy="-8.88716062109556E-16 -0.0347858115074048 2.77723769409236E-17" />
    <parent
      link="lift_link" />
    <child
      link="sroll_link" />
    <axis
      xyz="0 1 0" />
  </joint>
  <link
    name="elbow_link">
    <inertial>
      <origin
        xyz="1.94986314872025E-08 -0.00188906674213341 -5.35120358778896E-05"
        rpy="0 0 0" />
      <mass
        value="0.376117780879764" />
      <inertia
        ixx="0.000549299229275517"
        ixy="-7.9729749466551E-07"
        ixz="1.58279894940098E-07"
        iyy="0.000962144024023398"
        iyz="4.29883759380976E-08"
        izz="0.000949321132784204" />
    </inertial>
    <visual>
      <origin
        xyz="0 0 0"
        rpy="0 0 0" />
      <geometry>
        <mesh
          filename="package://fivedof_tracker_dyn_v4/meshes/elbow_link.STL" />
      </geometry>
      <material
        name="">
        <color
          rgba="1 0.501960784313725 0.501960784313725 1" />
      </material>
    </visual>
    <collision>
      <origin
        xyz="0 0 0"
        rpy="0 0 0" />
      <geometry>
        <mesh
          filename="package://fivedof_tracker_dyn_v4/meshes/elbow_link.STL" />
      </geometry>
    </collision>
  </link>
  <joint
    name="elbow_joint"
    type="continuous">
    <origin
      xyz="0.00044422 0.22733 0.01143"
      rpy="0.19028 7.8013E-12 -6.5919E-17" />
    <parent
      link="sroll_link" />
    <child
      link="elbow_link" />
    <axis
      xyz="1 0 0" />
  </joint>
  <link
    name="eroll_link">
    <inertial>
      <origin
        xyz="0.00031339756211729 0.112299314077981 -0.00823319758680291"
        rpy="0 0 0" />
      <mass
        value="0.389562812619229" />
      <inertia
        ixx="0.00330113895899062"
        ixy="1.48357978939789E-05"
        ixz="-2.09878136958772E-06"
        iyy="0.000194464406595764"
        iyz="0.000189108004907393"
        izz="0.00327165355720369" />
    </inertial>
    <visual>
      <origin
        xyz="0 0 0"
        rpy="0 0 0" />
      <geometry>
        <mesh
          filename="package://fivedof_tracker_dyn_v4/meshes/eroll_link.STL" />
      </geometry>
      <material
        name="">
        <color
          rgba="0.792156862745098 0.819607843137255 0.933333333333333 1" />
      </material>
    </visual>
    <collision>
      <origin
        xyz="0 0 0"
        rpy="0 0 0" />
      <geometry>
        <mesh
          filename="package://fivedof_tracker_dyn_v4/meshes/eroll_link.STL" />
      </geometry>
    </collision>
  </link>
  <joint
    name="eroll_joint"
    type="continuous">
    <origin
      xyz="0 0.024341 0"
      rpy="-3.8326E-15 -0.034786 -9.6624E-13" />
    <parent
      link="elbow_link" />
    <child
      link="eroll_link" />
    <axis
      xyz="0 1 0" />
  </joint>
</robot>