<?xml version="1.0"?>

<!-- XML namespaces -->
<robot xmlns:xacro="http://ros.org/wiki/xacro">

  <!-- Inertial properties differ slightly for left vs right arm -->
  <xacro:property name="base_left_min"  value="-2.3412" />
  <xacro:property name="base_left_max"  value= "3.3999" />

  <xacro:property name="base_right_min"  value="-3.3999" />
  <xacro:property name="base_right_max"  value= "2.3412" />

  <!-- ============================  link  ============================ -->
  <!-- Includes elbow flex, FA roll joints in macros below -->
  <xacro:macro name="blue_base_v0" params="side reflect child">

    <link name="${side}_base_link">
      <inertial>
        <origin
          xyz="0.0560024374186662 0.000189445541681321 0.0201835602327798"
          rpy="0 0 0" />
        <mass
          value="0.284612172465311" />
        <inertia
          ixx="0.000716950374478633"
          ixy="-4.58477843167981E-06"
          ixz="4.20772050305934E-06"
          iyy="0.00197711566495113"
          iyz="9.13561852910017E-07"
          izz="0.00239705630031167" />
      </inertial>
      <visual>
        <origin
          xyz="0 0 0"
          rpy="0 0 0" />
        <geometry>
          <mesh
            filename="package://blue_descriptions/meshes/base_link.STL" />
        </geometry>
        <material
          name="">
          <color
            rgba="0.792156862745098 0.819607843137255 0.933333333333333 1" />
        </material>
      </visual>
      <collision>
        <origin
          xyz="0 0 0"
          rpy="0 0 0" />
        <geometry>
          <mesh
            filename="package://blue_descriptions/meshes/base_link.STL" />
        </geometry>
      </collision>
    </link>

    <joint
      name="${side}_base_roll_joint"
      type="revolute">
      <origin
        xyz="0 0 0.087371"
        rpy="3.1416 -2.2011E-29 0.0" />
      <parent
        link="${side}_base_link" />
      <child
        link="${side}_${child}" />
      <axis
        xyz="0 0 1" />
      <limit
        lower="${0.5*((reflect+1)*base_left_min+(1-reflect)*base_right_min)}"
        upper="${0.5*((reflect+1)*base_left_max+(1-reflect)*base_right_max)}"
        effort="0"
        velocity="0" />
    </joint>

  </xacro:macro>

</robot>
