<robot
  name="koko_description_base">
  <link
    name="base_link">
    <inertial>
      <origin
        xyz="0.0560024374186662 0.000189445541681321 0.0201835602327798"
        rpy="0 0 0" />
      <mass
        value="0.284612172465311" />
      <inertia
        ixx="0.000716950374478633"
        ixy="-4.58477843167981E-06"
        ixz="4.20772050305934E-06"
        iyy="0.00197711566495113"
        iyz="9.13561852910017E-07"
        izz="0.00239705630031167" />
    </inertial>
    <visual>
      <origin
        xyz="0 0 0"
        rpy="0 0 0" />
      <geometry>
        <mesh
          filename="package://koko_description_base/meshes/base_link.STL" />
      </geometry>
      <material
        name="">
        <color
          rgba="0.792156862745098 0.819607843137255 0.933333333333333 1" />
      </material>
    </visual>
    <collision>
      <origin
        xyz="0 0 0"
        rpy="0 0 0" />
      <geometry>
        <mesh
          filename="package://koko_description_base/meshes/base_link.STL" />
      </geometry>
    </collision>
  </link>
  <link
    name="shoulder_link">
    <inertial>
      <origin
        xyz="0.0043477541389173 2.01234773878345E-05 -0.0764683318824377"
        rpy="0 0 0" />
      <mass
        value="1.80901122392276" />
      <inertia
        ixx="0.0091937456982913"
        ixy="1.27362263865398E-08"
        ixz="0.00010247865043886"
        iyy="0.00871917388181738"
        iyz="3.26622166777351E-06"
        izz="0.00388062453070139" />
    </inertial>
    <visual>
      <origin
        xyz="0 0 0"
        rpy="0 0 0" />
      <geometry>
        <mesh
          filename="package://koko_description_base/meshes/shoulder_link.STL" />
      </geometry>
      <material
        name="">
        <color
          rgba="0.843137254901961 0.815686274509804 0.752941176470588 1" />
      </material>
    </visual>
    <collision>
      <origin
        xyz="0 0 0"
        rpy="0 0 0" />
      <geometry>
        <mesh
          filename="package://koko_description_base/meshes/shoulder_link.STL" />
      </geometry>
    </collision>
  </link>
  <joint
    name="base_roll_joint"
    type="revolute">
    <origin
      xyz="0 0 0.054356"
      rpy="3.1416 -2.2011E-29 0.0" />
    <parent
      link="base_link" />
    <child
      link="shoulder_link" />
    <axis
      xyz="0 0 1" />
    <limit
      lower="-2.3412"
      upper="3.3999"
      effort="0"
      velocity="0" />
  </joint>
</robot>
