<?xml version="1.0"?>

<!-- XML namespaces -->
<robot xmlns:xacro="http://ros.org/wiki/xacro">

  <!-- ============================  End link and gripper ============================ -->
  <xacro:macro name="blue_end_effector_v1" params="side name">
    <xacro:blue_end_v1 side="${side}" name="${name}"/>
    <xacro:blue_gripper_v1 side="${side}" parent="${name}"/>
    <xacro:blue_gripper_finger_v1 side="${side}" parent="${name}"/>
  </xacro:macro>

  <xacro:macro name="mimic_joint_plugin_gazebo" params="name_prefix parent_joint mimic_joint has_pid:=false multiplier:=1.0 offset:=0 sensitiveness:=0.0 max_effort:=1.0 robot_namespace:=''">
    <gazebo>
      <plugin name="${name_prefix}_mimic_joint_plugin" filename="libroboticsgroup_gazebo_mimic_joint_plugin.so">
        <joint>${parent_joint}</joint>
        <mimicJoint>${mimic_joint}</mimicJoint>
        <xacro:if value="${has_pid}">                     <!-- if set to true, PID parameters from "/gazebo_ros_control/pid_gains/${mimic_joint}" are loaded -->
          <hasPID />
        </xacro:if>
        <multiplier>${multiplier}</multiplier>
        <offset>${offset}</offset>
        <sensitiveness>${sensitiveness}</sensitiveness>   <!-- if absolute difference between setpoint and process value is below this threshold, do nothing; 0.0 = disable [rad] -->
        <maxEffort>${max_effort}</maxEffort>              <!-- only taken into account if has_pid:=true [Nm] -->
        <xacro:unless value="${robot_namespace == ''}">
          <robotNamespace>($robot_namespace)</robotNamespace>
        </xacro:unless>
      </plugin>
    </gazebo>
  </xacro:macro>

  <xacro:macro name="blue_end_v1" params="side name">
    <link
      name="${side}_${name}">
      <inertial>
        <origin
          xyz="0.00526385736219506 2.70691865020822E-05 -0.0641638075944594"
          rpy="0 0 0" />
        <mass
          value="0.657109755986862" />
        <inertia
          ixx="0.0057866591250737"
          ixy="3.71515699629511E-07"
          ixz="-6.32890111626103E-05"
          iyy="0.00530223654324281"
          iyz="8.9999884666805E-07"
          izz="0.00342399181200673" />
      </inertial>
      <visual>
        <origin
          xyz="0 0 0"
          rpy="0 0 0" />
        <geometry>
          <mesh
            filename="package://blue_descriptions/meshes/hand_base_link.STL" />
        </geometry>
        <material name="">
          <color rgba="1 1 1 1" />
        </material>
      </visual>
      <collision>
        <origin
          xyz="0 0 0"
          rpy="0 0 0" />
        <geometry>
          <mesh
            filename="package://blue_descriptions/meshes/hand_base_link.STL" />
        </geometry>
      </collision>
    </link>
  </xacro:macro>

  <xacro:macro name="blue_gripper_finger_v1" params="side parent">
    <link
      name="${side}_gripper_finger_link">
    </link>
    <joint
      name="${side}_gripper_finger_joint"
      type="fixed">
        <dynamics damping="0.7" friction="10.0"/>
      <origin
        xyz="0 0.0 -0.18"
        rpy="1.5708 1.5708 1.5708" />
      <parent
        link="${side}_${parent}" />
      <child
        link="${side}_gripper_finger_link" />
    </joint>
  </xacro:macro>

  <xacro:macro name="blue_gripper_v1" params="side parent">
    <link
      name="${side}_gripper_link">
      <inertial>
        <origin
          xyz="-7.00549073506807E-05 2.51271935254316E-05 -0.052367118189184"
          rpy="0 0 0" />
        <mass
          value="0.0047109755986862" />
        <inertia
          ixx="0.000916887873826385"
          ixy="-6.04547948818479E-08"
          ixz="0.6796133363069E-06"
          iyy="0.000877268801166351"
          iyz="0.64172907801915E-07"
          izz="0.000293333065172452" />
      </inertial>
    </link>
    <joint
      name="${side}_gripper_joint"
      type="revolute">
        <dynamics damping="0.7" friction="10.0"/>
      <origin
        xyz="0 0 -0.10"
        rpy="1.5 1.5 0" />
      <parent
        link="${side}_${parent}" />
      <child
        link="${side}_gripper_link" />
      <axis
        xyz="0 0 1" />
      <limit
        lower="0"
        upper="1.05"
        effort="800"
        velocity="50" />
    </joint>

    <xacro:if value="${is_gazebo}">
      <transmission name="${side}_gripper_transmission">
        <type>transmission_interface/SimpleTransmission</type>
        <joint name="${side}_gripper_joint">
        <dynamics damping="0.7" friction="10.0"/>
          <hardwareInterface>hardware_interface/EffortJointInterface</hardwareInterface>
        </joint>
        <actuator name="${side}_gripper_motor">
          <hardwareInterface>hardware_interface/EffortJointInterface</hardwareInterface>
          <mechanicalReduction>1</mechanicalReduction>
        </actuator>
      </transmission>
    </xacro:if>

    <xacro:if value="${is_gazebo == 'false'}">
    <!-- right finger -->
    <link
      name="${side}_r_finger_link">
      <inertial>
        <origin
          xyz="0.00046733152633803 0.0122666320844707 1.16452530510985E-07"
          rpy="0 0 0" />
        <mass
          value="0.0384620979765985" />
        <inertia
          ixx="1.93716279065148E-05"
          ixy="-1.74835869619804E-06"
          ixz="3.21020594362941E-11"
          iyy="5.23390911087335E-06"
          iyz="-5.04535602261134E-11"
          izz="1.92560542157392E-05" />
      </inertial>
      <visual>
        <origin
          xyz="0 0 0"
          rpy="0 0 0" />
        <geometry>
          <mesh
            filename="package://blue_descriptions/meshes/finger_limb_link.STL" />
        </geometry>
        <material
          name="">
          <color
            rgba="0.792156862745098 0.819607843137255 0.933333333333333 1" />
        </material>
      </visual>
      <collision>
        <origin
          xyz="0 0 0"
          rpy="0 0 0" />
        <geometry>
          <mesh
            filename="package://blue_descriptions/meshes/finger_limb_link.STL" />
        </geometry>
      </collision>
    </link>

    <joint
      name="${side}_r_finger_joint"
      type="continuous">
        <dynamics damping="0.7" friction="10.0"/>
      <origin
        xyz="0.000 0.030703 -0.071979"
        rpy="-1.5708 -0.63969 1.5708" />
      <parent
        link="${side}_${parent}" />
      <child
        link="${side}_r_finger_link" />
      <axis
        xyz="0 0 1" />
      <mimic
        joint="${side}_gripper_joint"
        multiplier="1"/>
    </joint>

    <xacro:mimic_joint_plugin_gazebo name_prefix="${side}_r_finger_joint"
      parent_joint="${side}_gripper_joint" mimic_joint="${side}_r_finger_joint"
      has_pid="false" multiplier="1.0" max_effort="10.0" />

    <link
      name="${side}_r_finger_tip_link">
      <inertial>
        <origin
          xyz="0.000428096363398578 -6.3962924111774E-08 0.0162809660053768"
          rpy="0 0 0" />
        <mass
          value="0.0096424502794395" />
        <inertia
          ixx="1.76146900164229E-06"
          ixy="-1.63725174281941E-11"
          ixz="-5.09403577370148E-07"
          iyy="1.95368501856251E-06"
          iyz="-2.7403586363238E-12"
          izz="6.78506827465793E-07" />
      </inertial>
      <visual>
        <origin
          xyz="0 0 0"
          rpy="0 0 0" />
        <geometry>
          <mesh
            filename="package://blue_descriptions/meshes/finger_tip_link.STL" />
        </geometry>
        <material
          name="">
          <color
            rgba="0.792156862745098 0.819607843137255 0.933333333333333 1" />
        </material>
      </visual>
      <collision>
        <origin
          xyz="0 0 0"
          rpy="0 0 0" />
        <geometry>
          <mesh
            filename="package://blue_descriptions/meshes/finger_tip_link.STL" />
        </geometry>
      </collision>
    </link>
    <joint
      name="${side}_r_finger_tip_joint"
      type="revolute">
      <limit lower="0.5" upper="1" velocity="0.7" effort="100" />
        <dynamics damping="0.7" friction="10.0"/>
      <origin
        xyz="0 0.06 0"
        rpy="1.5708 -1.5754E-31 -2.5019" />
      <parent
        link="${side}_r_finger_link" />
      <child
        link="${side}_r_finger_tip_link" />
      <axis
        xyz="0 1 0" />
      <mimic
        joint="${side}_gripper_joint"
        multiplier="-1"/>
    </joint>

    <xacro:mimic_joint_plugin_gazebo name_prefix="${side}_r_finger_tip_joint"
      parent_joint="${side}_gripper_joint" mimic_joint="${side}_r_finger_tip_joint"
      has_pid="true" multiplier="-0.25" offset="0.85" max_effort="20" />

    <!-- left finger -->
    <link
      name="${side}_l_finger_link">
      <inertial>
        <origin
          xyz="0.00046733152633803 0.0122666320844707 1.16452530510985E-07"
          rpy="0 0 0" />
        <mass
          value="0.0384620979765985" />
        <inertia
          ixx="1.93716279065148E-05"
          ixy="-1.74835869619804E-06"
          ixz="3.21020594362941E-11"
          iyy="5.23390911087335E-06"
          iyz="-5.04535602261134E-11"
          izz="1.92560542157392E-05" />
      </inertial>
      <visual>
        <origin
          xyz="0 0 0"
          rpy="0 0 0" />
        <geometry>
          <mesh
            filename="package://blue_descriptions/meshes/finger_limb_link.STL" />
        </geometry>
        <material
          name="">
          <color
            rgba="0.792156862745098 0.819607843137255 0.933333333333333 1" />
        </material>
      </visual>
      <collision>
        <origin
          xyz="0 0 0"
          rpy="0 0 0" />
        <geometry>
          <mesh
            filename="package://blue_descriptions/meshes/finger_limb_link.STL" />
        </geometry>
      </collision>
    </link>
    <joint
      name="${side}_l_finger_joint"
      type="continuous">
        <dynamics damping="0.7" friction="10.0"/>
      <origin
        xyz="0.000 -0.030703 -0.071979"
        rpy="-1.5708 -0.63969 -1.5708" />
      <parent
        link="${side}_${parent}" />
      <child
        link="${side}_l_finger_link" />
      <axis
        xyz="0 0 1" />
      <mimic
        joint="${side}_gripper_joint"
        multiplier="1"/>
    </joint>


    <link
      name="${side}_l_finger_tip_link">
      <inertial>
        <origin
          xyz="0.000428096363398578 -6.3962924111774E-08 0.0162809660053768"
          rpy="0 0 0" />
        <mass
          value="0.0096424502794395" />
        <inertia
          ixx="1.76146900164229E-06"
          ixy="-1.63725174281941E-11"
          ixz="-5.09403577370148E-07"
          iyy="1.95368501856251E-06"
          iyz="-2.7403586363238E-12"
          izz="6.78506827465793E-07" />
      </inertial>
      <visual>
        <origin
          xyz="0 0 0"
          rpy="0 0 0" />
        <geometry>
          <mesh
            filename="package://blue_descriptions/meshes/finger_tip_link.STL" />
        </geometry>
        <material
          name="">
          <color
            rgba="0.792156862745098 0.819607843137255 0.933333333333333 1" />
        </material>
      </visual>
      <collision>
        <origin
          xyz="0 0 0"
          rpy="0 0 0" />
        <geometry>
          <mesh
            filename="package://blue_descriptions/meshes/finger_tip_link.STL" />
        </geometry>
      </collision>
    </link>
    <joint
      name="${side}_l_finger_tip_joint"
      type="revolute">
      <limit lower="0.5" upper="1" velocity="0.7" effort="100" />
      <dynamics damping="0.7" friction="10.0"/>
      <origin
        xyz="0 0.06 0"
        rpy="1.5708 -1.5754E-31 -2.5019" />
      <parent
        link="${side}_l_finger_link" />
      <child
        link="${side}_l_finger_tip_link" />
      <axis
        xyz="0 1 0" />
      <mimic
        joint="${side}_gripper_joint"
        multiplier="-1"/>
    </joint>
    <xacro:mimic_joint_plugin_gazebo name_prefix="${side}_l_finger_tip_joint"
      parent_joint="${side}_gripper_joint" mimic_joint="${side}_l_finger_tip_joint"
      has_pid="true" multiplier="-0.25" offset="0.85" max_effort="20" />
    </xacro:if>
  </xacro:macro>
</robot>
