<?xml version="1.0" ?>
<!-- =================================================================================== -->
<!-- |    This document was autogenerated by xacro from koko_left_arm.urdf.xacro       | -->
<!-- |    EDITING THIS FILE BY HAND IS NOT RECOMMENDED                                 | -->
<!-- =================================================================================== -->
<robot name="koko_description_sevendof_right" xmlns:xacro="http://ros.org/wiki/xacro">
  <!-- <xacro:include filename="$(find koko_description_sevendof)/urdf/upper_arm_v0/upper_arm.urdf.xacro" /> -->
  <!-- <xacro:include filename="$(find koko_description_sevendof)/urdf/forearm_v0/forearm.urdf.xacro" /> -->
  <!-- PR2 gripper -->
  <!-- <xacro:include filename="$(find pr2_description)/urdf/gripper_v0/gripper.urdf.xacro" /> -->
  <!-- Now we can start using the macros included above to define the actual PR2 -->
  <!-- The first use of a macro.  This one was defined in base.urdf.xacro above.
       A macro like this will expand to a set of link and joint definitions, and to additional
       Gazebo-related extensions (sensor plugins, etc).  The macro takes an argument, name,
       that equals "base", and uses it to generate names for its component links and joints
       (e.g., base_link).  The included origin block is also an argument to the macro.  By convention,
       the origin block defines where the component is w.r.t its parent (in this case the parent
       is the world frame). For more, see http://www.ros.org/wiki/xacro -->
  <link name="left_base_link">
    <inertial>
      <origin rpy="0 0 0" xyz="0.0560024374186662 0.000189445541681321 0.0201835602327798"/>
      <mass value="0.284612172465311"/>
      <inertia ixx="0.000716950374478633" ixy="-4.58477843167981E-06" ixz="4.20772050305934E-06" iyy="0.00197711566495113" iyz="9.13561852910017E-07" izz="0.00239705630031167"/>
    </inertial>
    <visual>
      <origin rpy="0 0 0" xyz="0 0 0"/>
      <geometry>
        <mesh filename="package://koko_description_sevendof/meshes/base_link.STL"/>
      </geometry>
      <material name="">
        <color rgba="0.792156862745098 0.819607843137255 0.933333333333333 1"/>
      </material>
    </visual>
    <collision>
      <origin rpy="0 0 0" xyz="0 0 0"/>
      <geometry>
        <mesh filename="package://koko_description_sevendof/meshes/base_link.STL"/>
      </geometry>
    </collision>
  </link>
  <joint name="left_base_roll_joint" type="revolute">
    <origin rpy="3.1416 -2.2011E-29 0.0" xyz="0 0 0.087371"/>
    <parent link="left_base_link"/>
    <child link="left_shoulder_roll_link"/>
    <axis xyz="0 0 1"/>
    <limit effort="0" lower="-2.3412" upper="3.3999" velocity="0"/>
  </joint>
  <link name="left_shoulder_roll_link">
    <inertial>
      <origin rpy="0 0 0" xyz="0.00526385736219506 2.70691865020822E-05 -0.0641638075944594"/>
      <mass value="1.91396434923"/>
      <inertia ixx="0.0057866591250737" ixy="3.71515699629511E-07" ixz="-6.32890111626103E-05" iyy="0.00530223654324281" iyz="8.9999884666805E-07" izz="0.00342399181200673"/>
    </inertial>
    <visual>
      <origin rpy="0 0 0" xyz="0 0 0"/>
      <geometry>
        <mesh filename="package://koko_description_sevendof/meshes/roll_link.STL"/>
      </geometry>
      <material name="">
        <color rgba="1 1 1 1"/>
      </material>
    </visual>
    <collision>
      <origin rpy="0 0 0" xyz="0 0 0"/>
      <geometry>
        <mesh filename="package://koko_description_sevendof/meshes/roll_link.STL"/>
      </geometry>
    </collision>
  </link>
  <joint name="left_shoulder_lift_joint" type="revolute">
    <origin rpy="-1.5708 4.4409E-16 3.1416" xyz="-0.01143 0 -0.18056"/>
    <parent link="left_shoulder_roll_link"/>
    <child link="left_shoulder_lift_link"/>
    <axis xyz="0 0 1"/>
    <limit effort="0" lower="-2.2944" upper="0" velocity="0"/>
  </joint>
  <link name="left_shoulder_lift_link">
    <inertial>
      <origin rpy="0 0 0" xyz="-5.0083559080677E-06 0.000232928456050885 -1.77451392545103E-05"/>
      <mass value="0.448307108622636"/>
      <inertia ixx="0.000804272985961788" ixy="4.84548777859872E-08" ixz="2.09160815704306E-06" iyy="0.000818260636171894" iyz="-1.44954778549764E-08" izz="0.000550840705045094"/>
    </inertial>
    <visual>
      <origin rpy="0 0 0" xyz="0 0 0"/>
      <geometry>
        <mesh filename="package://koko_description_sevendof/meshes/lift_link.STL"/>
      </geometry>
      <material name="">
        <color rgba="0.792156862745098 0.819607843137255 0.933333333333333 1"/>
      </material>
    </visual>
    <collision>
      <origin rpy="0 0 0" xyz="0 0 0"/>
      <geometry>
        <mesh filename="package://koko_description_sevendof/meshes/lift_link.STL"/>
      </geometry>
    </collision>
  </link>
  <joint name="left_shoulder_roll_joint" type="revolute">
    <origin rpy="-1.5708 1.5673 -3.1416" xyz="0 0.070147 -6.25E-05"/>
    <parent link="left_shoulder_lift_link"/>
    <child link="left_elbow_roll_link"/>
    <axis xyz="0 0 1"/>
    <limit effort="0" lower="-2.6761" upper="2.6761" velocity="0"/>
  </joint>
  <link name="left_elbow_roll_link">
    <inertial>
      <origin rpy="0 0 0" xyz="0.00526385736219506 2.70691865020822E-05 -0.0641638075944594"/>
      <mass value="1.91396434923"/>
      <inertia ixx="0.0057866591250737" ixy="3.71515699629511E-07" ixz="-6.32890111626103E-05" iyy="0.00530223654324281" iyz="8.9999884666805E-07" izz="0.00342399181200673"/>
    </inertial>
    <visual>
      <origin rpy="0 0 0" xyz="0 0 0"/>
      <geometry>
        <mesh filename="package://koko_description_sevendof/meshes/roll_link.STL"/>
      </geometry>
      <material name="">
        <color rgba="1 1 1 1"/>
      </material>
    </visual>
    <collision>
      <origin rpy="0 0 0" xyz="0 0 0"/>
      <geometry>
        <mesh filename="package://koko_description_sevendof/meshes/roll_link.STL"/>
      </geometry>
    </collision>
  </link>
  <joint name="left_elbow_lift_joint" type="revolute">
    <origin rpy="-1.5708 4.4409E-16 3.1416" xyz="-0.01143 0 -0.18056"/>
    <parent link="left_elbow_roll_link"/>
    <child link="left_elbow_lift_link"/>
    <axis xyz="0 0 1"/>
    <limit effort="0" lower="-2.2944" upper="0" velocity="0"/>
  </joint>
  <link name="left_elbow_lift_link">
    <inertial>
      <origin rpy="0 0 0" xyz="-5.0083559080677E-06 0.000232928456050885 -1.77451392545103E-05"/>
      <mass value="0.448307108622636"/>
      <inertia ixx="0.000804272985961788" ixy="4.84548777859872E-08" ixz="2.09160815704306E-06" iyy="0.000818260636171894" iyz="-1.44954778549764E-08" izz="0.000550840705045094"/>
    </inertial>
    <visual>
      <origin rpy="0 0 0" xyz="0 0 0"/>
      <geometry>
        <mesh filename="package://koko_description_sevendof/meshes/lift_link.STL"/>
      </geometry>
      <material name="">
        <color rgba="0.792156862745098 0.819607843137255 0.933333333333333 1"/>
      </material>
    </visual>
    <collision>
      <origin rpy="0 0 0" xyz="0 0 0"/>
      <geometry>
        <mesh filename="package://koko_description_sevendof/meshes/lift_link.STL"/>
      </geometry>
    </collision>
  </link>
  <joint name="left_elbow_roll_joint" type="revolute">
    <origin rpy="-1.5708 -1.5673 -3.1416" xyz="0 0.070147 -6.25E-05"/>
    <parent link="left_elbow_lift_link"/>
    <child link="left_wrist_roll_link"/>
    <axis xyz="0 0 1"/>
    <limit effort="0" lower="-2.6761" upper="2.6761" velocity="0"/>
  </joint>
  <link name="left_wrist_roll_link">
    <inertial>
      <origin rpy="0 0 0" xyz="0.00526385736219506 2.70691865020822E-05 -0.0641638075944594"/>
      <mass value="1.41368434923"/>
      <inertia ixx="0.0057866591250737" ixy="3.71515699629511E-07" ixz="-6.32890111626103E-05" iyy="0.00530223654324281" iyz="8.9999884666805E-07" izz="0.00342399181200673"/>
    </inertial>
    <visual>
      <origin rpy="0 0 0" xyz="0 0 0"/>
      <geometry>
        <mesh filename="package://koko_description_sevendof/meshes/roll_link.STL"/>
      </geometry>
      <material name="">
        <color rgba="1 1 1 1"/>
      </material>
    </visual>
    <collision>
      <origin rpy="0 0 0" xyz="0 0 0"/>
      <geometry>
        <mesh filename="package://koko_description_sevendof/meshes/roll_link.STL"/>
      </geometry>
    </collision>
  </link>
  <joint name="left_wrist_lift_joint" type="revolute">
    <origin rpy="-1.5708 4.4409E-16 3.1416" xyz="-0.01143 0 -0.18056"/>
    <parent link="left_wrist_roll_link"/>
    <child link="left_wrist_lift_link"/>
    <axis xyz="0 0 1"/>
    <limit effort="0" lower="-2.2944" upper="0" velocity="0"/>
  </joint>
  <link name="left_wrist_lift_link">
    <inertial>
      <origin rpy="0 0 0" xyz="-5.0083559080677E-06 0.000232928456050885 -1.77451392545103E-05"/>
      <mass value="0.448307108622636"/>
      <inertia ixx="0.000804272985961788" ixy="4.84548777859872E-08" ixz="2.09160815704306E-06" iyy="0.000818260636171894" iyz="-1.44954778549764E-08" izz="0.000550840705045094"/>
    </inertial>
    <visual>
      <origin rpy="0 0 0" xyz="0 0 0"/>
      <geometry>
        <mesh filename="package://koko_description_sevendof/meshes/lift_link.STL"/>
      </geometry>
      <material name="">
        <color rgba="0.792156862745098 0.819607843137255 0.933333333333333 1"/>
      </material>
    </visual>
    <collision>
      <origin rpy="0 0 0" xyz="0 0 0"/>
      <geometry>
        <mesh filename="package://koko_description_sevendof/meshes/lift_link.STL"/>
      </geometry>
    </collision>
  </link>
  <joint name="left_wrist_roll_joint" type="revolute">
    <origin rpy="-1.5708 0.0 -3.1416" xyz="0 0.070147 -6.25E-05"/>
    <parent link="left_wrist_lift_link"/>
    <child link="left_end_roll_link"/>
    <axis xyz="0 0 1"/>
    <limit effort="0" lower="-2.6761" upper="2.6761" velocity="0"/>
  </joint>
  <link name="left_end_roll_link">
    <inertial>
      <origin rpy="0 0 0" xyz="0.00526385736219506 2.70691865020822E-05 -0.0641638075944594"/>
      <mass value="0.657109755986862"/>
      <inertia ixx="0.0057866591250737" ixy="3.71515699629511E-07" ixz="-6.32890111626103E-05" iyy="0.00530223654324281" iyz="8.9999884666805E-07" izz="0.00342399181200673"/>
    </inertial>
    <visual>
      <origin rpy="0 0 0" xyz="0 0 0"/>
      <geometry>
        <mesh filename="package://koko_description_sevendof/meshes/wrist_roll_link.STL"/>
      </geometry>
      <material name="">
        <color rgba="1 1 1 1"/>
      </material>
    </visual>
    <collision>
      <origin rpy="0 0 0" xyz="0 0 0"/>
      <geometry>
        <mesh filename="package://koko_description_sevendof/meshes/wrist_roll_link.STL"/>
      </geometry>
    </collision>
  </link>
  <link name="left_gripper_link">
    <inertial>
      <origin rpy="0 0 0" xyz="-7.00549073506807E-05 2.51271935254316E-05 -0.052367118189184"/>
      <mass value="0.0047109755986862"/>
      <inertia ixx="0.000916887873826385" ixy="-6.04547948818479E-08" ixz="0.6796133363069E-06" iyy="0.000877268801166351" iyz="0.64172907801915E-07" izz="0.000293333065172452"/>
    </inertial>
    <visual>
      <origin rpy="0 0 0" xyz="0 0 0"/>
      <geometry>
        <mesh filename="package://koko_description_sevendof/meshes/wrist_roll_link.STL"/>
      </geometry>
      <material name="">
        <color rgba="0.792156862745098 0.819607843137255 0.933333333333333 1"/>
      </material>
    </visual>
    <collision>
      <origin rpy="0 0 0" xyz="0 0 0"/>
      <geometry>
        <mesh filename="package://koko_description_sevendof/meshes/wrist_roll_link.STL"/>
      </geometry>
    </collision>
  </link>
  <joint name="left_gripper_joint" type="revolute">
    <origin rpy="-1.5708 -2.4803E-15 -3.1416" xyz="0 0.070147 -6.25E-05"/>
    <parent link="left_end_roll_link"/>
    <child link="left_gripper_link"/>
    <axis xyz="0 0 1"/>
    <limit effort="0" lower="-2.6761" upper="2.6761" velocity="0"/>
  </joint>
</robot>

