<?xml version="1.0"?>

<!-- XML namespaces -->
<robot xmlns:xacro="http://ros.org/wiki/xacro">

  <!-- ============================  link  ============================ -->
  <!-- Includes elbow flex, FA roll joints in macros below -->
  <xacro:macro name="blue_link_v2" params="side stage child reflect wrist:=0">
    <xacro:blue_roll_link_v2 side="${side}" stage="${stage}" reflect="${reflect}" wrist="${wrist}"/>
    <xacro:blue_lift_link_v2 side="${side}" stage="${stage}" child="${child}" reflect="${reflect}" wrist="${wrist}"/>
  </xacro:macro>

  <xacro:macro name="blue_roll_link_v2" params="side stage reflect wrist">
    <link
      name="${side}_${stage}_roll_link">
      <inertial>
        <origin
          xyz="0.0069 -0.0001 -0.1116"
          rpy="0 0 0" />
        <mass
          value="${2.03492 - 0.86982 * wrist}" />
        <inertia
          ixx="61495.01E-07"
          ixy="-19.9700E-07"
          ixz="328.6000E-07"
          iyy="50978.60E-07"
          iyz="243.2100E-07"
          izz="41841.05E-07" />
      </inertial>
      <visual>
        <origin
          xyz="0 0 0"
          rpy="0 0 0" />
        <geometry>
          <mesh
            filename="package://blue_descriptions/meshes/roll_link_v2.STL" />
        </geometry>
        <material name="">
          <color rgba="1 1 1 1" />
        </material>
      </visual>
      <collision>
        <origin
          xyz="0 0 0"
          rpy="0 0 0" />
        <geometry>
          <mesh
            filename="package://blue_descriptions/meshes/roll_link_v2.STL" />
        </geometry>
      </collision>
    </link>

    <joint
      name="${side}_${stage}_lift_joint"
      type="revolute">
      <dynamics damping="0.7" friction="10.0"/>
      <origin
        xyz="-0.012 0 -0.232779056600415"
        rpy="-1.5707963267949 -4.98868359282976E-16 2.07570761486143E-16" />
      <parent
        link="${side}_${stage}_roll_link"/>
      <child
        link="${side}_${stage}_lift_link"/>
      <axis
        xyz="0 0 -1" />
      <limit
        lower="-2.3911"
        upper="0.3316"
        effort="800"
        velocity="50" />
    </joint>

    <xacro:if value="${is_gazebo}">
      <transmission name="${side}_${stage}_lift_joint_transmission">
        <type>transmission_interface/SimpleTransmission</type>
        <joint name="${side}_${stage}_lift_joint">
          <dynamics damping="0.7" friction="10.0"/>
          <hardwareInterface>hardware_interface/EffortJointInterface</hardwareInterface>
        </joint>
        <actuator name="${side}_${stage}_lift_motor">
          <hardwareInterface>hardware_interface/EffortJointInterface</hardwareInterface>
          <mechanicalReduction>1</mechanicalReduction>
        </actuator>
      </transmission>
    </xacro:if>

    <link
      name="${side}_${stage}_accel_link"/>
    <joint
      name="${side}_${stage}_accel_joint"
      type="fixed">
      <dynamics damping="0.7" friction="10.0"/>
      <origin
        xyz="-0.020008330615085 -0.000510000000000066 -0.111067108096273"
        rpy="1.5707963267949 0.328491802364426 5.16250107234938E-16" />
      <parent
        link="${side}_${stage}_roll_link" />
      <child
        link="${side}_${stage}_accel_link" />
      <axis
        xyz="0 0 0" />
    </joint>
  </xacro:macro>

  <xacro:macro name="blue_lift_link_v2" params="side stage child reflect wrist">
    <link
      name="${side}_${stage}_lift_link">
      <inertial>
        <origin
          xyz="0.0 0.01524 0.0"
          rpy="0 0 0" />
        <mass
          value="${0.58967 - 0.14061 * wrist}" />
        <inertia
          ixx="11631.35E-07"
          ixy="0.000000E-07"
          ixz="0.000000E-07"
          iyy="9852.210E-07"
          iyz="0.000000E-07"
          izz="8916.610E-07" />
      </inertial>
      <visual>
        <origin
          xyz="0 0 0"
          rpy="0 0 0" />
        <geometry>
          <mesh
            filename="package://blue_descriptions/meshes/lift_link_v2.STL" />
        </geometry>
        <material name="">
          <color rgba="0.116747 0.862745 1.0 1" />
        </material>
      </visual>
      <collision>
        <origin
          xyz="0 0 0"
          rpy="0 0 0" />
        <geometry>
          <mesh
            filename="package://blue_descriptions/meshes/lift_link_v2.STL" />
        </geometry>
      </collision>
    </link>

    <joint
      name="${side}_${stage}_roll_joint"
      type="revolute">
      <dynamics damping="0.7" friction="10.0"/>
      <origin
        xyz="0 ${0.0359531521130187+wrist*0.03419} 0"
        rpy="1.5707963267949 ${reflect*-1.56798} 0" />
      <parent
        link="${side}_${stage}_lift_link"/>
      <child
        link="${side}_${child}" />
      <axis
        xyz="0 0 1" />
      <limit
        lower="-2.6761"
        upper="2.6761"
        effort="800"
        velocity="50" />
    </joint>


    <xacro:if value="${is_gazebo}">
      <transmission name="${side}_${stage}_roll_joint_transmission">
        <type>transmission_interface/SimpleTransmission</type>
        <joint name="${side}_${stage}_roll_joint">
        <dynamics damping="0.7" friction="10.0"/>
          <hardwareInterface>hardware_interface/EffortJointInterface</hardwareInterface>
        </joint>
        <actuator name="${side}_${stage}_roll_motor">
          <hardwareInterface>hardware_interface/EffortJointInterface</hardwareInterface>
          <mechanicalReduction>1</mechanicalReduction>
        </actuator>
      </transmission>
    </xacro:if>

  </xacro:macro>
</robot>
