<robot
  name="koko_description_threedof_dyn">
  <link
    name="base_link">
    <inertial>
      <origin
        xyz="0.0167813742037007 -0.156233711844303 0.154308684460535"
        rpy="0 0 0" />
      <mass
        value="2.59188408490607" />
      <inertia
        ixx="0.0629598955948742"
        ixy="-0.00942160694730313"
        ixz="0.000756500622876714"
        iyy="0.0611228412796982"
        iyz="0.000232419074296784"
        izz="0.0415578554498367" />
    </inertial>
    <visual>
      <origin
        xyz="0 0 0"
        rpy="0 0 0" />
      <geometry>
        <mesh
          filename="package://koko_description_threedof_dyn/meshes/base_link.STL" />
      </geometry>
      <material
        name="">
        <color
          rgba="0.792156862745098 0.819607843137255 0.933333333333333 1" />
      </material>
    </visual>
    <collision>
      <origin
        xyz="0 0 0"
        rpy="0 0 0" />
      <geometry>
        <mesh
          filename="package://koko_description_threedof_dyn/meshes/base_link.STL" />
      </geometry>
    </collision>
  </link>
  <link
    name="base_roll_link">
    <inertial>
      <origin
        xyz="-0.00747857947952829 -2.49198025326636E-05 0.0799282586721559"
        rpy="0 0 0" />
      <mass
        value="4.07268027743269" />
      <inertia
        ixx="0.00617143853873105"
        ixy="-6.35617397339031E-07"
        ixz="-7.28586372305347E-06"
        iyy="0.00633184758217003"
        iyz="-4.26825720152351E-07"
        izz="0.00593999200785274" />
    </inertial>
    <visual>
      <origin
        xyz="0 0 0"
        rpy="0 0 0" />
      <geometry>
        <mesh
          filename="package://koko_description_threedof_dyn/meshes/base_roll_link.STL" />
      </geometry>
      <material
        name="">
        <color
          rgba="0.6 0.6 0.6 1" />
      </material>
    </visual>
    <collision>
      <origin
        xyz="0 0 0"
        rpy="0 0 0" />
      <geometry>
        <mesh
          filename="package://koko_description_threedof_dyn/meshes/base_roll_link.STL" />
      </geometry>
    </collision>
  </link>
  <joint
    name="base_roll_joint"
    type="continuous">
    <origin
      xyz="0.096645 -0.090805 0.21862"
      rpy="6.8385E-15 0.7854 4.8356E-15" />
    <parent
      link="base_link" />
    <child
      link="base_roll_link" />
    <axis
      xyz="0 0 1" />
  </joint>
  <link
    name="shoulder_link">
    <inertial>
      <origin
        xyz="-0.00194548267655537 -0.000308525194418541 -2.64734109634013E-08"
        rpy="0 0 0" />
      <mass
        value="0.437261200364267" />
      <inertia
        ixx="0.00108381098583672"
        ixy="1.14741689236012E-05"
        ixz="9.73805804020251E-07"
        iyy="0.00102494832628715"
        iyz="-1.61217444077573E-06"
        izz="0.000657515886602446" />
    </inertial>
    <visual>
      <origin
        xyz="0 0 0"
        rpy="0 0 0" />
      <geometry>
        <mesh
          filename="package://koko_description_threedof_dyn/meshes/shoulder_link.STL" />
      </geometry>
      <material
        name="">
        <color
          rgba="1 0.501960784313725 0.501960784313725 1" />
      </material>
    </visual>
    <collision>
      <origin
        xyz="0 0 0"
        rpy="0 0 0" />
      <geometry>
        <mesh
          filename="package://koko_description_threedof_dyn/meshes/shoulder_link.STL" />
      </geometry>
    </collision>
  </link>
  <joint
    name="shoulder_joint"
    type="continuous">
    <origin
      xyz="0.01143 4.0407E-05 0.20168"
      rpy="1.5708 -0.7854 0.0035351" />
    <parent
      link="base_roll_link" />
    <child
      link="shoulder_link" />
    <axis
      xyz="0 0 1" />
  </joint>
  <link
    name="shoulder_roll_link">
    <inertial>
      <origin
        xyz="-0.00624476977193023 -9.21624888806649E-05 0.073197077483341"
        rpy="0 0 0" />
      <mass
        value="4.76034588621041" />
      <inertia
        ixx="0.0157493288986156"
        ixy="-8.61170419671822E-06"
        ixz="-0.00115358914504996"
        iyy="0.01627865194805"
        iyz="-1.55878715822768E-05"
        izz="0.00791008496477049" />
    </inertial>
    <visual>
      <origin
        xyz="0 0 0"
        rpy="0 0 0" />
      <geometry>
        <mesh
          filename="package://koko_description_threedof_dyn/meshes/shoulder_roll_link.STL" />
      </geometry>
      <material
        name="">
        <color
          rgba="0.298039215686275 0.298039215686275 0.298039215686275 1" />
      </material>
    </visual>
    <collision>
      <origin
        xyz="0 0 0"
        rpy="0 0 0" />
      <geometry>
        <mesh
          filename="package://koko_description_threedof_dyn/meshes/shoulder_roll_link.STL" />
      </geometry>
    </collision>
  </link>
  <joint
    name="shoulder_roll_joint"
    type="continuous">
    <origin
      xyz="0.069522 0.012605 0"
      rpy="-1.5708 -0.014012 -1.3914" />
    <parent
      link="shoulder_link" />
    <child
      link="shoulder_roll_link" />
    <axis
      xyz="0 0 1" />
  </joint>
</robot>