<?xml version="1.0"?>

<!-- XML namespaces -->
<robot xmlns:xacro="http://ros.org/wiki/xacro">

  <!-- Inertial properties differ slightly for left vs right arm -->
  <xacro:property name="base_left_min"  value="-3.14159" />
  <xacro:property name="base_left_max"  value="3.1" />

  <xacro:property name="base_right_min"  value="-3.1" />
  <xacro:property name="base_right_max"  value="3.14159" />

  <!-- ============================  link  ============================ -->
  <!-- Includes elbow flex, FA roll joints in macros below -->
  <xacro:macro name="blue_base_v2" params="side reflect child">
    <!-- ad -->
    <link name="${side}_base_link">
      <inertial>
        <origin
          xyz="0.10796437546629 -0.000118075432376297 0.0740606975550663"
          rpy="0 0 0" />
        <mass
          value="3.45160966669018" />
        <inertia
          ixx="0.00801268059065087"
          ixy="-2.57142344841348E-05"
          ixz="-0.00260219134387606"
          iyy="0.0157384822948846"
          iyz="-9.21399274816697E-06"
          izz="0.0168436725169874" />
      </inertial>
      <visual>
        <origin
          xyz="0 0 0"
          rpy="0 0 0" />
        <geometry>
          <mesh
            filename="package://blue_descriptions/meshes/arm_base_link_v2.STL" />
        </geometry>
        <material name="">
          <color rgba="0.792156862745098 0.819607843137255 0.933333333333333 1" />
        </material>
      </visual>
      <collision>
        <origin
          xyz="0 0 0"
          rpy="0 0 0" />
        <geometry>
          <mesh
            filename="package://blue_descriptions/meshes/arm_base_link_v2.STL" />
        </geometry>
      </collision>
    </link>

    <joint
      name="${side}_base_roll_joint"
      type="revolute">
      <dynamics damping="0.7" friction="10.0"/>
      <origin
        xyz="0 0 0.0834989807730001"
        rpy="3.14159265358979 -1.1927577496737E-15 2.81382558958119E-17" />
      <parent
        link="${side}_base_link" />
      <child
        link="${side}_${child}" />
      <axis
        xyz="0 0 1" />
      <limit
        lower="${0.5*((reflect+1)*base_left_min+(1-reflect)*base_right_min)}"
        upper="${0.5*((reflect+1)*base_left_max+(1-reflect)*base_right_max)}"
        effort="800"
        velocity="50" />
    </joint>

    <xacro:if value="${is_gazebo}">
      <transmission name="${side}_base_roll_joint_transmission">
        <type>transmission_interface/SimpleTransmission</type>
        <joint name="${side}_base_roll_joint">
          <dynamics damping="0.7" friction="10.0"/>
          <hardwareInterface>hardware_interface/EffortJointInterface</hardwareInterface>
        </joint>
        <actuator name="${side}_base_roll_motor">
          <hardwareInterface>hardware_interface/EffortJointInterface</hardwareInterface>
          <mechanicalReduction>1</mechanicalReduction>
        </actuator>
      </transmission>
    </xacro:if>

  </xacro:macro>

</robot>
